File: 06_XPS_Analysis/data/raw/02122025_duncanreece_rit2749.vms
VAMAS Surface Chemical Analysis Standard Data Transfer Format 1988 May 4
Not Specified
Kratos Axis
Not Specified
/C=/data/2025/02-2025/02122025_DuncanReece_RIT2749.dset
3
Casa Info Follows CasaXPS Version 2.3.25PR1.0
0
SourceAnalyserAngle: Not Specified
MAP
REGULAR
4
18
32768
32768
1
Angle
degree
0
0
0
0
24
Survey/2
Not Specified
2025
2
12
12
55
0
0
8
Casa Info Follows
0
0
0
0
   XPS     Spectrum    Lens Mode:Hybrid   Res:80   Iris(Aper):slot(Slot)
   Acqn. Time(s): 241        Sweeps: 2        Anode:Mono(Al (Mono))(225 W)   Step(meV): 1000.0
   Dwell Time(ms): 100        Charge Neutraliser :On (Current 1.9 A: Balance 3.1 V: Bias 1.0 V)   Acquired On :25/02/12 12:55:00
XPS
9
0
1
Mono(Al (Mono))
1486.69
225
1e+037
1e+037
6000
6000
1e+037
1e+037
FAT
80
1e+037
-4.9
0
1e+037
1e+037
1e+037
1e+037
Wide
None
-1
Kinetic Energy
eV
286.69
1
2
Intensity
d
Transmission
d
pulse counting
0.1
0
1e+037
0
0
1.47543
1963
2097
1995
2039
2055
2033
1997
1989
2004
2124
2098
2106
2080
2105
2083
2081
2013
2065
2089
2073
2076
2068
2055
2033
2057
2053
2067
2162
2131
2115
2171
2092
2125
2107
2042
2062
2075
2163
2151
2053
2171
2119
2202
2139
2138
2138
2191
2106
2157
2125
2110
2135
2202
2143
2110
2173
2182
2135
2150
2186
2188
2171
2162
2178
2215
2149
2140
2188
2229
2278
2191
2175
2269
2297
2269
2182
2229
2263
2286
2307
2229
2257
2237
2250
2297
2239
2292
2291
2265
2241
2277
2264
2267
2297
2290
2333
2317
2240
2261
2340
2339
2308
2331
2286
2346
2356
2332
2385
2355
2276
2345
2315
2317
2355
2327
2324
2343
2380
2386
2417
2307
2301
2383
2391
2225
2343
2425
2388
2327
2387
2440
2487
2443
2443
2398
2463
2432
2349
2403
2392
2417
2495
2477
2398
2442
2471
2489
2485
2507
2504
2412
2594
2512
2483
2536
2557
2574
2507
2557
2507
2541
2545
2584
2527
2606
2618
2544
2583
2615
2627
2644
2691
2651
2653
2651
2660
2613
2621
2637
2644
2674
2689
2630
2682
2705
2706
2787
2736
2713
2814
2822
2729
2627
2700
2726
2705
2749
2773
2836
2810
2846
2893
2954
2965
2991
2960
2878
2810
2750
2728
2635
2581
2560
2499
2484
2421
2428
2459
2530
2607
2806
2991
3143
3266
3379
3509
3294
3090
2894
2678
2574
2431
2355
2088
1906
1883
1816
1702
1709
1554
1560
1601
1622
1602
1629
1582
1580
1624
1584
1636
1647
1593
1603
1596
1593
1714
1726
1643
1602
1727
1640
1642
1621
1660
1574
1643
1640
1604
1593
1603
1700
1610
1582
1638
1634
1647
1654
1705
1709
1688
1614
1661
1681
1667
1677
1572
1668
1674
1667
1655
1604
1651
1720
1721
1672
1682
1694
1693
1710
1724
1696
1651
1664
1692
1677
1683
1703
1719
1700
1711
1718
1696
1740
1692
1689
1716
1686
1704
1724
1720
1725
1737
1749
1759
1741
1754
1747
1761
1788
1682
1749
1733
1748
1776
1774
1756
1789
1812
1808
1805
1769
1773
1827
1771
1838
1703
1742
1850
1798
1809
1852
1813
1757
1751
1777
1813
1795
1734
1799
1832
1810
1826
1809
1832
1827
1825
1870
1856
1875
1837
1784
1844
1832
1816
1856
1849
1832
1849
1840
1855
1834
1789
1736
1851
1888
1870
1861
1826
1881
1896
1808
1831
1843
1888
1910
1875
1906
1933
1913
1874
1955
1981
1862
1844
1927
1867
1869
1903
1886
1882
1906
1813
1931
1967
1916
1973
1900
1905
1921
1933
1910
1905
1923
1908
1990
1950
1990
1985
1948
1995
1934
1977
1940
1965
1967
1965
1939
1907
1953
1980
1951
1971
1953
2003
1948
1948
1965
1963
2029
2035
2076
1978
1974
2062
1979
1997
2040
2001
2040
2069
2000
1979
2006
1975
2060
2095
2035
2080
1994
2075
2038
2039
1990
1958
2048
2071
2051
2017
2074
2052
1992
2093
2150
2090
2082
2104
2092
2021
2065
2132
2137
2059
2042
2092
2135
2096
2125
2095
2142
2051
2088
2152
2104
2082
2097
2162
2148
2079
2088
2180
2117
2188
2233
2151
2208
2145
2180
2167
2144
2140
2166
2206
2183
2196
2101
2184
2141
2115
2128
2099
2201
2213
2202
2221
2268
2189
2200
2271
2167
2181
2227
2230
2224
2218
2267
2239
2201
2240
2223
2246
2171
2231
2293
2216
2251
2227
2260
2294
2281
2273
2298
2252
2333
2188
2287
2292
2242
2269
2257
2289
2293
2288
2281
2240
2295
2318
2309
2324
2335
2338
2291
2344
2269
2248
2331
2250
2300
2371
2305
2338
2345
2349
2418
2354
2327
2372
2293
2342
2330
2295
2371
2353
2358
2355
2390
2337
2331
2320
2360
2354
2382
2412
2389
2369
2380
2382
2392
2371
2368
2378
2420
2407
2445
2507
2427
2553
2445
2370
2429
2431
2387
2337
2337
2367
2331
2299
2284
2257
2249
2280
2327
2370
2472
2473
2610
2563
2656
2709
2749
2684
2593
2599
2427
2359
2273
2146
2078
1931
1737
1682
1574
1508
1415
1438
1395
1280
1254
1321
1793
3900
9077
11621
6976
2822
1381
1092
1006
1015
988
1022
1002
983
943
968
1000
988
942
999
962
1006
990
1002
1026
992
956
977
993
1004
1043
999
1031
993
990
977
1011
1026
976
975
1022
1014
1019
1021
945
975
1025
1043
993
983
1016
988
997
993
984
1009
1038
1035
1020
1010
1000
1011
1048
1053
1055
1038
1000
1023
1007
995
1023
992
1040
1068
1036
1030
1050
1030
1062
1035
1019
1067
1069
1001
1073
1030
1011
1114
1055
1027
1117
1061
1107
1062
1038
1117
1098
1117
1112
1066
1080
1118
1097
1103
1049
1129
1137
1075
1090
1070
1118
1077
1130
1108
1101
1130
1093
1054
1103
1094
1140
1125
1114
1155
1100
1083
1149
1102
1128
1127
1084
1155
1128
1115
1177
1156
1152
1150
1114
1163
1134
1097
1079
1135
1123
1154
1134
1110
1093
1186
1157
1146
1182
1153
1133
1136
1200
1208
1188
1136
1106
1195
1188
1159
1252
1246
1170
1129
1213
1136
1185
1196
1197
1173
1201
1171
1209
1210
1194
1225
1174
1200
1225
1272
1227
1168
1228
1232
1279
1198
1273
1221
1243
1245
1280
1301
1290
1226
1285
1315
1286
1260
1226
1319
1237
1287
1325
1299
1287
1251
1304
1234
1276
1301
1298
1334
1334
1316
1333
1321
1302
1346
1377
1425
1420
1435
1398
1459
1498
1396
1391
1338
1264
1212
1136
1106
996
947
858
808
710
700
765
716
680
709
981
2053
4585
6016
5663
2890
1105
542
398
353
354
356
342
369
368
344
396
372
345
357
341
353
356
336
322
333
380
349
345
340
363
365
375
371
373
343
357
338
345
368
385
351
380
368
354
353
369
363
360
383
375
382
364
376
326
353
323
362
360
370
367
378
360
381
366
346
336
332
339
320
359
363
352
386
344
332
335
360
354
367
380
365
378
354
369
367
356
371
350
340
363
352
361
368
381
353
361
358
333
393
385
370
390
423
380
394
399
366
387
383
363
375
359
368
383
393
374
357
403
339
372
362
383
383
412
404
409
385
381
378
346
364
368
384
430
395
429
413
376
411
385
414
405
408
392
446
422
418
443
454
388
394
384
362
368
346
345
337
333
335
308
296
290
288
274
304
317
493
890
1447
1356
737
418
307
287
288
256
239
244
244
227
228
255
253
244
240
254
276
280
250
291
273
269
248
236
234
236
251
249
251
223
199
189
174
170
166
174
151
140
138
142
155
236
620
1245
971
353
182
125
121
155
144
130
131
109
117
127
136
149
151
129
130
135
139
139
148
137
153
141
128
140
148
148
145
142
139
131
126
119
120
131
110
106
112
115
114
126
97
107
112
150
186
257
309
347
251
202
136
100
106
94
117
141
176
120
100
85
86
96
83
102
84
82
80
61
60
20
1
1
0
0
0
1.47543
Survey/5
Not Specified
2025
2
12
13
0
33
0
8
Casa Info Follows
0
0
0
0
   XPS     Spectrum    Lens Mode:Hybrid   Res:80   Iris(Aper):slot(Slot)
   Acqn. Time(s): 241        Sweeps: 2        Anode:Mono(Al (Mono))(225 W)   Step(meV): 1000.0
   Dwell Time(ms): 100        Charge Neutraliser :On (Current 1.9 A: Balance 3.1 V: Bias 1.0 V)   Acquired On :25/02/12 13:00:33
XPS
7
1
2
Mono(Al (Mono))
1486.69
225
1e+037
1e+037
6000
6000
1e+037
1e+037
FAT
80
1e+037
-4.9
0
1e+037
1e+037
1e+037
1e+037
Wide
None
-1
Kinetic Energy
eV
286.69
1
2
Intensity
d
Transmission
d
pulse counting
0.1
0
1e+037
0
0
1.47543
1978
1980
1925
1952
1921
1912
1975
2028
1993
2012
1978
1979
1969
1958
2010
2026
2040
1980
1998
1933
1978
1986
2026
2023
2002
1983
1932
2034
2064
2037
2053
2064
1988
1991
2027
2041
1976
2014
2110
2024
2005
2072
2021
2021
2039
2044
2014
2021
2037
2022
2013
2070
2079
2060
2060
2101
2162
2112
2099
2119
2152
2100
2124
2135
2143
2182
2123
2054
2115
2144
2193
2181
2228
2165
2196
2153
2075
2180
2166
2200
2172
2234
2209
2158
2168
2137
2183
2202
2160
2230
2250
2250
2168
2182
2219
2191
2294
2227
2170
2158
2225
2234
2188
2243
2252
2234
2216
2216
2250
2275
2243
2239
2311
2289
2243
2266
2304
2374
2307
2293
2292
2273
2163
2227
2283
2292
2335
2305
2440
2394
2357
2336
2346
2373
2441
2418
2378
2395
2333
2336
2375
2379
2396
2362
2404
2370
2389
2411
2431
2386
2442
2482
2462
2457
2444
2476
2382
2443
2545
2514
2407
2512
2414
2423
2504
2508
2512
2499
2554
2526
2482
2523
2499
2475
2549
2553
2554
2554
2629
2687
2576
2563
2686
2605
2596
2642
2683
2738
2719
2674
2650
2620
2547
2492
2572
2597
2597
2746
2690
2717
2811
2874
2941
2883
2900
2914
2804
2657
2627
2612
2562
2467
2431
2499
2361
2344
2383
2392
2410
2591
2729
2966
3088
3229
3393
3479
3361
3065
2805
2605
2519
2375
2289
2090
1944
1815
1733
1704
1546
1544
1581
1508
1555
1598
1519
1549
1549
1560
1594
1563
1566
1560
1586
1562
1533
1629
1598
1573
1602
1607
1584
1572
1583
1544
1568
1602
1634
1597
1592
1615
1628
1605
1571
1589
1553
1600
1554
1630
1602
1576
1557
1660
1668
1633
1647
1625
1626
1678
1615
1646
1679
1647
1667
1591
1641
1638
1633
1654
1640
1647
1586
1604
1629
1606
1612
1586
1663
1645
1651
1691
1628
1620
1658
1611
1652
1705
1725
1623
1719
1697
1622
1638
1688
1608
1676
1686
1701
1701
1661
1678
1689
1693
1722
1699
1647
1669
1673
1757
1648
1692
1695
1794
1747
1709
1699
1769
1747
1706
1700
1709
1760
1769
1771
1727
1703
1702
1794
1763
1724
1731
1770
1739
1756
1713
1791
1846
1761
1805
1788
1757
1800
1764
1796
1780
1805
1801
1730
1814
1796
1790
1780
1768
1821
1749
1792
1881
1771
1782
1802
1816
1799
1767
1817
1840
1794
1842
1779
1780
1802
1861
1810
1818
1784
1743
1838
1897
1893
1836
1790
1842
1911
1888
1842
1832
1889
1840
1848
1884
1843
1820
1857
1870
1876
1868
1901
1850
1911
1850
1853
1848
1891
1930
1918
1891
1907
1824
1831
1882
1988
1914
1882
1888
1958
1968
1937
1953
2028
1963
1893
1900
1933
1938
1938
1957
1889
1946
2010
2008
1886
1975
2017
1956
1950
1967
1938
1940
1945
1966
1987
1972
2020
1971
1971
1973
2014
1952
1949
1932
1906
1959
2061
2067
2025
2034
2013
2000
1971
2045
2009
2004
2006
2063
2053
2010
2062
2075
2045
1973
2029
1970
2042
2062
2071
2029
2038
2066
2047
2100
2101
2048
2082
2117
2053
2077
2134
2148
2084
2114
2089
2122
2155
2150
2093
2113
2111
2069
2098
2088
2107
2104
2078
2062
2063
2076
2116
2147
2190
2188
2117
2098
2188
2141
2126
2191
2093
2126
2095
2151
2159
2208
2172
2139
2170
2138
2189
2208
2172
2148
2233
2243
2152
2187
2193
2186
2168
2169
2188
2221
2213
2210
2227
2195
2252
2275
2240
2299
2282
2286
2217
2265
2262
2218
2177
2256
2261
2148
2238
2248
2238
2271
2224
2240
2264
2231
2259
2318
2298
2298
2304
2255
2271
2269
2245
2299
2234
2282
2211
2298
2264
2280
2310
2260
2271
2328
2335
2346
2311
2304
2348
2253
2311
2348
2383
2335
2315
2354
2363
2434
2378
2316
2284
2279
2212
2255
2187
2210
2220
2187
2204
2278
2271
2253
2281
2407
2472
2637
2631
2624
2618
2573
2566
2514
2356
2303
2241
2128
1967
1842
1753
1647
1495
1503
1371
1347
1323
1228
1246
1337
1789
3806
8962
11603
6852
2725
1341
1018
981
957
962
970
994
987
970
924
982
944
955
956
941
937
955
970
919
983
1006
1025
939
977
1022
1019
949
987
950
928
953
988
996
967
1000
1005
979
974
978
972
968
985
986
989
963
999
992
996
974
1010
1028
1043
1024
1052
1042
1028
1006
954
980
1050
1033
1031
991
996
1007
1001
1000
991
969
989
984
969
992
1011
1024
1011
1034
1051
1061
1063
1002
1027
1013
1048
1071
1027
1042
1079
1052
1034
1056
1068
1000
1006
1084
1053
1000
1000
1044
984
1029
1031
1051
1039
1051
1058
1030
1032
1102
1064
1096
1100
1093
1019
1021
1046
1053
1094
1116
1082
1076
1084
1133
1084
1091
1057
1039
1090
1088
1143
1158
1116
1113
1131
1075
1052
1116
1057
1142
1087
1119
1117
1127
1169
1115
1066
1120
1088
1090
1104
1091
1126
1161
1113
1132
1133
1151
1127
1137
1133
1136
1137
1150
1118
1189
1246
1187
1186
1153
1147
1119
1154
1166
1150
1160
1158
1214
1172
1204
1201
1228
1164
1265
1260
1222
1219
1234
1235
1217
1246
1234
1255
1268
1194
1192
1256
1256
1204
1190
1201
1208
1245
1204
1267
1298
1270
1275
1238
1155
1200
1175
1270
1232
1262
1318
1284
1287
1361
1391
1378
1394
1462
1371
1396
1357
1275
1267
1135
1049
986
926
838
800
744
732
684
693
662
603
665
922
2021
4438
5935
5213
2640
1028
534
369
352
361
343
337
331
318
341
327
331
370
346
357
316
335
357
360
362
341
345
348
327
326
324
330
344
341
355
345
333
301
343
345
355
314
364
324
336
365
325
348
344
347
354
349
367
363
339
354
337
345
374
359
375
352
351
360
393
348
348
355
316
353
367
343
363
369
356
323
341
363
354
361
361
391
353
346
369
355
334
329
354
360
342
318
369
367
333
362
362
368
366
367
348
348
358
367
368
355
391
362
373
343
363
347
330
351
324
366
384
341
372
355
368
397
371
377
374
378
364
371
389
345
344
375
388
372
388
388
401
381
372
379
396
406
397
393
413
434
429
419
412
418
419
379
391
377
362
339
334
310
303
311
283
289
275
265
306
308
403
823
1439
1291
691
398
299
274
240
249
236
229
235
213
216
219
221
228
235
253
249
274
253
229
256
242
248
251
269
232
223
223
216
233
180
188
174
176
152
142
168
160
146
131
148
220
597
1127
869
350
189
114
136
138
142
136
119
132
124
137
137
130
138
143
119
130
151
107
138
140
148
147
139
116
134
138
152
136
124
137
130
122
113
113
114
107
108
114
117
115
106
102
127
173
202
264
343
339
259
204
107
109
95
97
115
132
153
123
94
96
65
78
91
89
79
71
69
76
50
35
3
0
0
0
0
1.47543
Survey/8
Not Specified
2025
2
12
13
5
54
0
8
Casa Info Follows
0
0
0
0
   XPS     Spectrum    Lens Mode:Hybrid   Res:80   Iris(Aper):slot(Slot)
   Acqn. Time(s): 241        Sweeps: 2        Anode:Mono(Al (Mono))(225 W)   Step(meV): 1000.0
   Dwell Time(ms): 100        Charge Neutraliser :On (Current 1.9 A: Balance 3.1 V: Bias 1.0 V)   Acquired On :25/02/12 13:05:54
XPS
8
3
3
Mono(Al (Mono))
1486.69
225
1e+037
1e+037
6000
6000
1e+037
1e+037
FAT
80
1e+037
-4.9
0
1e+037
1e+037
1e+037
1e+037
Wide
None
-1
Kinetic Energy
eV
286.69
1
2
Intensity
d
Transmission
d
pulse counting
0.1
0
1e+037
0
0
1.47543
2045
2097
2124
2099
2080
2062
2041
2108
2116
2119
2088
2128
2103
2101
2125
2112
2174
2145
2082
2082
2072
2014
2103
2137
2121
2039
2094
2145
2114
2110
2188
2213
2174
2212
2148
2141
2138
2235
2200
2170
2203
2208
2160
2174
2206
2192
2201
2150
2188
2236
2189
2190
2102
2165
2264
2227
2094
2123
2179
2197
2221
2202
2207
2219
2220
2263
2225
2226
2191
2219
2249
2280
2231
2239
2285
2270
2227
2259
2269
2289
2312
2309
2276
2266
2275
2315
2346
2286
2356
2387
2362
2313
2347
2357
2339
2348
2296
2423
2376
2354
2358
2304
2406
2443
2409
2400
2403
2357
2356
2404
2426
2404
2369
2398
2415
2403
2440
2445
2434
2488
2420
2372
2478
2402
2435
2412
2345
2411
2472
2474
2529
2534
2460
2443
2527
2516
2432
2491
2440
2543
2482
2510
2522
2445
2540
2523
2529
2557
2532
2472
2463
2523
2473
2520
2482
2523
2618
2551
2603
2573
2562
2589
2524
2664
2630
2609
2585
2585
2611
2644
2587
2635
2692
2661
2628
2701
2609
2731
2664
2714
2742
2645
2700
2754
2757
2749
2735
2784
2866
2843
2866
2809
2718
2712
2727
2731
2713
2802
2829
2829
2883
2945
3054
3053
3071
3062
2941
2886
2849
2685
2599
2676
2655
2637
2510
2530
2495
2514
2607
2747
2889
2991
3187
3276
3509
3582
3551
3262
3018
2822
2657
2527
2347
2236
2099
1888
1808
1744
1764
1660
1661
1630
1686
1620
1655
1659
1667
1655
1646
1654
1666
1706
1681
1677
1623
1605
1637
1659
1674
1670
1687
1665
1708
1668
1645
1699
1681
1665
1710
1702
1617
1681
1674
1714
1679
1692
1669
1719
1704
1704
1687
1702
1673
1672
1716
1702
1711
1699
1674
1685
1751
1729
1750
1722
1740
1679
1719
1720
1736
1698
1657
1740
1678
1727
1713
1725
1745
1744
1771
1751
1773
1752
1762
1679
1732
1802
1712
1733
1826
1810
1761
1749
1724
1702
1762
1821
1753
1776
1826
1834
1756
1761
1788
1888
1779
1785
1730
1809
1910
1825
1782
1762
1785
1797
1844
1798
1848
1827
1810
1871
1884
1893
1805
1832
1904
1840
1839
1875
1900
1881
1866
1867
1861
1882
1855
1859
1848
1907
1885
1873
1882
1856
1911
1845
1841
1879
1892
1837
1838
1851
1817
1850
1893
1850
1867
1873
1931
1891
1949
1889
1864
1900
1891
1930
1915
1919
1924
1856
1893
1905
1917
1951
1902
1935
1966
1933
1896
1942
1958
1923
1964
2000
1941
1960
1910
1922
1916
2004
1967
1942
1916
1937
1923
1964
1968
1957
1968
2014
1972
2016
1964
1971
1985
1998
2028
2072
2064
1999
1982
2004
2013
1930
1981
2073
2015
2059
1998
2053
2063
1992
2012
2060
2002
1982
1996
2041
2060
2030
2054
2056
2065
2079
2082
2049
2059
2173
2156
2057
2134
2092
2068
2017
2050
2110
2153
2062
2048
2130
2128
2169
2164
2090
2123
2151
2089
2118
2096
2049
2103
2143
2146
2145
2079
2138
2160
2147
2177
2154
2204
2113
2145
2175
2139
2153
2234
2178
2119
2220
2215
2227
2184
2211
2218
2166
2151
2233
2281
2221
2234
2231
2221
2223
2198
2257
2177
2164
2250
2248
2202
2218
2174
2197
2204
2244
2278
2276
2289
2245
2245
2341
2292
2187
2217
2301
2364
2355
2331
2343
2324
2329
2338
2327
2259
2280
2314
2273
2236
2289
2331
2383
2299
2335
2363
2302
2308
2292
2334
2314
2348
2360
2350
2342
2363
2334
2335
2318
2343
2429
2419
2428
2393
2325
2334
2411
2425
2383
2416
2355
2376
2403
2404
2379
2391
2331
2366
2407
2403
2352
2383
2329
2367
2368
2434
2426
2346
2391
2391
2328
2417
2377
2362
2444
2471
2404
2399
2430
2381
2412
2480
2364
2388
2502
2452
2537
2583
2573
2505
2470
2484
2470
2401
2435
2392
2375
2456
2377
2362
2345
2330
2372
2453
2475
2536
2579
2619
2725
2767
2803
2743
2750
2692
2594
2516
2406
2328
2236
2100
1936
1811
1776
1658
1517
1452
1417
1380
1298
1232
1416
1882
3948
9326
12433
7399
2945
1417
1132
1070
1009
1028
1026
1023
1048
983
1032
1011
1055
1038
1024
991
1055
1017
962
1017
990
991
1038
1020
1029
1028
1029
977
1015
1013
1008
1016
995
1001
1038
1004
983
1046
1054
1041
1004
994
1050
1000
1054
999
1013
1048
999
981
999
1075
1099
1051
1044
1063
1075
1095
1061
1015
1102
1097
1074
1042
1075
1104
1096
1069
1071
1078
1054
1101
1080
1064
1036
1128
1080
1057
1099
1036
1099
1080
1081
1074
1054
1092
1089
1102
1082
1121
1092
1076
1081
1081
1079
1070
1109
1118
1085
1126
1090
1100
1110
1056
1113
1093
1129
1122
1128
1131
1103
1110
1113
1181
1181
1144
1132
1090
1139
1190
1114
1159
1107
1130
1171
1208
1132
1154
1176
1127
1165
1189
1180
1165
1160
1166
1142
1166
1167
1140
1147
1239
1168
1127
1171
1245
1217
1200
1218
1249
1232
1207
1228
1189
1224
1229
1182
1191
1201
1184
1197
1200
1192
1203
1228
1242
1238
1186
1207
1292
1230
1225
1241
1260
1250
1280
1230
1249
1249
1326
1301
1300
1281
1238
1233
1266
1319
1324
1257
1308
1306
1320
1274
1309
1305
1364
1313
1302
1339
1317
1299
1325
1320
1295
1348
1310
1347
1317
1374
1331
1301
1335
1328
1333
1338
1354
1467
1435
1412
1463
1433
1418
1494
1483
1392
1405
1339
1270
1190
1112
1049
1001
905
897
801
714
728
750
734
638
704
961
2115
4802
6178
5577
2884
1103
550
404
390
366
352
366
369
355
408
374
386
350
387
355
338
368
359
329
320
315
342
353
392
388
337
357
356
360
375
388
387
376
405
358
332
346
363
392
375
393
397
357
376
355
379
386
363
394
368
333
374
347
376
366
371
390
379
353
362
368
358
365
356
343
383
399
362
359
383
373
387
364
379
393
363
367
361
369
350
375
378
384
353
393
375
347
368
382
405
406
363
366
397
368
355
402
393
385
375
409
386
374
372
402
365
366
390
382
391
413
371
378
418
406
400
418
399
404
437
410
364
382
371
393
359
355
379
402
439
399
407
419
420
413
426
431
397
428
450
422
439
439
422
408
407
386
382
415
352
342
339
334
330
314
283
306
296
308
322
350
474
855
1481
1458
772
446
313
275
231
245
253
243
237
247
261
240
223
193
239
299
284
267
262
273
264
272
274
258
253
270
263
238
217
229
183
189
184
185
181
173
164
164
136
153
162
226
601
1207
996
373
186
147
145
135
119
125
136
151
138
135
148
142
147
153
129
147
138
138
150
140
152
140
149
167
147
163
146
182
132
132
115
120
125
122
128
119
112
114
106
111
118
115
121
152
182
269
345
351
293
188
134
112
122
118
136
145
150
127
91
75
96
85
87
77
105
85
78
78
63
23
6
1
2
2
0
1.47543
Survey/11
Not Specified
2025
2
12
13
11
20
0
8
Casa Info Follows
0
0
0
0
   XPS     Spectrum    Lens Mode:Hybrid   Res:80   Iris(Aper):slot(Slot)
   Acqn. Time(s): 241        Sweeps: 2        Anode:Mono(Al (Mono))(225 W)   Step(meV): 1000.0
   Dwell Time(ms): 100        Charge Neutraliser :On (Current 1.9 A: Balance 3.1 V: Bias 1.0 V)   Acquired On :25/02/12 13:11:20
XPS
30
3
4
Mono(Al (Mono))
1486.69
225
1e+037
1e+037
6000
6000
1e+037
1e+037
FAT
80
1e+037
-4.9
0
1e+037
1e+037
1e+037
1e+037
Wide
None
-1
Kinetic Energy
eV
286.69
1
2
Intensity
d
Transmission
d
pulse counting
0.1
0
1e+037
0
0
1.47543
1935
1990
2005
2042
2069
2120
2044
2096
2042
1964
1986
2018
2084
2068
1996
2042
1979
2059
2003
2012
2033
2067
2062
2031
1989
2043
2021
2127
2062
2046
2092
2026
2060
2108
2131
2109
2126
2176
2141
2112
2165
2101
2092
2122
2119
2176
2217
2153
2144
2101
2126
2145
2148
2255
2257
2245
2179
2176
2258
2166
2215
2222
2178
2319
2265
2196
2254
2247
2255
2227
2211
2228
2270
2322
2271
2169
2292
2292
2218
2176
2227
2329
2338
2313
2287
2291
2291
2281
2314
2205
2297
2320
2296
2325
2318
2402
2329
2349
2311
2317
2375
2342
2377
2445
2352
2413
2382
2379
2336
2428
2378
2455
2427
2483
2401
2375
2316
2390
2429
2415
2442
2459
2420
2435
2470
2464
2452
2501
2463
2527
2492
2529
2606
2533
2482
2486
2513
2527
2490
2510
2526
2584
2516
2590
2557
2543
2515
2619
2614
2611
2641
2648
2615
2650
2588
2592
2639
2648
2571
2559
2550
2628
2702
2615
2597
2613
2719
2667
2697
2717
2631
2658
2684
2713
2725
2773
2745
2751
2744
2793
2826
2844
2787
2810
2811
2855
2828
2854
2867
2818
2897
2853
2797
2807
2721
2814
2852
2854
2885
2966
2967
3059
3087
3113
3141
2966
2969
2978
2882
2821
2687
2671
2719
2620
2529
2513
2573
2577
2605
2676
2823
3055
3118
3280
3438
3631
3657
3424
3087
2899
2741
2682
2643
2363
2121
2014
1879
1745
1674
1685
1716
1669
1692
1633
1634
1662
1620
1667
1637
1602
1629
1623
1630
1622
1659
1630
1664
1628
1667
1732
1653
1670
1596
1598
1686
1740
1771
1640
1618
1641
1658
1665
1707
1701
1697
1632
1691
1715
1677
1652
1693
1702
1760
1765
1734
1684
1758
1710
1729
1712
1733
1745
1726
1723
1793
1784
1704
1730
1744
1757
1754
1755
1765
1758
1793
1788
1774
1784
1758
1746
1786
1792
1765
1846
1823
1803
1733
1818
1877
1895
1830
1861
1845
1804
1880
1864
1843
1859
1854
1842
1884
1874
1868
1878
1895
1892
1879
1924
1940
1935
1929
1908
1951
1968
1893
1940
1953
1910
1868
1894
1902
1945
1880
1942
1944
1970
1955
1934
1920
1939
1988
1982
2031
2060
2121
2202
2196
2208
2210
2191
2205
2076
2070
2065
2036
2082
1986
2006
2002
2014
1958
1968
1959
1995
1883
1890
1956
1948
1944
1975
1928
1961
1994
1997
1997
1959
1965
1973
2004
1995
2026
1999
2000
2025
1991
1971
1944
1991
2084
2072
2000
1906
2014
2006
2016
2020
1972
1987
1974
1999
2047
2084
2049
2106
2045
2066
2078
2116
2082
2020
2063
2097
2114
2062
2100
2039
2071
2106
2085
2094
2105
2055
1999
2117
2030
2064
2149
2173
2150
2132
2143
2141
2167
2151
2122
2131
2192
2170
2145
2147
2110
2152
2249
2081
2086
2181
2194
2185
2155
2190
2224
2211
2205
2172
2175
2201
2188
2222
2193
2232
2235
2230
2219
2225
2245
2252
2241
2211
2214
2274
2266
2241
2240
2237
2247
2237
2262
2264
2214
2292
2223
2244
2247
2238
2252
2280
2255
2319
2333
2355
2429
2400
2715
3514
3430
2621
2334
2320
2361
2308
2285
2332
2322
2303
2296
2299
2299
2351
2344
2347
2306
2400
2410
2357
2318
2362
2331
2366
2332
2339
2396
2352
2370
2414
2428
2400
2384
2440
2471
2460
2384
2377
2387
2387
2363
2446
2374
2371
2456
2408
2450
2424
2436
2387
2459
2350
2469
2491
2422
2440
2480
2419
2413
2412
2398
2475
2393
2479
2541
2434
2507
2556
2411
2499
2519
2537
2522
2511
2520
2522
2517
2628
2567
2529
2535
2427
2494
2524
2490
2578
2552
2491
2578
2550
2492
2532
2522
2555
2525
2498
2494
2559
2557
2595
2543
2661
2556
2619
2656
2620
2553
2587
2589
2620
2621
2655
2594
2664
2645
2649
2599
2612
2603
2508
2505
2557
2532
2500
2429
2478
2502
2566
2673
2748
2795
2946
3014
3005
2966
2907
2895
2798
2680
2477
2324
2286
2118
2020
1871
1740
1650
1688
1565
1476
1383
1337
1444
1559
1768
3384
8565
13086
9164
3681
1498
1101
1064
1037
1051
1045
1037
1021
999
978
1016
1048
1064
1010
994
1011
1049
1024
1034
1031
1052
1044
1046
1061
1021
1054
1048
1076
1093
1034
1060
1063
1061
1074
1048
1054
1052
1085
1074
1026
1068
1037
1068
1106
1063
1049
1010
1112
1056
1026
1040
1077
1102
1093
1088
1055
1051
1096
1032
1062
1044
1062
1089
1062
1041
1034
1034
1080
1158
1118
1049
1042
1061
1070
1073
1068
1043
1066
1122
1138
1080
1062
1136
1175
1082
1075
1110
1124
1137
1048
1090
1124
1162
1133
1163
1087
1170
1133
1087
1179
1102
1191
1153
1103
1114
1097
1145
1130
1151
1125
1145
1171
1151
1102
1192
1136
1131
1172
1183
1152
1144
1198
1215
1209
1150
1161
1175
1144
1171
1253
1202
1199
1172
1139
1170
1151
1180
1223
1236
1233
1196
1128
1161
1197
1220
1170
1194
1201
1156
1228
1219
1179
1190
1253
1244
1209
1220
1243
1238
1273
1206
1231
1201
1219
1263
1234
1274
1247
1229
1231
1281
1257
1221
1248
1235
1245
1309
1317
1316
1296
1262
1348
1345
1274
1256
1209
1266
1273
1270
1338
1341
1338
1284
1227
1260
1317
1293
1329
1304
1256
1308
1310
1346
1309
1341
1304
1330
1322
1281
1313
1325
1264
1329
1302
1363
1412
1405
1384
1459
1463
1449
1508
1489
1503
1381
1283
1242
1167
1130
1058
1035
962
891
889
807
825
723
669
668
728
1014
2273
4265
5020
6399
3761
933
429
350
361
329
297
343
333
305
320
325
330
344
320
327
328
332
327
334
310
309
351
332
350
340
329
342
308
323
331
337
335
328
341
333
335
313
344
342
316
329
335
378
360
331
325
354
325
340
339
329
296
311
307
304
369
334
333
347
368
316
316
362
370
316
347
326
341
345
331
365
345
340
325
339
319
331
344
321
343
346
378
344
343
355
362
315
360
325
324
362
375
374
355
347
356
344
347
369
370
383
358
329
365
338
353
355
369
361
369
352
355
352
352
399
386
376
361
370
373
381
385
382
376
367
376
369
336
373
361
398
372
381
400
409
381
395
388
426
419
429
404
391
401
408
356
425
399
384
367
331
322
325
314
287
272
299
285
284
287
329
408
826
1393
1268
666
359
308
261
258
265
279
247
247
246
227
243
239
237
254
289
270
268
223
271
275
243
246
237
247
244
243
252
234
232
221
192
190
176
193
187
164
157
160
159
187
249
565
1204
900
310
193
145
133
132
157
144
151
145
167
158
151
155
126
145
144
136
140
162
166
159
172
193
180
136
150
176
157
170
150
154
146
144
128
140
151
160
143
162
142
130
122
146
147
158
195
271
365
426
303
209
143
107
108
132
133
167
169
131
83
93
94
105
104
80
84
94
82
86
55
13
4
3
0
0
0
1.47543
Survey/14
Not Specified
2025
2
12
13
16
42
0
8
Casa Info Follows
0
0
0
0
   XPS     Spectrum    Lens Mode:Hybrid   Res:80   Iris(Aper):slot(Slot)
   Acqn. Time(s): 241        Sweeps: 2        Anode:Mono(Al (Mono))(225 W)   Step(meV): 1000.0
   Dwell Time(ms): 100        Charge Neutraliser :On (Current 1.9 A: Balance 3.1 V: Bias 1.0 V)   Acquired On :25/02/12 13:16:42
XPS
34
2
5
Mono(Al (Mono))
1486.69
225
1e+037
1e+037
6000
6000
1e+037
1e+037
FAT
80
1e+037
-4.9
0
1e+037
1e+037
1e+037
1e+037
Wide
None
-1
Kinetic Energy
eV
286.69
1
2
Intensity
d
Transmission
d
pulse counting
0.1
0
1e+037
0
0
1.47543
2068
2061
2046
2095
2089
2095
2028
2010
2037
2130
2084
2060
2091
2022
2113
2068
2083
2145
2130
2123
2153
2136
2045
2054
2104
2068
2128
2105
2152
2147
2194
2119
2104
2135
2123
2134
2198
2171
2215
2147
2146
2207
2171
2240
2240
2183
2250
2239
2223
2206
2212
2221
2175
2177
2157
2236
2171
2213
2251
2299
2225
2237
2220
2232
2239
2316
2267
2313
2244
2245
2309
2326
2236
2329
2260
2294
2331
2317
2334
2293
2317
2340
2247
2283
2249
2332
2353
2348
2425
2378
2367
2370
2395
2365
2378
2434
2329
2358
2374
2354
2438
2391
2411
2465
2421
2394
2500
2422
2450
2490
2434
2400
2414
2470
2483
2487
2438
2511
2524
2525
2492
2497
2533
2500
2543
2486
2491
2535
2518
2541
2562
2586
2548
2515
2542
2575
2537
2637
2506
2503
2626
2627
2587
2601
2607
2607
2647
2669
2670
2631
2650
2687
2654
2667
2673
2686
2759
2758
2718
2699
2740
2805
2781
2689
2743
2772
2745
2827
2746
2720
2790
2806
2779
2798
2812
2814
2900
2893
2849
2894
2837
2848
2845
2901
2882
2902
2994
3016
2999
2901
2904
2890
2813
2931
3019
2956
2956
2946
3083
3023
3136
3194
3205
3289
3332
3230
3080
3000
2972
2945
2885
2925
2804
2793
2723
2630
2647
2616
2722
2838
2937
3164
3420
3496
3677
3876
3785
3600
3271
3052
2937
2853
2730
2434
2302
2112
1936
1768
1758
1651
1643
1664
1694
1685
1644
1607
1605
1604
1671
1619
1657
1665
1681
1675
1692
1700
1717
1687
1740
1685
1688
1740
1783
1664
1742
1742
1709
1760
1714
1732
1759
1744
1669
1736
1744
1710
1778
1773
1740
1766
1750
1726
1753
1747
1736
1724
1696
1727
1790
1769
1776
1694
1756
1808
1778
1759
1806
1817
1786
1758
1762
1750
1840
1828
1784
1772
1825
1825
1791
1746
1773
1787
1847
1815
1808
1771
1858
1865
1862
1872
1925
1908
1861
1892
1880
1866
1867
1857
1931
1921
1897
1923
1811
1879
1869
1905
1920
1949
1928
1942
1881
1971
1971
1963
1918
1990
2055
1981
1988
1944
2005
1931
1961
1997
1974
1934
1993
1987
1953
1984
2007
2006
2015
2114
2110
2131
2235
2323
2314
2298
2198
2106
2123
2101
2052
2089
2068
2082
2071
1979
2003
2040
1968
1906
1966
2001
1898
1992
2000
1985
2030
1923
1964
2040
2026
1978
2004
2011
2013
2104
2040
1999
1905
1952
1984
1961
2047
2033
2003
2102
2065
2080
1977
1999
2037
2070
2092
2120
2139
2067
2055
2038
2040
2024
2015
2089
2130
2070
2133
2175
2061
2067
2100
2059
2131
2092
2093
2050
2151
2162
2204
2154
2109
2198
2162
2208
2222
2210
2149
2109
2228
2196
2167
2180
2250
2187
2175
2160
2207
2294
2271
2224
2183
2152
2170
2152
2168
2337
2330
2306
2270
2178
2215
2269
2268
2286
2209
2310
2258
2278
2225
2250
2261
2372
2374
2306
2353
2332
2284
2319
2297
2291
2291
2281
2271
2241
2273
2298
2361
2353
2360
2254
2366
2405
2332
2297
2375
2355
2367
2272
2340
2483
2820
3565
3680
2829
2454
2439
2346
2351
2375
2356
2368
2313
2369
2323
2424
2344
2365
2397
2440
2450
2428
2438
2429
2374
2395
2402
2422
2342
2352
2412
2397
2464
2395
2474
2435
2353
2373
2429
2492
2469
2461
2548
2563
2470
2487
2488
2467
2452
2485
2441
2422
2517
2495
2483
2443
2549
2513
2399
2388
2387
2452
2485
2509
2586
2488
2491
2479
2515
2498
2567
2524
2520
2458
2563
2550
2581
2528
2610
2581
2563
2602
2567
2562
2548
2665
2686
2645
2620
2622
2609
2619
2622
2548
2617
2584
2641
2667
2649
2675
2707
2597
2597
2601
2641
2607
2608
2603
2654
2664
2633
2563
2617
2650
2718
2646
2609
2717
2698
2771
2750
2576
2602
2632
2577
2562
2640
2622
2556
2639
2691
2794
2861
2965
3046
3133
3112
3110
3067
2992
2943
2778
2544
2436
2357
2205
2117
2007
1907
1767
1704
1629
1522
1501
1451
1479
1621
1871
3310
8989
14344
10354
4244
1672
1173
1104
1062
1099
998
1054
1041
1027
1078
1082
1085
1060
1024
1040
1067
1086
1089
1042
1011
1061
1093
1040
1049
1078
1066
1071
1059
1053
1035
1083
1053
1090
1051
1083
1055
1057
1061
1056
1041
1085
1059
1011
1042
1124
1047
1070
1055
1125
1057
1058
1067
1051
1043
1070
1095
1068
1078
1082
1090
1107
1107
1114
1125
1150
1121
1099
1066
1104
1098
1144
1134
1108
1140
1118
1103
1133
1035
1090
1107
1083
1097
1121
1161
1098
1147
1066
1159
1137
1135
1118
1151
1093
1122
1117
1134
1173
1094
1139
1114
1105
1171
1179
1146
1151
1082
1140
1128
1141
1173
1176
1203
1114
1139
1193
1122
1129
1143
1143
1133
1191
1164
1158
1144
1170
1155
1196
1180
1233
1194
1215
1173
1140
1195
1200
1146
1219
1236
1166
1188
1160
1208
1218
1178
1154
1212
1233
1238
1227
1150
1278
1281
1260
1263
1246
1238
1224
1190
1263
1250
1225
1224
1221
1244
1235
1210
1205
1257
1212
1254
1290
1269
1260
1244
1283
1275
1316
1303
1302
1301
1231
1299
1352
1255
1275
1294
1325
1338
1289
1306
1308
1311
1326
1294
1362
1347
1308
1287
1349
1300
1314
1288
1272
1310
1346
1360
1325
1317
1284
1260
1294
1316
1281
1334
1350
1337
1365
1422
1434
1416
1479
1468
1509
1425
1324
1241
1271
1203
1173
1073
1005
886
842
812
847
832
727
713
657
731
953
2142
4456
4873
5882
4306
1206
451
375
378
362
319
344
343
342
301
319
334
305
337
343
335
348
332
327
320
313
323
315
328
359
370
341
352
362
366
328
313
312
322
358
323
341
324
333
335
319
319
325
342
337
348
343
333
351
326
346
314
349
341
334
377
331
342
336
357
325
337
344
380
357
329
318
371
326
336
361
362
341
346
378
334
348
326
346
360
350
380
358
373
395
384
352
360
332
370
335
348
331
362
369
358
354
378
370
352
364
388
373
354
361
356
351
370
348
357
348
367
366
348
367
369
378
401
360
389
393
384
386
352
351
367
397
372
371
430
459
395
398
392
396
414
407
447
424
407
419
434
460
442
431
398
406
373
386
371
355
325
315
298
295
292
302
290
253
268
306
409
702
1374
1515
836
416
334
259
253
274
264
246
260
244
256
251
241
243
250
271
307
301
267
252
302
273
276
281
288
245
254
260
235
222
212
200
181
190
196
173
173
164
154
139
150
210
472
1211
1088
400
187
154
140
169
121
143
162
155
147
132
156
134
148
156
160
160
142
168
167
171
158
159
173
161
181
169
167
146
167
159
166
160
167
139
151
165
143
164
135
137
118
139
123
162
204
263
409
431
374
243
148
118
112
120
140
179
164
140
90
80
91
96
108
99
90
85
83
91
73
30
5
2
2
0
0
1.47543
Survey/17
Not Specified
2025
2
12
13
22
11
0
8
Casa Info Follows
0
0
0
0
   XPS     Spectrum    Lens Mode:Hybrid   Res:80   Iris(Aper):slot(Slot)
   Acqn. Time(s): 241        Sweeps: 2        Anode:Mono(Al (Mono))(225 W)   Step(meV): 1000.0
   Dwell Time(ms): 100        Charge Neutraliser :On (Current 1.9 A: Balance 3.1 V: Bias 1.0 V)   Acquired On :25/02/12 13:22:11
XPS
35
0
6
Mono(Al (Mono))
1486.69
225
1e+037
1e+037
6000
6000
1e+037
1e+037
FAT
80
1e+037
-4.9
0
1e+037
1e+037
1e+037
1e+037
Wide
None
-1
Kinetic Energy
eV
286.69
1
2
Intensity
d
Transmission
d
pulse counting
0.1
0
1e+037
0
0
1.47543
1943
1967
2006
2010
1940
2060
2017
1982
2035
2056
1993
2024
2033
2064
2006
2042
2025
1995
1992
2073
2022
2079
2008
2015
2056
2129
2068
2060
2094
2095
2068
2047
2135
2126
2108
2089
2128
2098
2046
2035
2089
2077
2100
2101
2112
2133
2141
2108
2140
2149
2175
2136
2119
2149
2148
2137
2191
2221
2172
2205
2263
2201
2181
2210
2141
2149
2258
2293
2241
2169
2223
2213
2287
2273
2285
2260
2268
2236
2242
2214
2276
2347
2313
2276
2286
2247
2319
2314
2322
2294
2329
2330
2393
2306
2312
2323
2334
2348
2402
2438
2354
2390
2374
2450
2387
2393
2364
2287
2373
2385
2342
2453
2463
2431
2433
2386
2458
2428
2438
2415
2447
2461
2498
2489
2501
2512
2564
2467
2517
2501
2526
2511
2490
2454
2496
2522
2562
2531
2499
2520
2601
2581
2570
2625
2572
2555
2584
2486
2617
2634
2626
2597
2605
2585
2654
2615
2695
2708
2636
2630
2693
2615
2581
2680
2743
2725
2728
2751
2725
2724
2711
2712
2734
2746
2793
2787
2805
2767
2762
2898
2880
2813
2946
2895
2884
2904
2951
2989
3055
2958
2923
2856
2878
2906
2921
2866
2956
2964
2913
3017
3041
3047
3155
3282
3148
3158
3079
3053
3042
3024
2846
2752
2783
2696
2640
2662
2637
2659
2708
2779
2864
3095
3247
3330
3524
3730
3774
3563
3293
3004
2922
2712
2532
2382
2255
2058
1912
1854
1682
1652
1685
1657
1656
1693
1636
1623
1641
1593
1649
1668
1621
1651
1608
1591
1629
1634
1650
1700
1665
1613
1664
1698
1677
1744
1692
1653
1669
1679
1669
1663
1706
1606
1630
1722
1687
1688
1765
1682
1680
1610
1660
1706
1784
1709
1750
1739
1741
1665
1720
1738
1661
1673
1781
1741
1768
1718
1699
1721
1729
1769
1732
1758
1810
1742
1755
1757
1758
1825
1833
1739
1708
1815
1813
1770
1817
1793
1780
1835
1836
1820
1773
1833
1857
1864
1815
1819
1865
1840
1868
1875
1818
1813
1858
1867
1825
1867
1858
1848
1955
1900
1956
1978
1932
1902
1925
1910
1944
1935
1901
1949
1933
1871
1944
1913
1868
1950
1983
1984
2002
1981
1982
1951
2030
2014
2113
2188
2222
2248
2290
2310
2166
2069
2158
2128
2058
2016
1962
2007
1989
1960
1921
1971
1870
1914
1973
1879
1945
1981
1991
2004
1927
1897
1922
1917
1950
1971
1979
2005
1921
2026
2045
2035
2031
2003
1958
1879
2010
2062
1973
1966
1976
1985
2007
1983
2036
1918
2056
1970
1995
2041
2017
1985
2011
2071
2019
2049
2033
2062
2051
2058
2070
2033
2052
2029
2112
2079
2056
2118
2153
2027
2055
2077
2079
2120
2130
2122
2049
2132
2147
2053
2061
2132
2198
2150
2129
2081
2115
2121
2128
2104
2069
2154
2106
2200
2190
2141
2109
2120
2203
2231
2193
2173
2242
2241
2215
2196
2138
2171
2247
2144
2171
2248
2166
2219
2185
2282
2228
2134
2186
2221
2236
2279
2274
2226
2235
2215
2259
2251
2296
2259
2237
2265
2269
2245
2286
2271
2319
2306
2232
2281
2331
2459
2788
3775
3816
2847
2419
2298
2336
2321
2337
2357
2251
2325
2238
2320
2381
2321
2309
2323
2325
2291
2391
2293
2294
2302
2350
2298
2338
2319
2325
2374
2376
2363
2373
2390
2360
2321
2383
2390
2394
2422
2389
2406
2316
2368
2392
2395
2380
2389
2407
2396
2408
2454
2425
2421
2391
2417
2427
2501
2478
2425
2450
2362
2545
2517
2571
2481
2526
2476
2444
2452
2498
2484
2458
2475
2518
2587
2513
2482
2524
2573
2542
2537
2544
2518
2541
2557
2621
2566
2528
2556
2567
2527
2508
2487
2505
2560
2586
2560
2511
2614
2630
2593
2613
2553
2539
2628
2591
2633
2586
2615
2650
2641
2630
2601
2678
2611
2560
2656
2621
2566
2586
2567
2522
2572
2499
2492
2427
2532
2544
2646
2752
2774
2809
2823
3001
3058
3064
2980
2927
2747
2625
2528
2356
2295
2171
2063
1925
1824
1688
1595
1506
1477
1388
1360
1461
1608
1813
3275
8939
13973
9970
4021
1569
1119
1079
1031
999
1091
1018
1019
995
1059
1062
1048
1009
1004
1010
982
1031
1076
1034
985
1010
980
979
995
1023
1007
1017
1014
988
1021
1010
1026
1026
1024
973
1037
1030
1029
1012
1006
1014
1017
1004
1032
1053
1039
982
1017
1053
1059
1055
1084
1014
1021
1031
1015
1038
1061
1020
1040
1075
1053
1024
1033
1059
1077
1068
1065
1032
1069
1092
1070
1080
1078
1056
1081
1117
1076
1101
1113
1097
1084
1057
1073
1094
1055
1041
1077
1097
1075
1074
1119
1162
1050
1072
1088
1053
1118
1091
1084
1081
1114
1093
1117
1121
1117
1118
1101
1112
1159
1109
1131
1098
1134
1151
1072
1132
1154
1191
1179
1124
1139
1182
1151
1128
1150
1136
1154
1155
1204
1184
1123
1166
1211
1195
1141
1162
1182
1157
1188
1218
1213
1151
1150
1142
1116
1114
1140
1140
1162
1184
1145
1172
1146
1243
1227
1174
1176
1150
1219
1217
1217
1182
1195
1194
1186
1238
1236
1227
1223
1220
1219
1254
1228
1202
1243
1241
1246
1220
1232
1217
1204
1256
1266
1238
1239
1263
1267
1263
1245
1292
1307
1246
1260
1259
1246
1336
1318
1275
1242
1250
1312
1260
1248
1262
1295
1313
1332
1285
1266
1289
1285
1293
1289
1345
1363
1371
1380
1415
1433
1400
1397
1439
1342
1327
1280
1205
1187
1087
1050
960
896
893
849
840
869
751
691
615
696
954
2060
4264
4734
5601
4097
1141
459
385
372
335
297
302
321
337
341
306
313
301
339
331
304
326
352
316
321
335
306
338
319
329
313
314
324
328
335
330
327
337
341
317
325
304
336
310
364
325
329
328
294
338
334
331
338
321
337
337
333
344
339
330
319
304
333
324
294
335
344
334
346
319
333
341
360
328
314
346
352
338
345
336
358
353
344
325
358
370
337
325
385
353
358
345
351
357
331
327
348
367
355
362
355
346
354
338
353
362
350
324
344
345
345
350
364
324
371
374
347
362
365
373
377
371
366
382
363
365
371
367
373
386
366
397
382
368
374
366
365
365
390
397
383
387
369
414
399
423
415
409
423
424
417
351
369
359
341
331
315
315
315
298
299
280
246
292
291
320
378
668
1377
1493
833
410
317
282
249
227
257
246
236
232
233
252
253
244
241
235
246
274
268
266
252
262
260
265
273
235
239
232
227
202
210
191
192
163
160
182
181
161
146
149
182
169
454
1211
1084
392
169
164
131
146
140
142
158
167
146
146
147
169
145
158
144
157
152
122
168
139
159
143
159
163
159
170
160
154
161
151
145
135
153
147
160
144
147
172
149
129
122
129
129
151
161
260
335
389
368
251
151
119
123
154
149
144
169
154
84
78
106
109
116
109
92
89
92
98
69
27
4
0
2
0
1
1.47543
Survey/20
Not Specified
2025
2
12
13
27
35
0
8
Casa Info Follows
0
0
0
0
   XPS     Spectrum    Lens Mode:Hybrid   Res:80   Iris(Aper):slot(Slot)
   Acqn. Time(s): 241        Sweeps: 2        Anode:Mono(Al (Mono))(225 W)   Step(meV): 1000.0
   Dwell Time(ms): 100        Charge Neutraliser :On (Current 1.9 A: Balance 3.1 V: Bias 1.0 V)   Acquired On :25/02/12 13:27:35
XPS
58
1
7
Mono(Al (Mono))
1486.69
225
1e+037
1e+037
6000
6000
1e+037
1e+037
FAT
80
1e+037
-4.9
0
1e+037
1e+037
1e+037
1e+037
Wide
None
-1
Kinetic Energy
eV
286.69
1
2
Intensity
d
Transmission
d
pulse counting
0.1
0
1e+037
0
0
1.47543
2815
2898
2853
2825
2825
2791
2796
2814
2829
2833
2836
2841
2871
2900
2737
2877
2976
2925
2870
2881
2836
2877
2874
2924
2985
2970
2882
2908
2944
2954
2932
2946
2919
3013
2972
2981
2986
3002
3007
2971
2942
3018
3051
3053
2978
3002
3019
2978
3013
3016
2943
2959
2973
2968
3075
3075
2995
3008
3063
3126
3054
3134
3074
3083
3238
3148
3176
3173
3137
3113
3082
3104
3084
3175
3227
3214
3164
3223
3210
3286
3188
3281
3207
3095
3140
3205
3266
3209
3262
3261
3321
3271
3316
3295
3307
3279
3337
3343
3341
3342
3311
3330
3291
3258
3305
3363
3357
3408
3304
3355
3376
3386
3405
3428
3406
3369
3366
3394
3400
3495
3449
3393
3395
3410
3424
3586
3455
3528
3554
3546
3527
3597
3613
3541
3506
3486
3524
3562
3634
3578
3684
3654
3609
3600
3616
3627
3600
3584
3596
3580
3662
3612
3612
3725
3712
3577
3591
3713
3751
3830
3689
3724
3764
3781
3757
3842
3847
3775
3835
3854
3818
3833
3856
3929
3922
3969
3913
3904
4016
4022
3975
4097
4038
4134
4157
4108
4206
4208
4158
4178
4268
4078
4048
4099
4138
4210
4217
4234
4417
4504
4525
4658
4829
4852
4737
4621
4421
4345
4274
4146
4083
3962
3770
3721
3822
3758
3877
3974
4071
4329
4730
5210
5545
5998
6267
6063
5454
4823
4485
4281
3941
3676
3420
3140
2869
2527
2332
2241
2126
2090
1994
2016
2100
[...]
1084
0.349062
1124
0.349057
1152
0.349052
1083
0.349047
1129
0.349042
1049
0.349037
1130
0.349032
1110
0.349026
1065
0.349021
1141
0.349016
1105
0.349011
1142
0.349006
1143
0.349001
1104
0.348996
1142
0.348991
1093
0.348986
1151
0.348981
1103
0.348976
1076
0.348971
1142
0.348966
1194
0.348961
1172
0.348956
1193
0.348951
1231
0.348946
1294
0.348941
1268
0.348936
1334
0.348931
1405
0.348926
1443
0.348921
1515
0.348916
1504
0.348911
1540
0.348906
1610
0.348901
1598
0.348896
1702
0.34889
1674
0.348885
1747
0.34888
1763
0.348875
1785
0.34887
1860
0.348865
1812
0.34886
1751
0.348855
1756
0.34885
1826
0.348845
1782
0.34884
1661
0.348835
1670
0.34883
1638
0.348825
1646
0.34882
1584
0.348815
1529
0.34881
1568
0.348805
1579
0.3488
1579
0.348795
1544
0.34879
1471
0.348785
1480
0.34878
1463
0.348775
1541
0.34877
1523
0.348765
1508
0.34876
1485
0.348755
1585
0.348749
1605
0.348744
1577
0.348739
1759
0.348734
1731
0.348729
1774
0.348724
1830
0.348719
1896
0.348714
1964
0.348709
1980
0.348704
2131
0.348699
2132
0.348694
2239
0.348689
2380
0.348684
2407
0.348679
2508
0.348674
2593
0.348669
2681
0.348664
2833
0.348659
2930
0.348654
3073
0.348649
3258
0.348644
3469
0.348639
3608
0.348634
3796
0.348629
4063
0.348624
4250
0.348619
4482
0.348614
4558
0.348608
4721
0.348603
4804
0.348598
4817
0.348593
4933
0.348588
4895
0.348583
4715
0.348578
4659
0.348573
4342
0.348568
3939
0.348563
3675
0.348558
3434
0.348553
3019
0.348548
2765
0.348543
2397
0.348538
2137
0.348533
1886
0.348528
1700
0.348523
1486
0.348518
1361
0.348513
1335
0.348508
1192
0.348503
1174
0.348498
1124
0.348493
1085
0.348488
1019
0.348483
1007
0.348478
1064
0.348473
1004
0.348467
965
0.348462
1016
0.348457
983
0.348452
1008
0.348447
1000
0.348442
1006
0.348437
980
0.348432
1023
0.348427
1037
0.348422
1052
0.348417
993
0.348412
1008
0.348407
1045
0.348402
1005
0.348397
910
0.348392
957
0.348387
971
0.348382
971
0.348377
966
0.348372
960
0.348367
976
0.348362
973
0.348357
982
0.348352
1012
0.348347
1033
0.348342
1009
0.348337
974
0.348331
953
0.348326
961
0.348321
976
0.348316
1002
0.348311
984
0.348306
991
0.348301
962
0.348296
978
0.348291
Al 2p/50
Not Specified
2025
2
12
15
1
27
0
14
Casa Info Follows
1
Calib M = 282.84 A = 284.8 BE ADD
1
annot comps v2315 Display 0.05 0.2 RGB(0,0,0) Font(35,34,400,0,Arial)

1
CASA region (*Al 2p*) (*Tougaard*) 1408.049 1415.6396 0.5371 2 0 0 0 -450 0 0 (*Al 2p*) 26.9815 0 0.5371
2
CASA comp (*Al 2p*) (*GL(30)*) Area 5362.586 1e-020 218095.2 -1 1 MFWHM 1.6545719 0.38 9.5 -1 1 Position 1412.1139 1408.049 1415.6396 -1 1 RSF 0.5371 MASS 26.9815 INDEX -1 (*Al 2p*) CONST (**) UNCORRECTEDRSF 0.5371
CASA comp (*Al 2p*) (*GL(30)*) Area 1228.2808 1e-020 218095.2 -1 1 MFWHM 1.6545719 0.2 5 0 1 Position 1411.2095 1408.049 1415.6396 -1 1 RSF 0.5371 MASS 26.9815 INDEX -1 (*Al 2p*) CONST (**) UNCORRECTEDRSF 0.5371
   XPS     Spectrum    Lens Mode:Hybrid   Res:20   Iris(Aper):slot(Slot)
   Acqn. Time(s): 576        Sweeps: 8        Anode:Mono(Al (Mono))(225 W)   Step(meV): 100.0
   Dwell Time(ms): 298        Charge Neutraliser :On (Current 1.9 A: Balance 3.1 V: Bias 1.0 V)   Acquired On :25/02/12 15:01:27
XPS
58
1
15
Mono(Al (Mono))
1486.69
225
1e+037
1e+037
6000
6000
1e+037
1e+037
FAT
20
1e+037
-4.9
0
1e+037
1e+037
1e+037
1e+037
Al
2p
-1
Kinetic Energy
eV
1400.69
0.1
2
Intensity
d
Transmission
d
pulse counting
0.2985
8
0
1e+037
1e+037
1e+037
1
PROPAGATION_CONVERGED
d
1
482
375
8277
0.333164
0.333748
838
0.333748
761
0.333746
770
0.333744
801
0.333741
814
0.333739
792
0.333736
788
0.333734
816
0.333731
763
0.333729
714
0.333726
754
0.333724
739
0.333722
706
0.333719
730
0.333717
727
0.333714
752
0.333712
681
0.333709
692
0.333707
706
0.333705
697
0.333702
698
0.3337
692
0.333697
670
0.333695
675
0.333692
663
0.33369
684
0.333687
668
0.333685
640
0.333683
644
0.33368
596
0.333678
650
0.333675
659
0.333673
606
0.33367
648
0.333668
592
0.333666
643
0.333663
606
0.333661
598
0.333658
573
0.333656
549
0.333653
596
0.333651
613
0.333649
599
0.333646
581
0.333644
561
0.333641
557
0.333639
589
0.333636
558
0.333634
525
0.333631
525
0.333629
549
0.333627
522
0.333624
497
0.333622
534
0.333619
535
0.333617
515
0.333614
488
0.333612
473
0.333609
511
0.333607
509
0.333605
459
0.333602
468
0.3336
466
0.333597
460
0.333595
478
0.333592
471
0.33359
471
0.333588
506
0.333585
441
0.333583
440
0.33358
418
0.333578
445
0.333575
470
0.333573
445
0.333571
448
0.333568
425
0.333566
454
0.333563
431
0.333561
406
0.333558
424
0.333556
424
0.333553
397
0.333551
420
0.333549
429
0.333546
442
0.333544
447
0.333541
471
0.333539
451
0.333536
442
0.333534
437
0.333532
451
0.333529
457
0.333527
428
0.333524
425
0.333522
445
0.333519
451
0.333517
488
0.333514
458
0.333512
481
0.33351
484
0.333507
473
0.333505
451
0.333502
495
0.3335
518
0.333497
535
0.333495
557
0.333493
558
0.33349
584
0.333488
654
0.333485
682
0.333483
702
0.33348
823
0.333478
881
0.333475
1003
0.333473
1194
0.333471
1393
0.333468
1612
0.333466
1826
0.333463
2191
0.333461
2448
0.333458
2816
0.333456
3262
0.333454
3816
0.333451
4208
0.333449
4741
0.333446
5249
0.333444
5877
0.333441
6469
0.333439
6997
0.333436
7551
0.333434
7795
0.333432
8148
0.333429
8268
0.333427
8277
0.333424
8122
0.333422
7939
0.333419
7709
0.333417
7306
0.333415
6739
0.333412
6109
0.33341
5532
0.333407
4902
0.333405
4235
0.333402
3654
0.3334
3048
0.333398
2551
0.333395
2159
0.333393
1708
0.33339
1475
0.333388
1213
0.333385
965
0.333383
851
0.33338
754
0.333378
651
0.333376
582
0.333373
568
0.333371
530
0.333368
484
0.333366
469
0.333363
512
0.333361
471
0.333359
451
0.333356
466
0.333354
454
0.333351
453
0.333349
461
0.333346
479
0.333344
440
0.333341
458
0.333339
432
0.333337
429
0.333334
433
0.333332
420
0.333329
405
0.333327
422
0.333324
436
0.333322
459
0.33332
434
0.333317
419
0.333315
416
0.333312
403
0.33331
426
0.333307
429
0.333305
429
0.333302
417
0.3333
412
0.333298
414
0.333295
413
0.333293
421
0.33329
431
0.333288
434
0.333285
453
0.333283
452
0.333281
429
0.333278
452
0.333276
436
0.333273
445
0.333271
434
0.333268
433
0.333266
434
0.333263
443
0.333261
409
0.333259
437
0.333256
440
0.333254
416
0.333251
412
0.333249
386
0.333246
404
0.333244
395
0.333242
426
0.333239
401
0.333237
400
0.333234
383
0.333232
456
0.333229
421
0.333227
420
0.333225
391
0.333222
438
0.33322
419
0.333217
413
0.333215
418
0.333212
430
0.33321
407
0.333207
457
0.333205
412
0.333203
425
0.3332
421
0.333198
453
0.333195
388
0.333193
375
0.33319
423
0.333188
426
0.333186
417
0.333183
411
0.333181
392
0.333178
418
0.333176
427
0.333173
449
0.333171
429
0.333168
426
0.333166
410
0.333164
O 1s/53
Not Specified
2025
2
12
15
13
12
0
13
Casa Info Follows
1
Calib M = 282.26 A = 284.8 BE ADD
0
1
CASA region (*O 1s*) (*Shirley*) 951.21698 958.52456 2.93 2 0 0 0 -450 0 0 (*O 1s*) 15.9994 0 2.93
3
CASA comp (*O 1s*) (*GL(30)*) Area 28639.775 1e-020 467977.66 -1 1 MFWHM 1.8058308 0.46 11.5 -1 1 Position 954.63557 951.21698 958.52456 -1 1 RSF 2.93 MASS 15.9994 INDEX -1 (*O 1s*) CONST (**) UNCORRECTEDRSF 2.93
CASA comp (*O 1s*) (*GL(30)*) Area 9818.3627 1e-020 467977.66 -1 1 MFWHM 1.8058308 0.19891304 4.9728261 0 1 Position 955.79057 951.21698 958.52456 -1 1 RSF 2.93 MASS 15.9994 INDEX -1 (*O 1s*) CONST (**) UNCORRECTEDRSF 2.93
CASA comp (*O 1s*) (*LA(50)*) Area 1254.841 1e-020 467977.66 -1 1 MFWHM 1.8058308 0.77577136 19.394284 0 1 Position 953.17929 951.21698 958.52456 -1 1 RSF 2.93 MASS 15.9994 INDEX -1 (*O 1s*) CONST (**) UNCORRECTEDRSF 2.93
   XPS     Spectrum    Lens Mode:Hybrid   Res:20   Iris(Aper):slot(Slot)
   Acqn. Time(s): 244        Sweeps: 4        Anode:Mono(Al (Mono))(225 W)   Step(meV): 100.0
   Dwell Time(ms): 332        Charge Neutraliser :On (Current 1.9 A: Balance 3.1 V: Bias 1.0 V)   Acquired On :25/02/12 15:13:12
XPS
87
0
16
Mono(Al (Mono))
1486.69
225
1e+037
1e+037
6000
6000
1e+037
1e+037
FAT
20
1e+037
-4.9
0
1e+037
1e+037
1e+037
1e+037
O
1s
-1
Kinetic Energy
eV
943.69
0.1
2
Intensity
d
Transmission
d
pulse counting
0.3315
4
0
1e+037
1e+037
1e+037
1
PROPAGATION_CONVERGED
d
1
368
1287
23524
0.358325
0.359889
2734
0.359889
2713
0.35988
2850
0.359872
2638
0.359863
2711
0.359854
2715
0.359846
2616
0.359837
2591
0.359829
2612
0.35982
2608
0.359812
2630
0.359803
2574
0.359795
2596
0.359786
2556
0.359778
2543
0.359769
2519
0.35976
2464
0.359752
2460
0.359743
2405
0.359735
2451
0.359726
2407
0.359718
2427
0.359709
2376
0.359701
2423
0.359692
2340
0.359684
2356
0.359675
2367
0.359666
2246
0.359658
2253
0.359649
2277
0.359641
2192
0.359632
2177
0.359624
2149
0.359615
2174
0.359607
2130
0.359598
2192
0.359589
2163
0.359581
2147
0.359572
2177
0.359564
2198
0.359555
2101
0.359547
2098
0.359538
2063
0.35953
2056
0.359521
2020
0.359513
1994
0.359504
1936
0.359495
1943
0.359487
1908
0.359478
1934
0.35947
1964
0.359461
1902
0.359453
1856
0.359444
1949
0.359436
1900
0.359427
1841
0.359419
1839
0.35941
1870
0.359401
1821
0.359393
1811
0.359384
1821
0.359376
1687
0.359367
1731
0.359359
1841
0.35935
1728
0.359342
1664
0.359333
1734
0.359325
1653
0.359316
1633
0.359307
1626
0.359299
1627
0.35929
1612
0.359282
1576
0.359273
1634
0.359265
1564
0.359256
1629
0.359248
1603
0.359239
1551
0.359231
1656
0.359222
1573
0.359213
1616
0.359205
1598
0.359196
1626
0.359188
1587
0.359179
1543
0.359171
1526
0.359162
1562
0.359154
1534
0.359145
1611
0.359137
1556
0.359128
1592
0.359119
1521
0.359111
1607
0.359102
1615
0.359094
1630
0.359085
1619
0.359077
1611
0.359068
1614
0.35906
1604
0.359051
1653
0.359043
1652
0.359034
1616
0.359025
1687
0.359017
1723
0.359008
1732
0.359
1815
0.358991
1902
0.358983
1926
0.358974
1949
0.358966
2117
0.358957
2231
0.358949
2320
0.35894
2488
0.358931
2717
0.358923
2986
0.358914
3278
0.358906
3539
0.358897
3941
0.358889
4580
0.35888
5075
0.358872
5675
0.358863
6489
0.358855
7564
0.358846
8516
0.358837
9832
0.358829
11167
0.35882
12584
0.358812
13957
0.358803
15607
0.358795
16949
0.358786
18505
0.358778
19673
0.358769
20936
0.358761
22184
0.358752
23233
0.358743
23524
0.358735
23470
0.358726
23401
0.358718
22834
0.358709
22483
0.358701
21631
0.358692
20654
0.358684
19702
0.358675
18616
0.358667
17388
0.358658
16159
0.358649
15159
0.358641
13839
0.358632
12592
0.358624
11462
0.358615
10556
0.358607
9510
0.358598
8608
0.35859
7595
0.358581
6688
0.358573
5970
0.358564
5234
0.358555
4678
0.358547
4002
0.358538
3528
0.35853
3095
0.358521
2716
0.358513
2389
0.358504
2163
0.358496
2039
0.358487
1953
0.358478
1729
0.35847
1666
0.358461
1628
0.358453
1549
0.358444
1539
0.358436
1460
0.358427
1493
0.358419
1469
0.35841
1437
0.358402
1431
0.358393
1369
0.358384
1382
0.358376
1356
0.358367
1358
0.358359
1287
0.35835
1347
0.358342
1295
0.358333
1357
0.358325
C 1s/54
Not Specified
2025
2
12
15
18
17
0
17
Casa Info Follows
1
Calib M = 282.26 A = 284.8 BE ADD
1
annot comps v2315 Display 0.05 0.2 RGB(0,0,0) Font(35,34,400,0,Arial)

1
CASA region (*C 1s*) (*Shirley*) 1194.742 1206.0818 1 2 0 0 0 -450 0 0 (*C 1s*) 12.011 0 1
5
CASA comp (*C 1s*) (*GL(30)*) Area 2053.0085 1e-020 234887.73 -1 1 MFWHM 1.4384018 0.34 8.5 -1 1 Position 1200.3721 1194.742 1206.0818 -1 1 RSF 1 MASS 12.011 INDEX -1 (*C 1s*) CONST (**) UNCORRECTEDRSF 1
CASA comp (*C 1s*) (*GL(30)*) Area 8585.3552 0 234887.7 -1 1 MFWHM 1.4384018 0.34 8.5 0 1 Position 1201.8939 1194.742 1206.0818 -1 1 RSF 1 MASS 12.011 INDEX -1 (*C 1s*) CONST (**) UNCORRECTEDRSF 1
CASA comp (*C 1s*) (*GL(30)*) Area 554.18345 1e-020 234887.73 -1 1 MFWHM 1.4384018 0.60610572 15.152643 0 1 Position 1197.6816 1194.742 1206.0818 -1 1 RSF 1 MASS 12.011 INDEX -1 (*C 1s*) CONST (**) UNCORRECTEDRSF 1
CASA comp (*C 1s*) (*GL(30)*) Area 718.24213 1e-020 234887.73 -1 1 MFWHM 1.4384018 0.45247737 11.311934 0 1 Position 1199.2068 1194.742 1206.0818 -1 1 RSF 1 MASS 12.011 INDEX -1 (*C 1s*) CONST (**) UNCORRECTEDRSF 1
CASA comp (*C 1s*) (*GL(30)*) Area 216.86757 1e-020 234887.73 -1 1 MFWHM 1.4384018 0.38684956 9.6712391 0 1 Position 1196.4192 1194.742 1206.0818 -1 1 RSF 1 MASS 12.011 INDEX -1 (*C 1s*) CONST (**) UNCORRECTEDRSF 1
   XPS     Spectrum    Lens Mode:Hybrid   Res:20   Iris(Aper):slot(Slot)
   Acqn. Time(s): 362        Sweeps: 6        Anode:Mono(Al (Mono))(225 W)   Step(meV): 100.0
   Dwell Time(ms): 260        Charge Neutraliser :On (Current 1.9 A: Balance 3.1 V: Bias 1.0 V)   Acquired On :25/02/12 15:18:17
XPS
87
0
16
Mono(Al (Mono))
1486.69
225
1e+037
1e+037
6000
6000
1e+037
1e+037
FAT
20
1e+037
-4.9
0
1e+037
1e+037
1e+037
1e+037
C
1s
-1
Kinetic Energy
eV
1186.69
0.1
2
Intensity
d
Transmission
d
pulse counting
0.2597
6
0
1e+037
1e+037
1e+037
1
PROPAGATION_CONVERGED
d
1
464
1219
10061
0.348291
0.349292
1885
0.349254
1851
0.349255
1906
0.349256
1923
0.349257
1857
0.349258
1907
0.34926
1930
0.349261
1859
0.349262
1914
0.349263
1918
0.349264
1897
0.349266
1887
0.349267
1912
0.349268
1928
0.349269
1850
0.34927
1820
0.349272
1784
0.349273
1844
0.349274
1869
0.349275
1795
0.349276
1802
0.349278
1784
0.349279
1815
0.34928
1775
0.349281
1824
0.349282
1756
0.349284
1780
0.349285
1789
0.349286
1791
0.349287
1752
0.349289
1770
0.34929
1811
0.349291
1772
0.349292
1742
0.349288
1795
0.349283
1745
0.349278
1710
0.349273
1789
0.349268
1742
0.349263
1726
0.349258
1751
0.349253
1760
0.349248
1792
0.349243
1695
0.349238
1701
0.349233
1698
0.349228
1757
0.349223
1656
0.349218
1636
0.349213
1675
0.349208
1738
0.349203
1661
0.349198
1658
0.349193
1643
0.349188
1657
0.349183
1640
0.349178
1538
0.349173
1594
0.349167
1630
0.349162
1576
0.349157
1659
0.349152
1628
0.349147
1561
0.349142
1640
0.349137
1599
0.349132
1579
0.349127
1616
0.349122
1628
0.349117
1561
0.349112
1572
0.349107
1611
0.349102
1550
0.349097
1520
0.349092
1567
0.349087
1570
0.349082
1572
0.349077
1518
0.349072
1544
0.349067
1592
0.349062
1544
0.349057
1543
0.349052
1541
0.349047
1502
0.349042
1461
0.349037
1567
0.349032
1521
0.349026
1582
0.349021
1562
0.349016
1490
0.349011
1518
0.349006
1512
0.349001
1483
0.348996
1576
0.348991
1479
0.348986
1520
0.348981
1517
0.348976
1497
0.348971
1510
0.348966
1496
0.348961
1450
0.348956
1463
0.348951
1504
0.348946
1459
0.348941
1496
0.348936
1524
0.348931
1493
0.348926
1427
0.348921
1492
0.348916
1458
0.348911
1544
0.348906
1493
0.348901
1512
0.348896
1503
0.34889
1545
0.348885
1560
0.34888
1547
0.348875
1591
0.34887
1664
0.348865
1664
0.34886
1644
0.348855
1695
0.34885
1720
0.348845
1792
0.34884
1694
0.348835
1802
0.34883
1839
0.348825
1783
0.34882
1847
0.348815
1926
0.34881
1923
0.348805
1953
0.3488
2015
0.348795
2002
0.34879
2076
0.348785
2085
0.34878
2113
0.348775
2037
0.34877
2020
0.348765
2078
0.34876
2090
0.348755
2054
0.348749
2048
0.348744
2062
0.348739
2099
0.348734
2183
0.348729
2145
0.348724
2184
0.348719
2268
0.348714
2362
0.348709
2330
0.348704
2557
0.348699
2663
0.348694
2665
0.348689
2797
0.348684
2972
0.348679
3061
0.348674
3135
0.348669
3300
0.348664
3604
0.348659
3698
0.348654
3748
0.348649
3967
0.348644
4079
0.348639
4121
0.348634
4409
0.348629
4566
0.348624
4785
0.348619
5016
0.348614
5485
0.348608
5924
0.348603
6356
0.348598
7051
0.348593
7712
0.348588
8410
0.348583
8921
0.348578
9560
0.348573
9841
0.348568
9966
0.348563
10061
0.348558
9765
0.348553
9236
0.348548
8633
0.348543
7765
0.348538
6861
0.348533
6113
0.348528
5243
0.348523
4525
0.348518
3789
0.348513
3236
0.348508
2895
0.348503
2539
0.348498
2220
0.348493
2003
0.348488
1790
0.348483
1674
0.348478
1559
0.348473
1458
0.348467
1492
0.348462
1414
0.348457
1411
0.348452
1386
0.348447
1329
0.348442
1406
0.348437
1387
0.348432
1341
0.348427
1294
0.348422
1348
0.348417
1344
0.348412
1274
0.348407
1300
0.348402
1305
0.348397
1243
0.348392
1285
0.348387
1351
0.348382
1302
0.348377
1257
0.348372
1361
0.348367
1302
0.348362
1320
0.348357
1294
0.348352
1219
0.348347
1303
0.348342
1284
0.348337
1252
0.348331
1252
0.348326
1275
0.348321
1253
0.348316
1308
0.348311
1261
0.348306
1282
0.348301
1319
0.348296
1269
0.348291
Al 2p/55
Not Specified
2025
2
12
15
25
40
0
13
Casa Info Follows
1
Calib M = 282.26 A = 284.8 BE ADD
1
annot comps v2315 Display 0.05 0.2 RGB(0,0,0) Font(35,34,400,0,Arial)

1
CASA region (*Al 2p*) (*Tougaard*) 1408.8426 1415.31 0.5371 2 0 0 0 -450 0 0 (*Al 2p*) 26.9815 0 0.5371
1
CASA comp (*Al 2p*) (*GL(30)*) Area 3385.1957 1e-020 120896.28 -1 1 MFWHM 1.5206822 0.34 8.5 -1 1 Position 1412.1091 1408.8426 1415.31 -1 1 RSF 0.5371 MASS 26.9815 INDEX -1 (*Al 2p*) CONST (**) UNCORRECTEDRSF 0.5371
   XPS     Spectrum    Lens Mode:Hybrid   Res:20   Iris(Aper):slot(Slot)
   Acqn. Time(s): 576        Sweeps: 8        Anode:Mono(Al (Mono))(225 W)   Step(meV): 100.0
   Dwell Time(ms): 298        Charge Neutraliser :On (Current 1.9 A: Balance 3.1 V: Bias 1.0 V)   Acquired On :25/02/12 15:25:40
XPS
87
0
16
Mono(Al (Mono))
1486.69
225
1e+037
1e+037
6000
6000
1e+037
1e+037
FAT
20
1e+037
-4.9
0
1e+037
1e+037
1e+037
1e+037
Al
2p
-1
Kinetic Energy
eV
1400.69
0.1
2
Intensity
d
Transmission
d
pulse counting
0.2985
8
0
1e+037
1e+037
1e+037
1
PROPAGATION_CONVERGED
d
1
482
325
5192
0.333164
0.333748
590
0.333748
566
0.333746
573
0.333744
573
0.333741
564
0.333739
603
0.333736
592
0.333734
544
0.333731
558
0.333729
577
0.333726
548
0.333724
535
0.333722
524
0.333719
522
0.333717
544
0.333714
512
0.333712
540
0.333709
523
0.333707
539
0.333705
515
0.333702
548
0.3337
566
0.333697
497
0.333695
502
0.333692
474
0.33369
521
0.333687
527
0.333685
481
0.333683
487
0.33368
510
0.333678
481
0.333675
481
0.333673
468
0.33367
470
0.333668
471
0.333666
487
0.333663
479
0.333661
480
0.333658
434
0.333656
441
0.333653
443
0.333651
470
0.333649
475
0.333646
442
0.333644
454
0.333641
440
0.333639
492
0.333636
417
0.333634
403
0.333631
439
0.333629
430
0.333627
448
0.333624
422
0.333622
445
0.333619
414
0.333617
389
0.333614
446
0.333612
443
0.333609
429
0.333607
479
0.333605
432
0.333602
442
0.3336
436
0.333597
398
0.333595
417
0.333592
425
0.33359
419
0.333588
392
0.333585
420
0.333583
391
0.33358
383
0.333578
388
0.333575
421
0.333573
396
0.333571
376
0.333568
402
0.333566
376
0.333563
374
0.333561
382
0.333558
374
0.333556
371
0.333553
402
0.333551
389
0.333549
392
0.333546
350
0.333544
386
0.333541
388
0.333539
388
0.333536
415
0.333534
365
0.333532
379
0.333529
391
0.333527
398
0.333524
396
0.333522
400
0.333519
394
0.333517
395
0.333514
356
0.333512
383
0.33351
415
0.333507
380
0.333505
361
0.333502
407
0.3335
421
0.333497
371
0.333495
380
0.333493
389
0.33349
392
0.333488
359
0.333485
419
0.333483
401
0.33348
383
0.333478
435
0.333475
433
0.333473
401
0.333471
432
0.333468
445
0.333466
461
0.333463
464
0.333461
497
0.333458
551
0.333456
559
0.333454
561
0.333451
674
0.333449
774
0.333446
875
0.333444
985
0.333441
1182
0.333439
1428
0.333436
1725
0.333434
1963
0.333432
2456
0.333429
2794
0.333427
3270
0.333424
3689
0.333422
4196
0.333419
4603
0.333417
4894
0.333415
5105
0.333412
5192
0.33341
5181
0.333407
5050
0.333405
4972
0.333402
4676
0.3334
4278
0.333398
3897
0.333395
3367
0.333393
2899
0.33339
2476
0.333388
2060
0.333385
1728
0.333383
1499
0.33338
1173
0.333378
956
0.333376
799
0.333373
668
0.333371
585
0.333368
525
0.333366
482
0.333363
447
0.333361
403
0.333359
414
0.333356
410
0.333354
363
0.333351
399
0.333349
397
0.333346
367
0.333344
361
0.333341
396
0.333339
375
0.333337
355
0.333334
370
0.333332
371
0.333329
354
0.333327
390
0.333324
377
0.333322
367
0.33332
355
0.333317
374
0.333315
389
0.333312
386
0.33331
352
0.333307
351
0.333305
371
0.333302
367
0.3333
358
0.333298
366
0.333295
375
0.333293
382
0.33329
374
0.333288
370
0.333285
400
0.333283
406
0.333281
381
0.333278
362
0.333276
377
0.333273
325
0.333271
376
0.333268
374
0.333266
354
0.333263
369
0.333261
388
0.333259
348
0.333256
345
0.333254
393
0.333251
346
0.333249
374
0.333246
368
0.333244
381
0.333242
369
0.333239
377
0.333237
389
0.333234
360
0.333232
373
0.333229
390
0.333227
372
0.333225
328
0.333222
346
0.33322
374
0.333217
385
0.333215
373
0.333212
382
0.33321
337
0.333207
363
0.333205
341
0.333203
395
0.3332
377
0.333198
388
0.333195
356
0.333193
369
0.33319
344
0.333188
374
0.333186
369
0.333183
359
0.333181
336
0.333178
370
0.333176
378
0.333173
354
0.333171
371
0.333168
363
0.333166
363
0.333164
end of experiment