File: 06_XPS_Analysis/data/raw/XPS/03172025_DuncanReece_RIT2764.vms
VAMAS Surface Chemical Analysis Standard Data Transfer Format 1988 May 4
Not Specified
Kratos Axis
Not Specified
/C=/data/2025/03-2025/03172025_DuncanReece_RIT2764.dset
0
MAP
REGULAR
4
17
32768
32768
1
Angle
degree
0
0
0
0
24
Survey/2
Not Specified
2025
3
17
14
24
35
0
3
   XPS     Spectrum    Lens Mode:Hybrid   Res:80   Iris(Aper):slot(Slot)
   Acqn. Time(s): 241        Sweeps: 2        Anode:Mono(Al (Mono))(225 W)   Step(meV): 1000.0
   Dwell Time(ms): 100        Charge Neutraliser :On (Current 1.9 A: Balance 3.1 V: Bias 1.1 V)   Acquired On :25/03/17 14:24:35
XPS
9.418
4.452
1
Mono(Al (Mono))
1486.69
225
1E+37
1E+37
6000
6000
1E+37
1E+37
FAT
80
1E+37
-4.9
0
1E+37
1E+37
1E+37
1E+37
Wide
None
-1
Kinetic Energy
eV
286.69
1
2
Intensity
d
Transmission
d
pulse counting
0.1
0
1E+37
0
0
1.47543
2826
2909
2786
2740
2838
2817
2913
2871
2839
2960
2925
2874
2837
2865
2806
2891
2898
2783
2867
2830
2814
2804
2793
2875
2804
2873
2980
2899
2861
2837
2916
2976
2888
2937
2919
2870
2972
2952
3002
2962
2932
2958
2928
2986
2956
3008
3052
2947
2988
3004
3007
2988
3020
3095
3010
3012
2956
3063
3032
2965
3046
3122
3079
3066
3122
3078
3056
3173
3121
3207
3116
3123
3156
3164
3130
3213
3119
3173
3121
3116
3188
3215
3199
3165
3200
3174
3166
3286
3164
3237
3206
3174
3304
3154
3184
3222
3318
3357
3346
3273
3266
3275
3305
3289
3305
3387
3362
3328
3405
3355
3369
3359
3339
3300
3418
3406
3430
3419
3416
3501
3488
3406
3430
3526
3542
3483
3515
3398
3507
3479
3502
3588
3594
3549
3565
3566
3503
3473
3531
3494
3531
3563
3618
3651
3702
3685
3595
3599
3687
3686
3706
3767
3596
3684
3730
3722
3617
3666
3740
3723
3768
3759
3787
3716
3795
3801
3833
3856
3850
3818
3772
3900
3896
3854
3836
3804
3774
3916
3995
3870
3879
3932
4056
3999
3969
4014
4062
4059
4034
4066
4063
3949
3978
4012
3906
3926
3973
4041
4013
4138
4251
4267
4369
4626
4677
4515
4356
4116
3969
3848
3797
3716
3481
3484
3370
3273
3306
3307
3331
3490
3814
4102
4629
4994
5360
5256
4983
4430
3944
3623
3540
3353
3180
3003
2730
2590
2369
2188
2136
2112
2076
2086
2114
2086
2052
2072
2010
1976
2032
2083
2114
2124
2073
2100
2032
2032
2017
2052
2087
2056
2102
2083
2113
2103
2173
2127
2097
2120
2118
2136
2119
2184
2111
2140
2094
2093
2045
2085
2159
2167
2134
2188
2184
2170
2163
2156
2222
2218
2162
2106
2199
2102
2144
2201
2140
2178
2182
2163
2117
2195
2174
2160
2192
2176
2186
2199
2167
2227
2237
2195
2290
2192
2256
2211
2202
2243
2206
2202
2249
2237
2296
2303
2313
2195
2271
2271
2215
2249
2250
2313
2301
2308
2265
2283
2285
2348
2303
2323
2316
2285
2247
2341
2318
2345
2324
2356
2338
2336
2347
2306
2371
2378
2350
2358
2376
2332
2343
2407
2355
2379
2392
2275
2323
2337
2413
2373
2432
2392
2419
2445
2397
2363
2379
2438
2432
2404
2390
2396
2372
2407
2443
2434
2424
2473
2490
2405
2426
2431
2394
2501
2499
2467
2459
2403
2494
2557
2504
2493
2495
2534
2491
2446
2531
2541
2477
2485
2516
2608
2606
2559
2531
2524
2484
2511
2525
2560
2525
2584
2576
2503
2569
2580
2529
2601
2508
2593
2649
2603
2631
2559
2568
2677
2586
2567
2642
2659
2579
2592
2600
2659
2585
2666
2611
2605
2709
2676
2703
2604
2654
2746
2678
2646
2674
2717
2656
2729
2709
2683
2627
2673
2773
2674
2707
2658
2701
2701
2694
2785
2762
2743
2740
2727
2767
2761
2772
2794
2772
2738
2851
2858
2934
2782
2863
2839
2786
2906
2830
2836
2823
2848
2853
2844
2880
2900
2817
2868
2900
2959
2953
2971
2964
2958
2914
2906
2929
2911
2935
2904
2894
2862
2941
2953
2987
2944
2898
2881
2914
2966
3061
3062
3027
2994
2962
3051
3007
3011
3012
2958
2958
3041
3031
3070
3034
3027
3080
3073
3030
3019
3007
2996
3072
3061
3123
3117
3059
3185
3108
3079
3063
3146
3053
3141
3072
3182
3181
3132
3141
3094
3158
3181
3093
3147
3155
3158
3192
3142
3180
3190
3176
3221
3151
3135
3279
3297
3238
3191
3274
3234
3241
3273
3298
3281
3239
3240
3287
3270
3324
3294
3284
3354
3274
3372
3326
3314
3263
3308
3376
3371
3339
3347
3343
3406
3306
3329
3332
3402
3392
3377
3278
3329
3434
3498
3365
3358
3400
3412
3438
3474
3475
3385
3513
3488
3482
3589
3556
3589
3507
3539
3496
3528
3444
3488
3474
3368
3335
3388
3301
3211
3198
3182
3252
3339
3440
3564
3727
3884
4115
4327
4337
4436
4255
4103
3810
3516
3214
2899
2665
2510
2365
2265
1992
1798
1614
1435
1245
1178
1162
1200
1540
2634
7105
17136
21192
10645
2727
1151
964
878
839
824
853
820
769
816
819
794
818
805
792
814
790
787
838
828
812
768
810
814
800
802
798
798
809
828
855
889
867
827
834
786
830
791
763
807
809
788
805
825
826
832
790
799
878
852
847
810
823
790
816
814
820
821
822
850
791
860
836
870
811
824
821
824
806
803
797
800
799
825
848
854
841
817
850
816
783
898
819
844
864
866
851
878
873
892
899
915
853
897
882
794
846
868
827
887
885
846
843
864
884
858
885
863
869
873
827
887
903
800
864
846
857
860
837
874
875
876
874
898
840
829
895
890
902
899
951
925
916
913
871
875
875
878
862
887
898
874
912
907
936
898
902
882
883
913
942
940
911
908
922
958
927
944
914
928
915
934
942
922
876
915
940
923
959
956
965
929
995
949
950
964
966
1024
1071
1103
1031
1121
1185
1014
953
959
939
911
990
1005
995
1025
945
983
1000
1037
1016
1007
1025
1035
1024
1071
1023
1029
1031
1039
1102
1041
1083
1107
1119
1065
1138
1116
1110
1095
1098
1075
1096
1126
1145
1133
1172
1099
1139
1147
1145
1069
1057
1054
1023
1023
1037
1008
967
958
1003
957
964
1063
1202
1206
1549
2946
4886
2840
1088
903
896
909
896
876
876
855
845
889
873
853
865
909
921
886
885
871
917
892
900
879
906
868
861
918
906
934
879
933
897
942
908
940
894
889
885
898
920
912
931
914
856
907
953
903
929
919
906
924
918
957
903
947
958
1005
979
956
928
912
911
900
976
925
964
952
893
912
958
964
964
971
945
918
945
921
969
956
921
943
940
997
1003
973
977
986
988
960
938
956
938
922
921
929
923
932
939
1008
964
962
990
1024
1004
986
1007
1011
1060
1042
991
1036
1008
975
1034
1065
1073
1080
1023
1052
1033
1097
1067
1054
1067
1054
1061
1071
1008
984
1005
1060
1087
1055
1085
1080
1082
1085
1117
1168
1190
1247
1236
1254
1268
1184
1148
1136
1033
1007
956
908
920
836
809
767
781
700
658
657
698
720
823
1179
2315
4388
4394
2298
1146
816
690
669
622
557
571
553
567
567
567
554
541
553
598
632
617
601
671
681
695
663
627
615
582
575
538
508
499
472
385
359
321
299
262
250
250
231
242
299
439
1463
3812
3091
866
294
209
203
203
184
209
203
208
200
194
221
208
181
200
196
190
204
220
189
203
230
237
242
249
265
240
251
235
225
225
192
179
175
149
167
173
144
172
163
149
152
170
169
187
209
298
383
595
758
715
440
213
112
86
64
75
61
61
64
49
85
181
190
147
196
186
193
157
73
15
8
1
2
0
0
1.47543
Survey/5
Not Specified
2025
3
17
14
30
7
0
3
   XPS     Spectrum    Lens Mode:Hybrid   Res:80   Iris(Aper):slot(Slot)
   Acqn. Time(s): 241        Sweeps: 2        Anode:Mono(Al (Mono))(225 W)   Step(meV): 1000.0
   Dwell Time(ms): 100        Charge Neutraliser :On (Current 1.9 A: Balance 3.1 V: Bias 1.1 V)   Acquired On :25/03/17 14:30:07
XPS
10.786
3.691
2
Mono(Al (Mono))
1486.69
225
1E+37
1E+37
6000
6000
1E+37
1E+37
FAT
80
1E+37
-4.9
0
1E+37
1E+37
1E+37
1E+37
Wide
None
-1
Kinetic Energy
eV
286.69
1
2
Intensity
d
Transmission
d
pulse counting
0.1
0
1E+37
0
0
1.47543
2655
2622
2697
2733
2783
2708
2678
2760
2777
2764
2718
2720
2743
2699
2664
2755
2746
2716
2731
2697
2717
2718
2706
2715
2757
2775
2773
2726
2694
2725
2787
2791
2771
2786
2811
2821
2801
2845
2803
2866
2852
2821
2788
2851
2814
2869
2869
2872
2874
2863
2841
2832
2913
2772
2791
2922
2880
2907
2818
2924
2915
2936
2956
2932
2910
3009
2987
2971
2962
3020
2906
2993
2879
2946
3026
3022
3089
3094
3014
3061
3098
3060
3080
3087
2973
2968
3042
3057
3013
3049
3025
3065
3067
3167
3127
3187
3150
3125
3094
3108
3145
3153
3125
3166
3162
3191
3143
3164
3174
3230
3194
3208
3255
3248
3185
3215
3184
3179
3243
3246
3322
3247
3306
3263
3265
3270
3290
3301
3309
3239
3377
3432
3377
3354
3326
3349
3414
3418
3388
3264
3399
3416
3410
3397
3308
3366
3484
3449
3329
3384
3301
3454
3450
3380
3386
3460
3445
3547
3480
3546
3607
3565
3556
3562
3586
3614
3603
3551
3618
3617
3521
3565
3652
3575
3621
3673
3570
3551
3626
3632
3767
3813
3713
3706
3709
3745
3741
3819
3816
3774
3831
3858
3664
3743
3635
3645
3672
3665
3688
3879
3908
3959
4058
4191
4240
4122
3958
3826
3718
3714
3540
3415
3331
3246
3100
3100
3103
3083
3119
3284
3470
3772
4148
4583
4719
4774
4595
4096
3596
3489
3294
3142
2931
2801
2596
2437
2225
2218
2063
2021
2013
1973
1976
1975
1940
1975
1951
1964
1959
2046
2028
2015
2000
1967
1998
1987
2025
2003
1949
1978
2006
2018
2010
2015
2019
2028
2128
2080
1919
2054
2058
2074
2061
2029
2020
2031
2068
2107
2070
2018
2091
2057
2046
2100
2097
2114
2097
2102
2101
2091
2092
2069
2147
2059
2050
2120
2142
2109
2111
2040
2089
2079
2090
2118
2158
2117
2116
2036
2049
2115
2166
2189
2206
2169
2187
2132
2141
2125
2173
2166
2164
2204
2213
2206
2213
2249
2229
2192
2201
2207
2197
2200
2210
2141
2184
2213
2202
2151
2230
2227
2244
2285
2243
2242
2310
2270
2257
2313
2221
2346
2231
2263
2331
2308
2274
2345
2298
2320
2265
2266
2373
2360
2270
2255
2318
2297
2270
2294
2312
2322
2370
2332
2371
2396
2326
2337
2370
2383
2395
2405
2364
2367
2351
2321
2357
2358
2328
2326
2378
2367
2412
2380
2354
2413
2360
2471
2334
2367
2419
2338
2370
2419
2409
2428
2424
2418
2401
2489
2451
2456
2413
2456
2449
2424
2447
2448
2459
2477
2399
2542
2494
2573
2483
2541
2489
2537
2503
2593
2510
2486
2501
2495
2520
2510
2501
2458
2506
2507
2562
2592
2541
2573
2596
2593
2528
2539
2620
2625
2575
2560
2644
2564
2511
2572
2606
2596
2579
2636
2572
2597
2655
2558
2613
2693
2626
2655
2650
2668
2703
2655
2680
2626
2658
2686
2628
2637
2710
2783
2733
2691
2754
2775
2756
2751
2796
2754
2705
2785
2704
2756
2744
2752
2748
2749
2774
2788
2758
2738
2763
2701
2787
2756
2795
2825
2788
2776
2846
2755
2802
2826
2819
2844
2847
2815
2803
2930
2856
2869
2865
2893
2793
2798
2922
2916
2845
2892
2849
2887
2941
2861
2784
2881
2969
2964
2884
2856
2910
2956
2964
2857
2962
3047
3030
3001
3010
2923
2955
2925
2945
2968
2927
3013
2958
2989
3056
3045
3006
3044
2967
3043
3020
2960
3049
3101
3096
3131
3087
3051
3105
3114
3070
3107
3125
3078
3089
3095
3049
3084
3097
2984
3088
3082
3082
3152
3195
3201
3090
3094
3118
3102
3198
3185
3215
3145
3128
3149
3150
3070
3145
3066
3061
3097
3121
3115
3104
3150
3174
3172
3225
3186
3158
3190
3244
3340
3252
3161
3224
3314
3322
3275
3333
3281
3252
3281
3277
3391
3317
3232
3178
3114
3209
3278
3176
3194
3172
3139
2990
3082
3013
2975
3018
3096
3177
3340
3466
3634
3735
4031
4075
4051
3974
3801
3500
3240
2949
2709
2571
2375
2240
2065
1972
1782
1528
1399
1241
1115
1056
1207
1467
2361
6341
15229
18745
9709
2674
1112
930
877
810
822
841
817
828
783
845
773
831
758
790
787
776
787
841
799
808
777
821
801
779
781
822
808
796
840
837
799
830
875
808
795
812
747
809
803
784
792
858
788
804
796
820
829
826
756
768
790
784
793
780
795
836
856
813
829
811
865
862
818
843
865
829
842
807
801
809
842
848
762
888
805
820
827
840
839
823
836
863
856
840
866
827
869
857
927
934
931
891
907
872
864
801
858
830
844
856
851
832
867
868
878
842
873
910
828
857
839
876
865
903
871
854
856
900
875
918
852
876
862
896
882
898
904
936
1004
957
860
824
840
905
847
843
862
877
882
872
901
932
921
910
906
928
918
914
913
973
937
943
935
926
982
913
894
943
934
978
945
991
1021
920
979
963
925
984
955
965
945
1012
993
1004
1021
991
1038
1116
1063
1061
1197
1243
1080
980
980
986
1041
984
976
977
999
1008
987
1069
1014
1038
1049
1002
1082
1083
1086
1046
1065
1088
1088
1119
1112
1157
1137
1128
1173
1138
1110
1108
1104
1096
1102
1138
1171
1156
1174
1217
1236
1216
1210
1201
1121
1082
1073
1047
1072
1014
983
969
981
937
931
943
1012
1175
1206
1506
2965
5627
3417
1165
872
858
903
868
871
855
887
858
849
866
836
854
877
865
860
860
819
810
851
851
846
853
876
872
897
851
890
832
875
880
884
870
870
870
877
876
880
877
872
853
888
890
878
902
876
856
879
931
918
888
909
900
875
852
930
933
887
891
878
898
945
894
892
906
884
892
907
908
918
860
898
868
884
948
901
913
873
904
894
863
912
932
924
923
960
952
919
934
900
909
926
900
896
929
945
954
912
959
915
944
939
946
945
895
938
984
992
945
992
940
942
957
981
999
980
963
969
1028
1026
993
979
947
987
1040
990
958
1021
973
973
981
1016
956
994
979
978
1028
1055
1142
1174
1176
1181
1182
1115
1094
1039
1001
1002
923
876
826
832
777
708
694
660
618
589
651
672
745
1092
2062
3946
3955
2107
1034
723
622
599
565
512
539
524
520
526
535
513
494
497
575
604
640
613
676
667
652
638
615
609
568
508
538
486
442
388
358
323
355
287
257
230
208
226
244
284
433
1323
3329
2865
832
265
223
202
160
184
186
182
210
207
204
189
207
178
175
200
197
181
195
183
198
203
218
256
239
253
242
255
252
236
202
183
179
151
170
146
161
160
161
161
144
149
146
155
210
219
252
391
533
681
632
417
238
128
96
72
75
59
55
49
57
93
165
197
179
157
179
146
132
76
19
4
0
1
1
1
1.47543
Survey/8
Not Specified
2025
3
17
14
35
29
0
3
   XPS     Spectrum    Lens Mode:Hybrid   Res:80   Iris(Aper):slot(Slot)
   Acqn. Time(s): 241        Sweeps: 2        Anode:Mono(Al (Mono))(225 W)   Step(meV): 1000.0
   Dwell Time(ms): 100        Charge Neutraliser :On (Current 1.9 A: Balance 3.1 V: Bias 1.1 V)   Acquired On :25/03/17 14:35:29
XPS
13.522
2.372
3
Mono(Al (Mono))
1486.69
225
1E+37
1E+37
6000
6000
1E+37
1E+37
FAT
80
1E+37
-4.9
0
1E+37
1E+37
1E+37
1E+37
Wide
None
-1
Kinetic Energy
eV
286.69
1
2
Intensity
d
Transmission
d
pulse counting
0.1
0
1E+37
0
0
1.47543
2807
2793
2811
2818
2873
2919
2910
2821
2945
3001
2903
2855
2908
2891
2803
2885
2813
2838
2860
2918
2890
2848
2904
2782
2852
2888
2933
2858
2920
2847
2912
2953
2974
2999
2920
2931
2943
2966
2965
2952
3015
2980
2962
3000
2985
3020
3042
3043
3034
2959
3012
3051
3054
2920
2961
2980
3023
3139
2989
3086
3037
3126
3091
3084
3044
3111
3114
3012
3051
3160
3165
3127
3128
3094
3093
3178
3235
3129
3217
3199
3211
3184
3176
3205
3192
3184
3239
3228
3298
3258
3277
3400
3357
3266
3236
3284
3301
3354
3337
3378
3339
3358
3382
3377
3270
3334
3365
3368
3348
3386
3363
3392
3385
3213
3264
3364
3363
3442
3465
3448
3486
3453
3409
3396
3406
3508
3424
3445
3438
3467
3513
3826
3889
3656
3454
3557
3586
3546
3497
3551
3553
3517
3546
3577
3531
3620
3604
3455
3612
3607
3642
3653
3674
3649
3640
3660
3688
3792
3742
3605
3699
3795
3780
3831
3749
3723
3800
3775
3820
3773
3783
3787
3855
3836
3777
3732
3819
3831
3835
3781
3772
3904
3966
3912
3818
3907
3898
3899
3921
4006
3925
3860
3818
3756
3778
3791
3811
3829
3798
3993
4066
4142
4237
4313
4256
4170
4084
3887
3700
3707
3667
3538
3357
3306
3209
3111
3165
3114
3088
3290
3452
3882
4208
4668
4901
4881
4556
4121
3749
3448
3318
3226
3121
2802
2621
2425
2333
2167
2076
2118
2074
2003
2045
2005
2065
2067
2032
2038
2009
2017
2032
2027
1999
1992
2056
2019
2003
2055
2049
2083
2023
2019
2080
2079
2099
2105
2065
2150
2051
2046
2088
2118
2083
2089
2154
2165
2123
2101
2198
2141
2179
2167
2125
2156
2144
2123
2154
2129
2200
2140
2149
2175
2153
2188
2137
2160
2132
2186
2163
2105
2202
2169
2182
2194
2174
2199
2200
2197
2215
2248
2211
2263
2192
2200
2207
2225
2245
2300
2299
2222
2248
2221
2322
2240
2228
2254
2283
2311
2253
2201
2256
2253
2269
2234
2337
2376
2332
2313
2295
2279
2286
2327
2338
2281
2285
2358
2371
2311
2355
2375
2297
2311
2318
2329
2460
2408
2408
2357
2404
2373
2325
2363
2401
2304
2294
2354
2385
2393
2483
2367
2402
2402
2433
2384
2409
2398
2431
2407
2502
2424
2415
2378
2429
2431
2427
2510
2448
2416
2504
2566
2452
2456
2487
2471
2391
2345
2441
2531
2404
2450
2491
2465
2415
2438
2502
2572
2511
2533
2564
2555
2519
2485
2536
2553
2581
2626
2560
2451
2573
2552
2555
2533
2543
2562
2590
2578
2602
2639
2622
2593
2544
2641
2593
2515
2603
2621
2712
2668
2623
2615
2605
2621
2589
2611
2584
2667
2690
2672
2710
2651
2724
2629
2705
2609
2703
2742
2663
2666
2662
2665
2664
2674
2682
2666
2734
2693
2674
2692
2752
2731
2742
2780
2836
2790
2717
2737
2811
2801
2775
2783
2825
2834
2759
2713
2776
2792
2846
2779
2753
2864
2902
2824
2862
2854
2881
2814
2826
2863
2872
2948
2849
2825
2869
2783
2811
2934
2900
2926
2887
2865
2944
2947
2957
3029
2958
2945
2929
3023
2963
2972
3012
3016
3025
2990
2984
3042
2995
3013
2901
2950
3068
3039
2967
2972
3009
2972
3015
3052
3042
3074
3062
3005
3034
3026
3130
3192
3131
3099
2989
3038
2971
3135
3122
3181
3170
3103
3083
3082
3225
3177
3100
3261
3188
3133
3123
3192
3181
3122
3189
3227
3186
3208
3245
3311
3280
3231
3182
3334
3223
3277
3234
3275
3250
3254
3246
3199
3300
3253
3287
3256
3258
3347
3352
3347
3339
3277
3274
3266
3316
3329
3295
3295
3344
3360
3409
3378
3407
3369
3296
3408
3353
3406
3336
3374
3416
3398
3460
3496
3499
3524
3573
3502
3468
3461
3487
3551
3467
3417
3429
3390
3388
3366
3395
3340
3315
3333
3366
3367
3222
3219
3110
3174
3352
3452
3643
3871
4060
4092
4139
4213
4184
3922
3696
3419
3052
2816
2650
2495
2317
2158
2021
1801
1624
1488
1328
1183
1131
1327
1587
2757
7442
16514
18296
8765
2433
1105
925
824
851
853
842
846
842
813
836
866
861
827
794
894
836
840
831
813
872
859
845
835
864
922
888
881
885
859
958
1076
1031
972
876
887
851
831
791
786
827
841
864
872
856
802
795
812
833
847
775
866
854
859
830
808
795
815
839
860
860
887
862
866
826
876
879
866
896
791
850
869
854
813
839
824
858
817
823
778
809
824
851
896
901
854
858
896
933
948
967
900
897
904
838
859
831
866
879
867
858
882
882
878
899
863
868
912
883
895
865
866
841
876
870
876
878
904
876
883
870
894
934
931
834
851
900
873
926
1021
951
939
873
853
887
855
860
925
894
887
911
907
895
904
918
918
910
934
961
939
975
985
966
982
948
928
947
928
947
951
934
986
937
929
943
949
934
957
963
945
946
945
945
1007
949
973
998
1083
1175
1083
1047
1183
1176
1009
1009
1007
1007
1018
1019
1007
970
992
983
1007
992
1018
1020
993
1002
994
1091
1037
1017
1076
1120
1117
1043
1081
1063
1135
1071
1101
1154
1137
1140
1121
1053
1124
1176
1177
1174
1242
1233
1225
1193
1167
1198
1138
1120
1097
1073
1039
1024
1084
1027
999
1007
956
971
1027
1175
1258
1587
3188
5541
2918
1139
937
883
865
892
864
857
927
922
873
832
844
917
929
892
885
915
874
890
909
914
868
870
856
889
885
896
901
900
897
906
904
925
915
917
992
988
936
869
874
863
874
903
880
892
888
895
936
899
877
974
956
951
965
911
940
967
898
888
889
930
912
908
905
921
933
949
938
968
920
977
932
926
967
969
966
964
960
953
976
958
957
959
986
1000
994
995
931
977
951
1008
957
949
984
931
927
1006
972
983
971
975
1004
978
964
1020
992
979
1008
993
964
1032
1000
1026
1048
1070
1027
1018
1086
1061
1078
1081
1088
1027
1036
1104
1043
991
1008
995
1040
1047
985
1022
1063
1058
1068
1073
1065
1119
1227
1226
1198
1223
1179
1104
1091
1041
1003
1016
922
890
902
792
755
695
644
656
707
711
711
830
1198
2438
4251
4006
1955
962
752
691
620
593
544
571
553
560
556
559
561
570
554
607
596
628
613
640
695
682
678
629
610
601
549
488
493
443
441
390
356
323
288
262
234
240
237
249
287
447
1693
3728
2742
747
267
215
227
203
184
197
201
214
233
232
208
197
214
207
200
200
211
205
208
194
236
223
243
234
243
238
243
244
220
221
202
182
191
177
169
151
156
141
148
139
158
182
221
217
227
297
412
584
724
589
395
233
119
101
71
75
53
64
54
61
97
176
192
174
168
176
156
127
55
13
3
1
0
0
0
1.47543
Survey/11
Not Specified
2025
3
17
14
40
52
0
3
   XPS     Spectrum    Lens Mode:Hybrid   Res:80   Iris(Aper):slot(Slot)
   Acqn. Time(s): 241        Sweeps: 2        Anode:Mono(Al (Mono))(225 W)   Step(meV): 1000.0
   Dwell Time(ms): 100        Charge Neutraliser :On (Current 1.9 A: Balance 3.1 V: Bias 1.1 V)   Acquired On :25/03/17 14:40:52
XPS
34.146
4.452
4
Mono(Al (Mono))
1486.69
225
1E+37
1E+37
6000
6000
1E+37
1E+37
FAT
80
1E+37
-4.9
0
1E+37
1E+37
1E+37
1E+37
Wide
None
-1
Kinetic Energy
eV
286.69
1
2
Intensity
d
Transmission
d
pulse counting
0.1
0
1E+37
0
0
1.47543
2846
2873
2868
2893
2892
2875
2921
2875
2973
2929
2938
2968
2956
2994
2895
2921
2959
2893
2918
2945
2904
3000
2960
3028
2946
2958
3026
3005
2958
3011
3051
2979
3003
3045
3061
3057
3038
3050
3046
3025
3119
3108
3158
3062
3047
3111
3054
3107
3205
3151
3116
3145
3157
3242
3174
3208
3200
3122
3099
3087
3095
3177
3268
3202
3214
3160
3251
3230
3182
3201
3250
3262
3292
3235
3208
3267
3315
3339
3349
3267
3300
3261
3234
3386
3348
3363
3366
3383
3326
3258
3347
3267
3451
3461
3425
3323
3397
3427
3353
3483
3457
3443
3520
3388
3364
3528
3448
3495
3545
3439
3476
3506
3449
3588
3537
3574
3549
3502
3509
3503
3555
3653
3632
3643
3516
3572
3575
3555
3608
3630
3755
4233
4258
3913
3718
3565
3639
3639
3693
3803
3741
3680
3629
3740
3660
3621
3749
3774
3791
3811
3739
3773
3772
3816
3836
3840
3912
3949
3927
3901
3807
3945
3981
3927
3894
3891
3858
3944
3942
3881
4005
3950
3885
3952
4010
3960
4032
4043
4092
4091
4326
4350
4252
4194
4198
4208
4120
4226
4214
4271
4283
4274
4135
4054
4078
4163
4128
4288
4324
4312
4464
4504
4653
4733
4780
4680
4482
4216
4056
4085
3922
3828
3700
3556
3330
3393
3507
3438
3489
3780
4164
4566
5064
5521
5722
5654
5217
4484
4150
3857
3646
3462
3250
3013
2797
2559
2380
2265
2180
2142
2176
2112
2106
2132
2065
2056
2126
2175
2149
2068
2084
2126
2161
2084
2157
2133
2097
2115
2089
2123
2137
2120
2129
2236
2160
2194
2104
2097
2191
2185
2223
2199
2232
2166
2127
2112
2209
2227
2193
2187
2160
2149
2219
2250
2196
2213
2236
2175
2218
2189
2153
2145
2274
2184
2152
2172
2135
2225
2256
2280
2251
2237
2259
2190
2279
2257
2229
2227
2206
2183
2312
2182
2250
2305
2314
2259
2311
2341
2272
2285
2324
2325
2380
2380
2276
2324
2340
2322
2338
2331
2331
2344
2360
2356
2368
2321
2298
2351
2433
2390
2379
2450
2433
2415
2499
2418
2409
2365
2381
2454
2470
2361
2409
2375
2306
2316
2352
2328
2329
2415
2444
2383
2420
2423
2478
2455
2450
2459
2379
2411
2397
2413
2442
2452
2456
2446
2403
2431
2433
2559
2505
2427
2462
2528
2497
2481
2505
2432
2511
2466
2426
2519
2465
2452
2492
2551
2482
2483
2514
2600
2560
2539
2556
2527
2496
2533
2499
2575
2626
2541
2579
2582
2622
2662
2560
2599
2530
2609
2667
2628
2636
2594
2643
2660
2604
2667
2671
2664
2613
2706
2646
2602
2703
2733
2668
2635
2675
2635
2649
2711
2694
2683
2699
2608
2702
2664
2640
2674
2715
2788
2756
2720
2837
2755
2738
2768
2746
2846
2730
2724
2806
2805
2771
2812
2827
2825
2765
2802
2839
2882
2827
2744
2804
2817
2871
2834
2837
2827
2818
2886
2925
2868
2911
2865
2981
2939
2899
2802
2824
2884
2983
2926
2911
2908
2882
2884
2919
2910
2913
2916
2892
2934
2953
2985
2998
2973
3005
2949
2951
2980
2945
2986
2973
3065
3075
3048
3123
3073
3077
3080
3072
3042
3078
3060
3033
3003
3060
3149
3060
3069
3074
3151
3087
3118
3185
3116
3068
3048
3077
3109
3127
3144
3223
3171
3145
3091
3128
3170
3167
3210
3240
3236
3270
3183
3151
3189
3182
3303
3260
3202
3215
3275
3312
3241
3242
3246
3361
3312
3255
3224
3297
3221
3279
3237
3319
3364
3321
3234
3332
3356
3304
3349
3363
3328
3317
3389
3399
3409
3399
3379
3354
3344
3437
3434
3362
3387
3378
3397
3450
3426
3455
3492
3491
3414
3404
3477
3486
3429
3408
3448
3518
3542
3486
3511
3471
3515
3540
3519
3517
3664
3690
3724
3649
3659
3658
3660
3607
3675
3574
3604
3593
3564
3464
3558
3601
3527
3416
3460
3362
3345
3450
3518
3634
3759
3947
4200
4262
4532
4637
4564
4392
4182
3851
3559
3196
3022
2832
2606
2463
2348
2142
1906
1696
1446
1330
1246
1359
1462
1872
3922
10629
21205
20611
8283
2127
1116
963
962
926
912
904
883
890
867
917
849
882
852
896
834
837
867
894
902
892
827
833
831
858
881
915
948
950
993
1040
1195
1175
1002
868
834
830
813
796
803
853
826
835
799
778
812
794
800
812
839
870
862
880
842
794
818
809
821
836
864
818
773
883
802
790
813
850
836
827
798
804
855
817
850
802
816
794
821
880
849
860
838
814
874
822
822
846
868
840
799
807
829
874
872
811
862
812
847
825
824
853
871
815
801
826
823
850
858
800
789
855
899
837
806
840
856
887
885
849
858
819
833
832
895
862
857
856
847
925
997
930
855
848
820
849
870
836
861
869
832
799
853
856
865
833
864
907
885
895
834
899
859
865
888
874
826
862
890
847
854
854
888
888
911
922
873
886
894
879
904
918
900
879
927
916
945
903
909
911
915
920
923
921
942
923
935
961
945
929
927
960
943
981
977
942
946
922
906
933
983
982
897
993
995
981
1027
981
999
1035
1055
998
997
986
1021
1013
1001
1017
1040
1079
990
1024
1058
1028
1039
1046
1057
1023
995
998
1005
1042
997
975
998
929
935
917
922
949
1079
1166
1184
1519
2806
3805
2003
1041
925
871
848
882
860
860
903
909
916
875
843
869
886
870
912
864
894
914
876
877
904
894
882
905
861
871
880
870
867
925
940
868
916
888
919
906
917
932
889
887
896
871
869
876
839
911
870
878
879
942
966
966
958
976
919
932
928
902
918
892
932
902
881
896
901
895
893
910
886
929
951
939
934
928
958
900
923
915
922
931
920
954
955
961
945
961
986
970
961
1008
1024
1012
931
961
980
958
983
949
974
1001
986
982
983
1012
1070
1016
1003
994
965
952
934
935
1045
1161
1126
1036
1064
1011
1054
1034
1004
1011
991
1009
1024
1050
1049
1032
1106
1068
1099
1020
1031
1032
1037
1115
1132
1193
1226
1279
1270
1241
1247
1112
1118
1028
1032
1001
998
906
777
756
753
739
658
678
662
673
701
892
1337
2817
4869
3882
1764
942
751
637
640
606
572
574
590
586
583
593
566
562
631
739
724
633
700
701
663
687
678
678
607
584
550
543
528
500
420
356
355
317
299
266
223
234
216
255
277
581
2147
3961
2261
549
273
263
227
232
229
217
219
189
252
254
199
214
205
187
192
182
220
220
210
210
240
231
253
206
244
258
249
246
205
189
188
173
155
181
151
156
163
152
141
153
180
206
193
210
260
284
426
661
790
631
379
184
111
77
58
46
70
44
60
76
137
200
209
186
179
195
157
133
57
12
6
1
1
0
0
1.47543
Survey/14
Not Specified
2025
3
17
14
46
14
0
3
   XPS     Spectrum    Lens Mode:Hybrid   Res:80   Iris(Aper):slot(Slot)
   Acqn. Time(s): 241        Sweeps: 2        Anode:Mono(Al (Mono))(225 W)   Step(meV): 1000.0
   Dwell Time(ms): 100        Charge Neutraliser :On (Current 1.9 A: Balance 3.1 V: Bias 1.1 V)   Acquired On :25/03/17 14:46:14
XPS
35.264
2.94
5
Mono(Al (Mono))
1486.69
225
1E+37
1E+37
6000
6000
1E+37
1E+37
FAT
80
1E+37
-4.9
0
1E+37
1E+37
1E+37
1E+37
Wide
None
-1
Kinetic Energy
eV
286.69
1
2
Intensity
d
Transmission
d
pulse counting
0.1
0
1E+37
0
0
1.47543
2803
2864
2853
2870
2804
2872
2795
2849
2869
2870
2858
2914
2862
2953
3008
2832
2875
2927
2875
2846
2843
2889
2952
2935
2998
2977
2958
2879
2874
2945
2956
2924
3076
2962
3019
2978
3039
3036
3000
3021
2974
3018
2925
2937
2959
2987
3017
3034
2962
3026
3062
2993
3138
3102
3141
3054
3064
3016
3102
3111
3123
3102
3101
3179
3201
3212
3168
3187
3156
3202
3142
3112
3188
3155
3170
3288
3227
3185
3157
3212
3175
3187
3253
3278
3232
3228
3335
3274
3239
3259
3406
3346
3306
3263
3236
3402
3351
3416
3370
3392
3348
3363
3415
3419
3440
3405
3380
3424
3483
3490
3408
3439
3508
3513
3579
3523
3473
3526
3504
3487
3609
3605
3609
3603
3555
3557
3638
3556
3664
3647
3634
3747
3791
3642
3644
3695
3673
3654
3653
3694
3617
3650
3603
3695
3681
3715
3715
3732
3721
3647
3770
3780
3715
3817
3758
3812
3847
3907
3858
3961
3979
4003
3914
3914
3893
3947
3910
3935
3966
3976
3935
3955
3977
4002
3934
4085
4112
4071
4069
4108
4234
4323
4186
4164
4278
4210
4182
4235
4311
4125
4242
4136
4108
4060
4094
4048
4146
4177
4282
4481
4541
4678
4790
4790
4814
4717
4354
4244
4131
4064
3954
3865
3663
3507
3499
3408
3455
3496
3593
3865
4233
4609
5142
5711
5955
5864
5315
4657
4217
3866
3605
3403
3274
3011
2796
2554
2354
2182
2159
2088
2106
2111
2060
2054
2054
2061
1953
2057
2097
2058
2061
2105
2013
2038
2064
2057
2038
2076
2156
2095
2141
2041
2031
2047
2101
2111
2091
2082
2096
2100
2193
2118
2096
2104
2065
2105
2146
2152
2123
2085
2140
2155
2186
2148
2084
2055
2092
2164
2218
2205
2147
2198
2209
2180
2203
2132
2195
2197
2146
2186
2187
2155
2123
2194
2224
2225
2220
2147
2254
2179
2221
2273
2266
2309
2192
2219
2259
2240
2256
2289
2193
2238
2228
2265
2203
2247
2236
2221
2207
2291
2235
2329
2300
2305
2290
2290
2252
2310
2342
2361
2376
2278
2324
2359
2383
2387
2321
2281
2327
2375
2349
2373
2318
2335
2401
2418
2383
2394
2411
2347
2339
2355
2426
2437
2380
2384
2355
2408
2397
2423
2427
2419
2454
2428
2520
2477
2388
2398
2433
2435
2433
2443
2454
2418
2474
2502
2503
2438
2385
2427
2471
2509
2453
2458
2497
2594
2508
2506
2498
2448
2466
2531
2529
2460
2440
2517
2553
2435
2495
2473
2545
2570
2545
2504
2630
2598
2587
2545
2507
2572
2610
2584
2528
2566
2608
2569
2584
2604
2580
2545
2609
2677
2610
2636
2559
2590
2681
2633
2676
2672
2689
2623
2574
2609
2694
2672
2642
2655
2625
2704
2678
2668
2720
2721
2752
2774
2784
2805
2744
2687
2766
2738
2848
2719
2768
2798
2734
2816
2738
2791
2795
2787
2770
2822
2800
2756
2775
2763
2756
2825
2847
2815
2764
2855
2800
2826
2904
2823
2861
2845
2851
2839
2841
2820
2892
2864
2902
2872
2894
2932
2880
2882
2948
2924
2905
2877
2795
2901
2895
2938
2917
2932
2886
2923
3008
2955
2967
2999
3035
3040
3032
2952
2904
2944
3030
3023
2955
3032
3103
3020
2987
3073
3092
3074
3016
3016
3071
3038
3099
3120
3111
3089
3138
3081
3060
3088
3117
3117
3047
3100
3107
3103
3195
3174
3117
3150
3199
3077
3273
3187
3142
3184
3201
3178
3105
3178
3138
3217
3200
3233
3260
3289
3281
3221
3276
3298
3192
3267
3325
3307
3291
3253
3216
3305
3390
3363
3311
3295
3377
3422
3359
3405
3399
3378
3393
3338
3384
3406
3452
3368
3367
3474
3413
3412
3409
3431
3395
3460
3501
3473
3524
3487
3528
3474
3486
3460
3517
3610
3541
3664
3697
3678
3673
3613
3760
3729
3664
3600
3569
3556
3581
3489
3492
3503
3434
3356
3415
3469
3417
3424
3419
3467
3608
3715
3957
4124
4319
4490
4584
4654
4520
4250
3823
3506
3223
2886
2806
2577
2366
2259
1980
1851
1656
1399
1220
1126
1200
1349
1872
4063
11168
21824
21338
8474
2041
1067
930
865
833
833
858
830
851
820
743
792
778
807
802
777
784
779
762
801
782
802
784
782
848
826
789
791
852
803
847
863
877
847
834
804
811
758
789
790
750
800
841
815
770
777
802
806
790
831
803
804
778
803
822
777
738
803
773
833
782
834
820
775
777
829
802
824
796
844
826
775
889
792
824
829
820
789
778
786
802
811
826
808
840
796
809
784
836
822
793
801
840
827
790
833
856
799
842
824
814
834
807
804
838
805
828
830
834
831
860
837
787
807
804
838
853
849
781
819
877
847
804
804
853
803
817
841
861
922
862
843
825
868
806
815
819
822
805
845
867
878
850
855
817
806
828
823
840
818
813
816
832
861
868
834
861
851
845
912
879
875
891
865
883
818
809
852
864
899
891
867
883
863
855
853
843
927
930
868
865
897
832
909
921
906
883
888
881
925
924
883
862
843
839
907
937
926
964
931
955
970
902
915
901
930
882
914
964
958
1005
949
944
1007
1011
971
992
1004
1048
956
987
998
1033
1016
1054
994
1032
985
980
1008
982
924
970
924
900
905
911
937
931
1074
1130
1172
1412
2425
3438
1946
1016
910
863
864
849
825
885
876
911
862
884
881
865
924
867
880
881
911
953
884
852
884
942
910
885
828
869
904
871
918
946
956
865
886
910
890
904
898
866
860
864
890
929
895
908
912
909
964
906
899
935
930
961
917
947
954
922
925
963
940
921
930
929
906
907
924
968
924
889
954
900
953
907
974
940
914
925
943
927
972
977
963
933
972
993
989
958
983
979
968
1058
1045
991
960
991
979
1016
987
993
997
1025
957
949
990
952
976
1026
1026
1053
1042
1017
1026
1014
1033
1080
1071
1050
1057
1068
1066
1046
1074
1098
1040
1025
980
1036
999
1133
1188
1122
1111
1109
1088
1133
1107
1131
1168
1252
1257
1203
1245
1213
1225
1172
1091
1060
1038
1011
936
894
844
812
756
759
702
705
702
676
767
940
1368
2930
5124
4331
1969
1018
775
669
628
640
605
586
588
548
556
579
538
589
647
701
698
699
718
719
770
737
687
669
671
563
572
511
474
460
415
353
343
312
291
257
253
246
225
258
290
581
2157
4294
2569
598
244
219
214
195
196
198
202
212
230
201
174
188
198
184
196
191
215
218
204
210
197
214
221
235
238
247
246
232
236
221
171
207
179
176
164
157
155
148
146
167
175
181
197
226
257
310
468
677
797
684
404
195
100
73
59
45
42
41
62
54
125
204
205
193
188
204
188
136
55
10
1
2
0
0
1
1.47543
Survey/17
Not Specified
2025
3
17
14
51
40
0
3
   XPS     Spectrum    Lens Mode:Hybrid   Res:80   Iris(Aper):slot(Slot)
   Acqn. Time(s): 241        Sweeps: 2        Anode:Mono(Al (Mono))(225 W)   Step(meV): 1000.0
   Dwell Time(ms): 100        Charge Neutraliser :On (Current 1.9 A: Balance 3.1 V: Bias 1.1 V)   Acquired On :25/03/17 14:51:40
XPS
35.62
0.313
6
Mono(Al (Mono))
1486.69
225
1E+37
1E+37
6000
6000
1E+37
1E+37
FAT
80
1E+37
-4.9
0
1E+37
1E+37
1E+37
1E+37
Wide
None
-1
Kinetic Energy
eV
286.69
1
2
Intensity
d
Transmission
d
pulse counting
0.1
0
1E+37
0
0
1.47543
2936
3015
2998
2915
2880
2945
2938
2935
2951
2966
3039
3014
3072
3058
3053
3080
2984
3029
2992
3001
3068
3093
2950
2961
2889
2866
3000
2985
2932
3024
3098
2999
3032
3112
3093
3024
3020
3073
3117
3226
3145
3084
3157
3098
3153
3038
3091
3103
3078
3095
3131
3090
3134
3175
3213
3199
3252
3224
3216
3233
3177
3177
3211
3274
3254
3288
3266
3311
3273
3217
3237
3236
3270
3337
3300
3226
3244
3330
3344
3317
3300
3339
3444
3380
3422
3453
3422
3412
3408
3475
3438
3410
3367
3438
3415
3449
3394
3398
3476
3416
3445
3442
3566
3464
3553
3458
3557
3521
3527
3586
3633
3574
3611
3603
3582
3480
3542
3597
3599
3574
3570
3627
3724
3764
3717
3616
3713
3696
3573
3680
3778
4190
4280
3916
3818
3780
3655
3747
3810
3885
3752
3766
3769
3762
3845
3844
3848
3761
3839
3801
3843
3935
3905
3859
3885
3959
4011
3992
4082
4001
3929
3967
3963
3975
3993
4100
4101
3915
4047
4086
4021
4054
4113
4062
4125
4067
4121
4047
4153
4248
4407
4509
4350
4207
4218
4221
4248
4354
4428
4460
4400
4297
4196
4132
4139
4224
4156
4246
4402
4472
4668
4820
4874
4890
4787
4700
4520
4301
4160
4180
4036
3895
3774
3689
3639
3607
3526
3578
3669
3964
4318
4779
5309
5760
5942
5832
5432
4729
4243
3967
3736
3606
3268
3101
2918
2665
2534
2312
2169
2173
2131
2167
2184
2109
2099
2194
2184
2104
2103
2170
2157
2217
2191
2077
2147
2139
2100
2096
2165
2175
2148
2125
2172
2216
2222
2153
2099
2188
2230
2194
2202
2226
2259
2179
2182
2175
2138
2142
2175
2214
2233
2191
2198
2235
2199
2220
2235
2266
2260
2221
2183
2203
2297
2308
2297
2249
2281
2239
2252
2360
2265
2255
2238
2215
2193
2232
2282
2361
2320
2274
2338
2329
2262
2292
2306
2339
2353
2337
2292
2351
2361
2403
2330
2326
2359
2363
2299
2367
2397
2361
2398
2334
2329
2363
2367
2432
2377
2359
2426
2426
2457
2432
2412
2456
2386
2428
2432
2470
2496
2429
2389
2472
2429
2447
2398
2452
2502
2434
2429
2469
2431
2430
2425
2471
2400
2422
2443
2486
2507
2459
2455
2539
2518
2407
2479
2469
2565
2509
2536
2484
2477
2557
2509
2472
2520
2438
2468
2412
2557
2485
2528
2524
2568
2536
2631
2536
2582
2568
2535
2523
2558
2576
2602
2623
2615
2547
2559
2589
2723
2586
2646
2603
2682
2666
2618
2579
2623
2622
2675
2706
2674
2580
2665
2655
2658
2747
2680
2608
2637
2651
2697
2694
2674
2686
2777
2674
2634
2655
2783
2691
2734
2746
2702
2765
2753
2773
2730
2776
2769
2757
2759
2799
2793
2781
2744
2723
2712
2789
2712
2806
2824
2866
2785
2789
2782
2791
2895
2874
2838
2889
2861
2878
2835
2801
2853
2913
2845
2889
2865
2839
2892
2912
2937
2879
2876
2882
2960
2911
2915
2894
3031
2961
2902
2982
3014
2939
2962
3051
3049
3021
2977
2918
2873
2932
3007
3052
3048
3023
2955
3087
3039
2943
3004
3062
3065
3023
3061
3122
3101
3002
3045
3102
3020
2977
3051
3108
3105
3091
3119
3177
3203
3150
3061
3175
3158
3116
3163
3113
3163
3213
3236
3219
3135
3165
3202
3242
3139
3123
3084
3122
3145
3239
3217
3260
3263
3244
3258
3242
3241
3349
3333
3266
3265
3308
3281
3300
3361
3332
3275
3342
3451
3355
3287
3265
3354
3293
3283
3342
3349
3343
3309
3372
3429
3466
3478
3487
3415
3444
3413
3522
3469
3396
3418
3488
3448
3462
3408
3446
3389
3468
3563
3561
3450
3383
3427
3601
3621
3601
3576
3561
3621
3506
3653
3525
3604
3608
3675
3658
3587
3645
3673
3693
3734
3623
3657
3754
3693
3739
3754
3700
3718
3608
3711
3580
3627
3661
3504
3533
3435
3462
3412
3514
3709
3942
4127
4130
4480
4666
4748
4707
4559
4262
3940
3547
3309
3028
2835
2675
2529
2366
2160
1969
1738
1514
1285
1204
1212
1411
1894
3862
10524
21680
22407
9382
2326
1160
976
877
832
838
848
884
842
845
858
870
854
893
798
816
844
820
898
876
810
828
880
867
841
871
863
888
920
902
948
1096
1139
997
862
832
795
806
817
829
818
806
826
854
810
797
786
787
826
839
831
833
796
829
833
817
799
790
800
825
795
779
760
844
865
780
797
816
792
780
787
817
828
823
821
803
843
839
865
834
840
836
815
833
838
789
857
822
828
869
841
823
793
810
767
781
792
801
858
835
821
795
862
816
839
823
813
830
802
827
886
867
885
829
802
854
832
838
835
873
843
839
829
834
813
859
879
912
936
969
883
841
841
867
828
861
814
838
842
885
869
865
842
829
846
869
844
817
846
884
878
881
840
839
900
853
848
861
884
879
870
846
885
907
869
875
879
884
854
846
877
903
902
907
887
885
907
933
889
892
906
926
950
986
957
908
896
901
964
919
940
914
954
905
889
917
967
944
938
961
946
925
930
977
1021
982
912
924
961
968
1005
1017
971
953
1010
1011
996
1001
1033
1015
1004
994
1043
1034
1021
1021
1055
969
962
959
984
960
965
960
976
968
996
993
1055
1102
1185
1274
1488
2342
3505
2168
1101
891
910
909
863
895
925
894
946
933
900
909
894
931
907
867
902
893
890
873
871
885
892
881
858
874
903
901
882
900
928
913
922
925
893
924
936
961
923
905
891
933
948
951
955
956
987
915
938
940
950
979
993
965
952
967
924
966
980
956
920
948
967
929
955
955
935
936
978
955
920
979
969
917
947
945
892
922
942
942
956
964
945
963
1027
972
1016
964
1009
1003
1064
1047
956
975
993
986
962
1009
1029
1024
1017
1010
1017
1032
1002
991
1053
1030
1020
1001
1007
1018
1078
1076
1132
1133
1053
1068
1087
1062
1050
993
1036
1054
1073
1079
1059
1088
1117
1185
1180
1163
1110
1138
1093
1113
1163
1189
1256
1279
1289
1310
1276
1277
1208
1117
1091
1117
999
996
967
902
821
774
811
725
692
713
705
740
982
1421
2856
4986
4371
2089
1088
799
704
598
608
655
591
569
614
608
579
594
615
629
697
770
712
697
698
700
777
751
674
667
602
541
513
522
476
461
373
345
331
295
297
274
242
243
250
317
552
2020
4294
2848
662
280
212
218
218
217
202
217
206
251
263
206
226
212
207
212
210
210
195
209
219
235
230
246
269
291
263
259
242
245
218
200
192
175
175
176
167
155
146
174
160
169
210
221
226
268
339
453
672
783
670
419
207
111
79
70
59
48
53
43
63
103
224
226
228
215
218
214
142
73
23
4
2
2
0
4
1.47543
Survey/20
Not Specified
2025
3
17
14
57
3
0
3
   XPS     Spectrum    Lens Mode:Hybrid   Res:80   Iris(Aper):slot(Slot)
   Acqn. Time(s): 241        Sweeps: 2        Anode:Mono(Al (Mono))(225 W)   Step(meV): 1000.0
   Dwell Time(ms): 100        Charge Neutraliser :On (Current 1.9 A: Balance 3.1 V: Bias 1.1 V)   Acquired On :25/03/17 14:57:03
XPS
55.938
2.19
7
Mono(Al (Mono))
1486.69
225
1E+37
1E+37
6000
6000
1E+37
1E+37
FAT
80
1E+37
-4.9
0
1E+37
1E+37
1E+37
1E+37
Wide
None
-1
Kinetic Energy
eV
286.69
1
2
Intensity
d
Transmission
d
pulse counting
0.1
0
1E+37
0
0
1.47543
2818
2855
2837
2789
2918
2887
2826
2838
2830
2832
2856
2880
2883
2852
2865
2820
2878
2836
2877
2891
2871
2872
2828
2866
2858
2847
2884
2887
2908
2908
2963
2930
2977
2979
2947
2881
2919
2866
2964
3032
2999
2989
2962
3027
3014
2961
3094
3137
3027
3059
3053
3015
3028
3146
3085
3037
3196
3077
2987
3121
3156
3088
3082
3162
3193
3161
3174
3074
3196
3146
3167
3137
3164
3138
3167
3157
3167
3189
3112
3265
3270
3208
3219
3304
3221
3149
3170
3252
3222
3258
3269
3206
3295
3313
3337
3356
3248
3324
3425
3391
3322
3365
3343
3328
3405
3379
3365
3364
3439
3427
3463
3386
3431
3381
3410
3524
3466
3465
3609
3517
3577
3395
3464
3477
3561
3560
3510
3562
3458
3473
3544
3677
3623
3579
3612
3621
3559
3651
3624
3579
3610
3606
3641
3582
3658
3647
3717
3734
3644
3704
3738
3691
3734
3728
3692
3735
3727
3880
3928
3864
3885
3933
3953
3824
3842
3901
3915
3970
4018
3966
3899
3851
3910
3988
3916
3888
3963
4086
4161
4047
4065
4212
4145
4072
4064
4200
4041
4020
4158
4171
4136
4124
3966
3970
4077
4005
4052
4078
4176
4268
4257
4347
4432
4536
4581
4572
4245
4213
4060
3819
3734
3685
3507
3427
3325
3353
3352
3355
3390
3538
3801
4231
4695
5125
5381
5470
4956
4368
3986
3648
3436
3276
3134
2879
2674
2543
2430
2273
2087
2070
2082
2074
2077
2100
2146
2104
2111
2103
2083
2055
2038
2008
2030
2063
2077
2118
2058
2094
2098
2099
2067
2094
2088
2087
2088
2095
2125
2089
2149
2184
2142
2139
2106
2129
2139
2173
2163
2105
2124
2115
2135
2123
2155
2123
2148
2196
2205
2180
2136
2129
2226
2157
2205
2231
2199
2184
2155
2155
2161
2212
2243
2176
2158
2171
2200
2188
2157
2212
2207
2229
2315
2211
2179
2239
2247
2289
2236
2282
2280
2224
2279
2227
2266
2298
2272
2253
2232
2279
2227
2308
2183
2192
2257
2246
2296
2285
2281
2350
2323
2309
2257
2278
2275
2321
2329
2361
2324
2411
2351
2288
2265
2301
2380
2390
2357
2307
2448
2385
2400
2405
2381
2418
2360
2362
2383
2376
2372
2358
2349
2375
2379
2373
2376
2527
2458
2450
2462
2444
2454
2364
2455
2406
2509
2441
2449
2466
2452
2382
2528
2400
2421
2517
2466
2510
2492
2520
2451
2498
2483
2456
2550
2535
2613
2605
2503
2506
2561
2508
2491
2508
2563
2540
2550
2533
2567
2593
2597
2636
2558
2500
2484
2524
2572
2522
2541
2585
2611
2526
2608
2621
2664
2650
2653
2576
2580
2640
2598
2597
2649
2589
2578
2650
2634
2635
2629
2672
2736
[...]
0.359846
5919
0.359837
5969
0.359829
6016
0.35982
5874
0.359812
5937
0.359803
5840
0.359795
5789
0.359786
5780
0.359778
5723
0.359769
5782
0.35976
5700
0.359752
5503
0.359743
5425
0.359735
5494
0.359726
5377
0.359718
5342
0.359709
5250
0.359701
5219
0.359692
5199
0.359684
5293
0.359675
5122
0.359666
4964
0.359658
4978
0.359649
4883
0.359641
4774
0.359632
4738
0.359624
4783
0.359615
4744
0.359607
4712
0.359598
4687
0.359589
4574
0.359581
4480
0.359572
4409
0.359564
4406
0.359555
4316
0.359547
4166
0.359538
4196
0.35953
4084
0.359521
4090
0.359513
3992
0.359504
3866
0.359495
3968
0.359487
3848
0.359478
3774
0.35947
3683
0.359461
3652
0.359453
3690
0.359444
3649
0.359436
3538
0.359427
3453
0.359419
3466
0.35941
3313
0.359401
3251
0.359393
3244
0.359384
3244
0.359376
3141
0.359367
2956
0.359359
3002
0.35935
3012
0.359342
2901
0.359333
2879
0.359325
2753
0.359316
2634
0.359307
2713
0.359299
2679
0.35929
2635
0.359282
2614
0.359273
2504
0.359265
2506
0.359256
2526
0.359248
2585
0.359239
2441
0.359231
2399
0.359222
2424
0.359213
2385
0.359205
2366
0.359196
2485
0.359188
2381
0.359179
2380
0.359171
2387
0.359162
2289
0.359154
2439
0.359145
2394
0.359137
2370
0.359128
2407
0.359119
2368
0.359111
2287
0.359102
2349
0.359094
2337
0.359085
2488
0.359077
2483
0.359068
2538
0.35906
2450
0.359051
2520
0.359043
2579
0.359034
2679
0.359025
2733
0.359017
2677
0.359008
2738
0.359
2898
0.358991
3037
0.358983
3180
0.358974
3195
0.358966
3344
0.358957
3594
0.358949
3815
0.35894
4012
0.358931
4347
0.358923
4761
0.358914
5257
0.358906
5806
0.358897
6481
0.358889
7192
0.35888
8125
0.358872
8988
0.358863
10200
0.358855
11412
0.358846
12930
0.358837
14700
0.358829
16680
0.35882
19034
0.358812
21511
0.358803
24202
0.358795
27364
0.358786
30513
0.358778
33971
0.358769
37789
0.358761
42221
0.358752
46378
0.358743
50914
0.358735
54955
0.358726
58614
0.358718
62772
0.358709
65915
0.358701
68337
0.358692
69673
0.358684
70273
0.358675
69757
0.358667
68522
0.358658
65898
0.358649
62363
0.358641
58196
0.358632
53783
0.358624
48970
0.358615
43673
0.358607
38117
0.358598
32871
0.35859
28344
0.358581
23980
0.358573
20036
0.358564
16636
0.358555
13697
0.358547
11390
0.358538
9224
0.35853
7810
0.358521
6622
0.358513
5560
0.358504
4801
0.358496
4254
0.358487
3811
0.358478
3633
0.35847
3364
0.358461
3043
0.358453
2921
0.358444
2740
0.358436
2740
0.358427
2651
0.358419
2637
0.35841
2628
0.358402
2539
0.358393
2475
0.358384
2354
0.358376
2385
0.358367
2358
0.358359
2264
0.35835
2228
0.358342
2263
0.358333
2225
0.358325
C 1s/49
Not Specified
2025
3
17
16
44
13
0
3
   XPS     Spectrum    Lens Mode:Hybrid   Res:20   Iris(Aper):slot(Slot)
   Acqn. Time(s): 362        Sweeps: 6        Anode:Mono(Al (Mono))(225 W)   Step(meV): 100.0
   Dwell Time(ms): 260        Charge Neutraliser :On (Current 1.9 A: Balance 3.1 V: Bias 1.1 V)   Acquired On :25/03/17 16:44:13
XPS
57.386
3.823
15
Mono(Al (Mono))
1486.69
225
1E+37
1E+37
6000
6000
1E+37
1E+37
FAT
20
1E+37
-4.9
0
1E+37
1E+37
1E+37
1E+37
C
1s
-1
Kinetic Energy
eV
1186.69
0.1
2
Intensity
d
Transmission
d
pulse counting
0.2597
6
0
1E+37
1E+37
1E+37
0
464
1249
8073
0.348291
0.349292
1505
0.349254
1459
0.349255
1483
0.349256
1558
0.349257
1546
0.349258
1485
0.34926
1508
0.349261
1492
0.349262
1491
0.349263
1493
0.349264
1503
0.349266
1467
0.349267
1476
0.349268
1456
0.349269
1496
0.34927
1448
0.349272
1365
0.349273
1441
0.349274
1462
0.349275
1446
0.349276
1459
0.349278
1496
0.349279
1471
0.34928
1468
0.349281
1431
0.349282
1498
0.349284
1443
0.349285
1429
0.349286
1475
0.349287
1520
0.349289
1485
0.34929
1506
0.349291
1498
0.349292
1473
0.349288
1424
0.349283
1443
0.349278
1432
0.349273
1425
0.349268
1434
0.349263
1437
0.349258
1382
0.349253
1387
0.349248
1442
0.349243
1447
0.349238
1433
0.349233
1484
0.349228
1380
0.349223
1368
0.349218
1448
0.349213
1460
0.349208
1400
0.349203
1477
0.349198
1457
0.349193
1444
0.349188
1453
0.349183
1391
0.349178
1350
0.349173
1382
0.349167
1397
0.349162
1445
0.349157
1367
0.349152
1389
0.349147
1368
0.349142
1326
0.349137
1370
0.349132
1363
0.349127
1407
0.349122
1446
0.349117
1441
0.349112
1370
0.349107
1393
0.349102
1417
0.349097
1391
0.349092
1373
0.349087
1321
0.349082
1346
0.349077
1386
0.349072
1370
0.349067
1368
0.349062
1397
0.349057
1379
0.349052
1396
0.349047
1354
0.349042
1397
0.349037
1345
0.349032
1361
0.349026
1424
0.349021
1392
0.349016
1352
0.349011
1311
0.349006
1354
0.349001
1406
0.348996
1373
0.348991
1359
0.348986
1400
0.348981
1328
0.348976
1372
0.348971
1327
0.348966
1387
0.348961
1358
0.348956
1331
0.348951
1341
0.348946
1297
0.348941
1325
0.348936
1370
0.348931
1327
0.348926
1305
0.348921
1299
0.348916
1347
0.348911
1383
0.348906
1346
0.348901
1379
0.348896
1334
0.34889
1324
0.348885
1365
0.34888
1372
0.348875
1355
0.34887
1348
0.348865
1327
0.34886
1326
0.348855
1380
0.34885
1396
0.348845
1422
0.34884
1466
0.348835
1493
0.34883
1534
0.348825
1621
0.34882
1542
0.348815
1640
0.34881
1649
0.348805
1664
0.3488
1603
0.348795
1636
0.34879
1649
0.348785
1602
0.34878
1682
0.348775
1647
0.34877
1641
0.348765
1586
0.34876
1571
0.348755
1578
0.348749
1569
0.348744
1510
0.348739
1535
0.348734
1542
0.348729
1611
0.348724
1582
0.348719
1564
0.348714
1561
0.348709
1567
0.348704
1684
0.348699
1643
0.348694
1680
0.348689
1651
0.348684
1775
0.348679
1865
0.348674
1844
0.348669
1871
0.348664
2023
0.348659
2093
0.348654
2121
0.348649
2229
0.348644
2350
0.348639
2434
0.348634
2585
0.348629
2772
0.348624
3027
0.348619
3367
0.348614
3906
0.348608
4478
0.348603
5093
0.348598
5773
0.348593
6366
0.348588
6937
0.348583
7563
0.348578
7925
0.348573
8073
0.348568
7900
0.348563
7597
0.348558
7116
0.348553
6415
0.348548
5733
0.348543
5097
0.348538
4212
0.348533
3638
0.348528
3112
0.348523
2651
0.348518
2310
0.348513
2082
0.348508
1775
0.348503
1732
0.348498
1568
0.348493
1470
0.348488
1439
0.348483
1395
0.348478
1352
0.348473
1353
0.348467
1299
0.348462
1255
0.348457
1300
0.348452
1314
0.348447
1291
0.348442
1332
0.348437
1334
0.348432
1308
0.348427
1301
0.348422
1319
0.348417
1311
0.348412
1337
0.348407
1288
0.348402
1289
0.348397
1288
0.348392
1300
0.348387
1267
0.348382
1258
0.348377
1265
0.348372
1315
0.348367
1294
0.348362
1272
0.348357
1288
0.348352
1249
0.348347
1293
0.348342
1299
0.348337
1344
0.348331
1308
0.348326
1282
0.348321
1330
0.348316
1268
0.348311
1264
0.348306
1285
0.348301
1302
0.348296
1303
0.348291
Al 2p/50
Not Specified
2025
3
17
16
51
36
0
3
   XPS     Spectrum    Lens Mode:Hybrid   Res:20   Iris(Aper):slot(Slot)
   Acqn. Time(s): 724        Sweeps: 12       Anode:Mono(Al (Mono))(225 W)   Step(meV): 100.0
   Dwell Time(ms): 298        Charge Neutraliser :On (Current 1.9 A: Balance 3.1 V: Bias 1.1 V)   Acquired On :25/03/17 16:51:36
XPS
57.386
3.823
15
Mono(Al (Mono))
1486.69
225
1E+37
1E+37
6000
6000
1E+37
1E+37
FAT
20
1E+37
-4.9
0
1E+37
1E+37
1E+37
1E+37
Al
2p
-1
Kinetic Energy
eV
1400.69
0.1
2
Intensity
d
Transmission
d
pulse counting
0.2985
12
0
1E+37
1E+37
1E+37
0
404
612
20259
0.333259
0.333748
1492
0.333748
1488
0.333746
1491
0.333744
1439
0.333741
1451
0.333739
1467
0.333736
1392
0.333734
1427
0.333731
1442
0.333729
1416
0.333726
1372
0.333724
1386
0.333722
1369
0.333719
1330
0.333717
1323
0.333714
1309
0.333712
1326
0.333709
1332
0.333707
1283
0.333705
1291
0.333702
1253
0.3337
1244
0.333697
1194
0.333695
1207
0.333692
1214
0.33369
1139
0.333687
1146
0.333685
1166
0.333683
1149
0.33368
1163
0.333678
1085
0.333675
1120
0.333673
1034
0.33367
1108
0.333668
1038
0.333666
1002
0.333663
1028
0.333661
1005
0.333658
993
0.333656
1014
0.333653
1011
0.333651
985
0.333649
918
0.333646
987
0.333644
983
0.333641
956
0.333639
913
0.333636
906
0.333634
912
0.333631
913
0.333629
927
0.333627
908
0.333624
882
0.333622
848
0.333619
856
0.333617
833
0.333614
831
0.333612
817
0.333609
750
0.333607
778
0.333605
787
0.333602
766
0.3336
783
0.333597
734
0.333595
740
0.333592
723
0.33359
708
0.333588
719
0.333585
731
0.333583
701
0.33358
670
0.333578
729
0.333575
710
0.333573
685
0.333571
681
0.333568
684
0.333566
669
0.333563
627
0.333561
676
0.333558
675
0.333556
650
0.333553
667
0.333551
662
0.333549
614
0.333546
642
0.333544
612
0.333541
635
0.333539
643
0.333536
680
0.333534
650
0.333532
664
0.333529
644
0.333527
688
0.333524
687
0.333522
704
0.333519
675
0.333517
705
0.333514
707
0.333512
705
0.33351
657
0.333507
691
0.333505
717
0.333502
727
0.3335
742
0.333497
816
0.333495
797
0.333493
774
0.33349
826
0.333488
826
0.333485
892
0.333483
835
0.33348
885
0.333478
940
0.333475
996
0.333473
1035
0.333471
1102
0.333468
1087
0.333466
1148
0.333463
1304
0.333461
1496
0.333458
1724
0.333456
1998
0.333454
2367
0.333451
2911
0.333449
3645
0.333446
4506
0.333444
5558
0.333441
6771
0.333439
8287
0.333436
9860
0.333434
11699
0.333432
13374
0.333429
15456
0.333427
17027
0.333424
18351
0.333422
19272
0.333419
19960
0.333417
20259
0.333415
19933
0.333412
19255
0.33341
18293
0.333407
16693
0.333405
14825
0.333402
13038
0.3334
11292
0.333398
9465
0.333395
7720
0.333393
6248
0.33339
4945
0.333388
3797
0.333385
3046
0.333383
2396
0.33338
1927
0.333378
1538
0.333376
1242
0.333373
1103
0.333371
966
0.333368
869
0.333366
849
0.333363
813
0.333361
738
0.333359
763
0.333356
731
0.333354
715
0.333351
711
0.333349
724
0.333346
677
0.333344
711
0.333341
702
0.333339
711
0.333337
694
0.333334
736
0.333332
697
0.333329
652
0.333327
659
0.333324
675
0.333322
630
0.33332
640
0.333317
683
0.333315
655
0.333312
679
0.33331
661
0.333307
666
0.333305
650
0.333302
735
0.3333
674
0.333298
648
0.333295
667
0.333293
662
0.33329
681
0.333288
686
0.333285
703
0.333283
677
0.333281
645
0.333278
626
0.333276
664
0.333273
672
0.333271
689
0.333268
669
0.333266
668
0.333263
678
0.333261
637
0.333259
O 1s/53
Not Specified
2025
3
17
17
6
29
0
3
   XPS     Spectrum    Lens Mode:Hybrid   Res:20   Iris(Aper):slot(Slot)
   Acqn. Time(s): 488        Sweeps: 8        Anode:Mono(Al (Mono))(225 W)   Step(meV): 100.0
   Dwell Time(ms): 332        Charge Neutraliser :On (Current 1.9 A: Balance 3.1 V: Bias 1.1 V)   Acquired On :25/03/17 17:06:29
XPS
80.982
2.428
16
Mono(Al (Mono))
1486.69
225
1E+37
1E+37
6000
6000
1E+37
1E+37
FAT
20
1E+37
-4.9
0
1E+37
1E+37
1E+37
1E+37
O
1s
-1
Kinetic Energy
eV
943.69
0.1
2
Intensity
d
Transmission
d
pulse counting
0.3315
8
0
1E+37
1E+37
1E+37
0
368
4126
52708
0.358325
0.359889
7427
0.359889
7244
0.35988
7210
0.359872
7341
0.359863
7241
0.359854
7143
0.359846
7100
0.359837
7120
0.359829
7123
0.35982
7037
0.359812
6884
0.359803
6925
0.359795
6885
0.359786
6834
0.359778
6865
0.359769
6840
0.35976
6704
0.359752
6654
0.359743
6753
0.359735
6701
0.359726
6475
0.359718
6473
0.359709
6489
0.359701
6392
0.359692
6529
0.359684
6352
0.359675
6445
0.359666
6270
0.359658
6250
0.359649
6319
0.359641
6227
0.359632
6182
0.359624
6116
0.359615
6043
0.359607
6045
0.359598
6061
0.359589
5980
0.359581
5929
0.359572
5751
0.359564
5742
0.359555
5798
0.359547
5846
0.359538
5719
0.35953
5668
0.359521
5570
0.359513
5439
0.359504
5441
0.359495
5344
0.359487
5247
0.359478
5327
0.35947
5273
0.359461
5307
0.359453
5328
0.359444
5176
0.359436
5118
0.359427
5030
0.359419
5032
0.35941
4953
0.359401
4944
0.359393
4866
0.359384
4862
0.359376
4824
0.359367
4717
0.359359
4781
0.35935
4748
0.359342
4707
0.359333
4691
0.359325
4577
0.359316
4582
0.359307
4559
0.359299
4488
0.35929
4454
0.359282
4479
0.359273
4514
0.359265
4547
0.359256
4434
0.359248
4504
0.359239
4506
0.359231
4476
0.359222
4514
0.359213
4447
0.359205
4431
0.359196
4481
0.359188
4418
0.359179
4420
0.359171
4530
0.359162
4476
0.359154
4440
0.359145
4417
0.359137
4543
0.359128
4527
0.359119
4503
0.359111
4616
0.359102
4660
0.359094
4656
0.359085
4729
0.359077
4850
0.359068
4829
0.35906
4937
0.359051
5084
0.359043
5226
0.359034
5425
0.359025
5567
0.359017
5801
0.359008
6104
0.359
6335
0.358991
6798
0.358983
7169
0.358974
7772
0.358966
8472
0.358957
9225
0.358949
10295
0.35894
11504
0.358931
12935
0.358923
14433
0.358914
16480
0.358906
18174
0.358897
20438
0.358889
22778
0.35888
25425
0.358872
28030
0.358863
30584
0.358855
33543
0.358846
36702
0.358837
38905
0.358829
41746
0.35882
43866
0.358812
45629
0.358803
47767
0.358795
49091
0.358786
50028
0.358778
51221
0.358769
52130
0.358761
52158
0.358752
52376
0.358743
52708
0.358735
52230
0.358726
51825
0.358718
51523
0.358709
50149
0.358701
48732
0.358692
47340
0.358684
45466
0.358675
43492
0.358667
41176
0.358658
38159
0.358649
35526
0.358641
32406
0.358632
28971
0.358624
25940
0.358615
23124
0.358607
20275
0.358598
17643
0.35859
15228
0.358581
13058
0.358573
11192
0.358564
9882
0.358555
8788
0.358547
7634
0.358538
6977
0.35853
6292
0.358521
5888
0.358513
5512
0.358504
5302
0.358496
4959
0.358487
4987
0.358478
4751
0.35847
4705
0.358461
4581
0.358453
4481
0.358444
4522
0.358436
4457
0.358427
4359
0.358419
4419
0.35841
4357
0.358402
4325
0.358393
4305
0.358384
4241
0.358376
4140
0.358367
4126
0.358359
4221
0.35835
4235
0.358342
4152
0.358333
4152
0.358325
C 1s/54
Not Specified
2025
3
17
17
16
28
0
3
   XPS     Spectrum    Lens Mode:Hybrid   Res:20   Iris(Aper):slot(Slot)
   Acqn. Time(s): 362        Sweeps: 6        Anode:Mono(Al (Mono))(225 W)   Step(meV): 100.0
   Dwell Time(ms): 260        Charge Neutraliser :On (Current 1.9 A: Balance 3.1 V: Bias 1.1 V)   Acquired On :25/03/17 17:16:28
XPS
80.982
2.428
16
Mono(Al (Mono))
1486.69
225
1E+37
1E+37
6000
6000
1E+37
1E+37
FAT
20
1E+37
-4.9
0
1E+37
1E+37
1E+37
1E+37
C
1s
-1
Kinetic Energy
eV
1186.69
0.1
2
Intensity
d
Transmission
d
pulse counting
0.2597
6
0
1E+37
1E+37
1E+37
0
464
2394
8405
0.348291
0.349292
2892
0.349254
2894
0.349255
2937
0.349256
2928
0.349257
2877
0.349258
2940
0.34926
2977
0.349261
2910
0.349262
2916
0.349263
2954
0.349264
2959
0.349266
2894
0.349267
2897
0.349268
2870
0.349269
2873
0.34927
2863
0.349272
2849
0.349273
2895
0.349274
2871
0.349275
2938
0.349276
3017
0.349278
2847
0.349279
2813
0.34928
2847
0.349281
2922
0.349282
2848
0.349284
2874
0.349285
2824
0.349286
2853
0.349287
2795
0.349289
2832
0.34929
2864
0.349291
2891
0.349292
2824
0.349288
2837
0.349283
2859
0.349278
2880
0.349273
2838
0.349268
2835
0.349263
2876
0.349258
2844
0.349253
2788
0.349248
2784
0.349243
2857
0.349238
2688
0.349233
2684
0.349228
2831
0.349223
2750
0.349218
2775
0.349213
2822
0.349208
2737
0.349203
2773
0.349198
2730
0.349193
2665
0.349188
2664
0.349183
2782
0.349178
2747
0.349173
2781
0.349167
2732
0.349162
2709
0.349157
2681
0.349152
2675
0.349147
2705
0.349142
2773
0.349137
2697
0.349132
2724
0.349127
2656
0.349122
2662
0.349117
2614
0.349112
2740
0.349107
2692
0.349102
2638
0.349097
2691
0.349092
2687
0.349087
2686
0.349082
2626
0.349077
2684
0.349072
2692
0.349067
2627
0.349062
2640
0.349057
2606
0.349052
2631
0.349047
2593
0.349042
2710
0.349037
2615
0.349032
2619
0.349026
2703
0.349021
2692
0.349016
2662
0.349011
2644
0.349006
2650
0.349001
2619
0.348996
2622
0.348991
2593
0.348986
2652
0.348981
2601
0.348976
2622
0.348971
2628
0.348966
2638
0.348961
2617
0.348956
2586
0.348951
2600
0.348946
2701
0.348941
2640
0.348936
2609
0.348931
2605
0.348926
2663
0.348921
2630
0.348916
2654
0.348911
2667
0.348906
2757
0.348901
2761
0.348896
2816
0.34889
2813
0.348885
2821
0.34888
2831
0.348875
2777
0.34887
2830
0.348865
2963
0.34886
3001
0.348855
2973
0.34885
3038
0.348845
3119
0.34884
3220
0.348835
3032
0.34883
3128
0.348825
3102
0.34882
3089
0.348815
3117
0.34881
3096
0.348805
3108
0.3488
3115
0.348795
3010
0.34879
2914
0.348785
2978
0.34878
2914
0.348775
2889
0.34877
2815
0.348765
2838
0.34876
2864
0.348755
2879
0.348749
2821
0.348744
2860
0.348739
2933
0.348734
2876
0.348729
2939
0.348724
3020
0.348719
3018
0.348714
3123
0.348709
3143
0.348704
3168
0.348699
3284
0.348694
3405
0.348689
3571
0.348684
3620
0.348679
3625
0.348674
3640
0.348669
3891
0.348664
3977
0.348659
4164
0.348654
4162
0.348649
4296
0.348644
4425
0.348639
4682
0.348634
4971
0.348629
5351
0.348624
5626
0.348619
6006
0.348614
6520
0.348608
6934
0.348603
7421
0.348598
7737
0.348593
8151
0.348588
8348
0.348583
8405
0.348578
8390
0.348573
8353
0.348568
7960
0.348563
7478
0.348558
7022
0.348553
6386
0.348548
5857
0.348543
5202
0.348538
4757
0.348533
4210
0.348528
3846
0.348523
3474
0.348518
3249
0.348513
2986
0.348508
2830
0.348503
2759
0.348498
2719
0.348493
2604
0.348488
2550
0.348483
2565
0.348478
2583
0.348473
2545
0.348467
2600
0.348462
2494
0.348457
2518
0.348452
2605
0.348447
2477
0.348442
2523
0.348437
2516
0.348432
2500
0.348427
2502
0.348422
2496
0.348417
2446
0.348412
2473
0.348407
2418
0.348402
2487
0.348397
2530
0.348392
2523
0.348387
2518
0.348382
2516
0.348377
2459
0.348372
2495
0.348367
2456
0.348362
2576
0.348357
2539
0.348352
2492
0.348347
2475
0.348342
2491
0.348337
2450
0.348331
2517
0.348326
2405
0.348321
2476
0.348316
2498
0.348311
2450
0.348306
2394
0.348301
2438
0.348296
2435
0.348291
Al 2p/55
Not Specified
2025
3
17
17
23
50
0
3
   XPS     Spectrum    Lens Mode:Hybrid   Res:20   Iris(Aper):slot(Slot)
   Acqn. Time(s): 724        Sweeps: 12       Anode:Mono(Al (Mono))(225 W)   Step(meV): 100.0
   Dwell Time(ms): 298        Charge Neutraliser :On (Current 1.9 A: Balance 3.1 V: Bias 1.1 V)   Acquired On :25/03/17 17:23:50
XPS
80.982
2.428
16
Mono(Al (Mono))
1486.69
225
1E+37
1E+37
6000
6000
1E+37
1E+37
FAT
20
1E+37
-4.9
0
1E+37
1E+37
1E+37
1E+37
Al
2p
-1
Kinetic Energy
eV
1400.69
0.1
2
Intensity
d
Transmission
d
pulse counting
0.2985
12
0
1E+37
1E+37
1E+37
0
404
520
9528
0.333259
0.333748
863
0.333748
864
0.333746
882
0.333744
858
0.333741
910
0.333739
882
0.333736
859
0.333734
837
0.333731
870
0.333729
848
0.333726
838
0.333724
804
0.333722
845
0.333719
803
0.333717
850
0.333714
787
0.333712
786
0.333709
763
0.333707
769
0.333705
834
0.333702
883
0.3337
782
0.333697
782
0.333695
772
0.333692
715
0.33369
781
0.333687
714
0.333685
733
0.333683
765
0.33368
699
0.333678
704
0.333675
715
0.333673
736
0.33367
708
0.333668
747
0.333666
713
0.333663
705
0.333661
714
0.333658
710
0.333656
712
0.333653
725
0.333651
697
0.333649
694
0.333646
713
0.333644
705
0.333641
673
0.333639
667
0.333636
621
0.333634
656
0.333631
694
0.333629
621
0.333627
666
0.333624
617
0.333622
592
0.333619
613
0.333617
651
0.333614
619
0.333612
633
0.333609
588
0.333607
599
0.333605
613
0.333602
591
0.3336
583
0.333597
581
0.333595
584
0.333592
583
0.33359
575
0.333588
629
0.333585
565
0.333583
538
0.33358
575
0.333578
551
0.333575
605
0.333573
573
0.333571
535
0.333568
567
0.333566
533
0.333563
577
0.333561
543
0.333558
570
0.333556
564
0.333553
591
0.333551
565
0.333549
520
0.333546
590
0.333544
595
0.333541
558
0.333539
557
0.333536
563
0.333534
635
0.333532
583
0.333529
603
0.333527
587
0.333524
592
0.333522
520
0.333519
591
0.333517
583
0.333514
617
0.333512
610
0.33351
643
0.333507
624
0.333505
642
0.333502
619
0.3335
616
0.333497
598
0.333495
627
0.333493
655
0.33349
708
0.333488
669
0.333485
696
0.333483
809
0.33348
754
0.333478
803
0.333475
890
0.333473
911
0.333471
1021
0.333468
1265
0.333466
1367
0.333463
1552
0.333461
1855
0.333458
2171
0.333456
2531
0.333454
3006
0.333451
3604
0.333449
4046
0.333446
4782
0.333444
5406
0.333441
6260
0.333439
6790
0.333436
7635
0.333434
8297
0.333432
8849
0.333429
9201
0.333427
9396
0.333424
9528
0.333422
9356
0.333419
9212
0.333417
8730
0.333415
8230
0.333412
7542
0.33341
6812
0.333407
5975
0.333405
5217
0.333402
4454
0.3334
3756
0.333398
3071
0.333395
2512
0.333393
2191
0.33339
1805
0.333388
1531
0.333385
1287
0.333383
1053
0.33338
955
0.333378
853
0.333376
755
0.333373
716
0.333371
649
0.333368
629
0.333366
656
0.333363
597
0.333361
626
0.333359
595
0.333356
605
0.333354
586
0.333351
620
0.333349
621
0.333346
611
0.333344
593
0.333341
572
0.333339
603
0.333337
614
0.333334
583
0.333332
589
0.333329
588
0.333327
590
0.333324
588
0.333322
587
0.33332
604
0.333317
564
0.333315
556
0.333312
581
0.33331
595
0.333307
592
0.333305
585
0.333302
591
0.3333
596
0.333298
595
0.333295
618
0.333293
639
0.33329
591
0.333288
590
0.333285
578
0.333283
542
0.333281
612
0.333278
599
0.333276
615
0.333273
599
0.333271
607
0.333268
563
0.333266
561
0.333263
577
0.333261
586
0.333259
end of experiment