File: 06_XPS_Analysis/data/raw/XPS/04042024_DuncanReece_RIT2678.vms
VAMAS Surface Chemical Analysis Standard Data Transfer Format 1988 May 4
Not Specified
Kratos Axis
Not Specified
/C=/data/2024/04-2024/04042024_DuncanReece_RIT2678.dset
0
MAP
REGULAR
5
37
32768
32768
1
Angle
degree
0
0
0
0
108
Survey/2
Not Specified
2024
4
4
17
34
51
0
3
   XPS     Spectrum    Lens Mode:Hybrid   Res:80   Iris(Aper):slot(Slot)
   Acqn. Time(s): 121        Sweeps: 1        Anode:Mono(Al (Mono))(225 W)   Step(meV): 1000.0
   Dwell Time(ms): 100        Charge Neutraliser :On (Current 1.9 A: Balance 3.6 V: Bias 1.1 V)   Acquired On :24/04/04 17:34:51
XPS
9.084
0.361
1
Mono(Al (Mono))
1486.69
225
1E+37
1E+37
6000
6000
1E+37
1E+37
FAT
80
1E+37
-4.6
0
1E+37
1E+37
1E+37
1E+37
Wide
None
-1
Kinetic Energy
eV
286.69
1
2
Intensity
d
Transmission
d
pulse counting
0.1
0
1E+37
0
0
1.47543
891
967
955
910
938
929
925
949
957
953
995
942
998
953
983
963
958
913
977
975
939
963
990
967
984
991
954
983
952
999
1018
989
994
986
1020
966
1014
963
976
1007
973
975
945
1007
1009
993
1052
1032
1027
1045
1011
1021
1014
1039
1018
1020
1062
1009
1025
1056
988
990
1015
1064
1033
1023
999
1078
1079
1031
1039
989
1018
1086
1042
1055
1078
1117
1094
1043
1062
1069
1099
1081
1092
1061
1119
1056
1065
1035
1111
1070
1086
1088
1132
1115
1090
1125
1115
1089
1089
1122
1140
1146
1111
1095
1072
1133
1078
1138
1160
1169
1112
1168
1095
1114
1070
1161
1157
1179
1166
1125
1137
1161
1175
1165
1178
1176
1167
1189
1179
1169
1161
1119
1184
1196
1192
1185
1210
1205
1181
1212
1232
1255
1236
1278
1225
1202
1247
1219
1230
1246
1240
1223
1231
1288
1242
1261
1288
1273
1254
1273
1302
1279
1300
1348
1310
1307
1315
1289
1293
1275
1328
1284
1315
1330
1322
1391
1317
1323
1368
1441
1362
1319
1333
1350
1363
1351
1378
1424
1388
1376
1344
1345
1369
1337
1371
1327
1449
1481
1503
1526
1617
1572
1543
1537
1495
1408
1357
1292
1321
1236
1202
1191
1128
1083
1102
1181
1174
1329
1511
1714
1857
1936
2017
1992
1694
1451
1326
1239
1124
1068
980
902
831
793
694
667
634
635
640
634
656
621
607
608
673
672
603
634
638
629
615
634
628
643
643
627
624
662
652
661
613
647
644
648
649
635
672
638
658
649
694
662
660
629
644
638
613
612
657
662
648
710
655
678
681
650
653
656
673
694
711
643
666
689
682
667
700
677
703
676
698
671
673
698
705
712
690
676
669
681
668
679
672
656
675
679
706
712
709
668
682
683
672
715
703
697
703
716
704
736
718
728
712
744
706
714
721
715
724
755
771
732
719
747
734
716
741
749
685
718
736
739
719
724
750
740
761
761
770
730
783
769
769
778
754
762
756
731
748
780
783
798
754
781
764
737
770
762
748
723
734
778
778
779
808
808
768
787
833
812
836
809
777
782
773
806
809
811
785
814
810
853
845
809
840
820
802
785
828
789
809
836
831
851
825
871
838
830
842
864
832
831
861
841
822
812
814
821
820
820
837
852
852
874
860
892
846
834
883
854
852
873
878
858
896
913
870
914
887
842
832
862
878
899
901
902
846
832
859
915
897
928
915
911
897
900
931
947
939
935
929
972
948
971
954
924
976
917
954
940
928
921
928
973
992
973
945
985
972
982
974
958
946
990
1026
953
1034
999
993
1044
978
976
995
997
988
1008
1008
1043
1066
1056
1108
1065
1048
1094
1090
1130
1092
996
1054
1064
1045
1046
1054
1065
1104
1078
1046
1056
1102
1070
1072
1099
1074
1097
1107
1066
1087
1102
1078
1077
1050
1089
1070
1134
1139
1083
1086
1080
1072
1109
1152
1117
1146
1204
1213
1129
1146
1125
1144
1145
1163
1157
1143
1188
1193
1165
1167
1231
1213
1210
1165
1202
1173
1228
1233
1236
1230
1197
1261
1182
1195
1298
1251
1233
1223
1207
1253
1235
1252
1288
1245
1278
1258
1278
1270
1232
1236
1310
1333
1273
1290
1278
1285
1316
1276
1275
1305
1314
1286
1353
1402
1335
1352
1342
1331
1397
1424
1419
1398
1386
1355
1376
1374
1416
1398
1386
1413
1399
1369
1361
1394
1336
1331
1341
1368
1344
1346
1367
1391
1390
1473
1557
1595
1686
1736
1751
1774
1785
1712
1589
1440
1313
1234
1159
1094
1047
1017
902
865
780
688
674
595
576
620
734
1143
2545
5964
8444
5340
1572
691
528
527
493
488
455
465
444
499
464
502
481
512
460
502
480
473
488
493
475
457
458
466
470
467
460
480
454
510
478
466
479
491
495
521
503
487
473
498
482
448
466
483
505
507
511
490
495
479
487
504
492
500
476
495
470
465
518
489
492
504
508
501
477
477
488
492
471
500
485
458
477
493
462
488
476
493
489
500
499
481
494
462
512
519
518
506
510
521
502
487
500
501
502
488
503
528
512
524
497
471
479
506
501
471
500
495
530
508
500
500
485
504
497
470
507
522
527
511
480
489
482
485
482
510
501
547
577
517
548
499
484
483
533
520
487
520
512
484
491
486
495
475
480
521
547
525
481
484
502
545
526
541
487
557
544
547
548
543
523
515
496
484
531
508
510
514
526
521
532
517
517
541
520
536
550
550
504
512
500
534
531
512
487
536
489
531
528
526
502
514
539
552
539
537
517
511
507
539
527
509
535
582
538
580
553
542
546
555
554
508
526
534
554
549
554
562
529
545
541
562
563
526
567
562
544
512
531
544
542
527
534
539
543
522
505
514
504
506
573
553
649
978
1372
1020
620
519
449
504
476
433
499
504
477
466
459
484
474
464
438
463
464
496
475
444
454
448
465
423
461
477
463
426
464
471
447
448
464
449
485
516
439
442
465
449
423
423
447
436
456
437
411
427
421
433
442
453
450
439
438
459
424
417
445
455
430
404
408
430
405
410
422
407
424
402
421
426
417
396
408
432
421
400
399
398
402
376
369
396
364
390
431
391
379
358
355
351
379
376
423
376
368
398
386
374
353
367
382
351
356
362
387
359
371
380
368
370
367
397
393
369
393
395
385
382
395
401
393
367
393
360
358
338
317
373
381
386
378
422
432
394
350
372
369
407
418
456
423
371
393
359
382
309
322
320
342
313
306
257
234
240
236
223
266
271
282
336
656
1403
1852
1165
509
306
234
219
196
198
196
192
198
216
193
192
172
172
172
211
213
220
212
280
256
223
226
202
201
189
153
157
154
142
133
129
98
98
91
83
70
68
86
82
110
336
1095
1425
571
141
88
67
77
69
62
65
71
62
61
59
73
57
66
64
65
74
66
60
61
71
76
73
68
82
76
81
80
81
73
62
69
59
46
57
67
55
49
61
67
64
55
63
60
81
95
124
195
260
275
201
116
60
33
20
24
22
14
19
22
19
40
75
62
57
63
73
56
30
14
3
1
0
2
0
0
1.47543
Sn 3d/3
Not Specified
2024
4
4
17
37
39
0
3
   XPS     Spectrum    Lens Mode:Hybrid   Res:80   Iris(Aper):slot(Slot)
   Acqn. Time(s): 141        Sweeps: 6        Anode:Mono(Al (Mono))(225 W)   Step(meV): 300.0
   Dwell Time(ms): 298        Charge Neutraliser :On (Current 1.9 A: Balance 3.6 V: Bias 1.1 V)   Acquired On :24/04/04 17:37:39
XPS
9.084
0.361
1
Mono(Al (Mono))
1486.69
225
1E+37
1E+37
6000
6000
1E+37
1E+37
FAT
80
1E+37
-4.6
0
1E+37
1E+37
1E+37
1E+37
Sn
3d
-1
Kinetic Energy
eV
986.69
0.3
2
Intensity
d
Transmission
d
pulse counting
0.2985
6
0
1E+37
1E+37
1E+37
0
158
8486
8944
1.64313
1.65517
8565
1.65517
8750
1.65501
8688
1.65486
8678
1.6547
8501
1.65455
8558
1.6544
8559
1.65424
8638
1.65409
8645
1.65393
8848
1.65378
8732
1.65362
8726
1.65347
8675
1.65332
8613
1.65316
8625
1.65301
8486
1.65285
8656
1.6527
8743
1.65254
8723
1.65239
8635
1.65223
8743
1.65208
8755
1.65193
8787
1.65177
8783
1.65162
8807
1.65146
8669
1.65131
8621
1.65115
8772
1.651
8669
1.65085
8721
1.65069
8773
1.65054
8655
1.65038
8626
1.65023
8809
1.65007
8743
1.64992
8560
1.64977
8755
1.64961
8707
1.64946
8776
1.6493
8729
1.64915
8774
1.64899
8816
1.64884
8815
1.64868
8729
1.64853
8837
1.64838
8702
1.64822
8630
1.64807
8742
1.64791
8754
1.64776
8695
1.6476
8607
1.64745
8795
1.6473
8745
1.64714
8825
1.64699
8792
1.64683
8852
1.64668
8551
1.64652
8702
1.64637
8691
1.64622
8809
1.64606
8779
1.64591
8820
1.64575
8746
1.6456
8736
1.64544
8861
1.64529
8720
1.64513
8627
1.64498
8812
1.64483
8944
1.64467
8754
1.64452
8824
1.64436
8867
1.64421
8744
1.64405
8884
1.6439
8847
1.64375
8784
1.64359
8756
1.64344
8837
1.64328
8809
1.64313
Survey/6
Not Specified
2024
4
4
17
41
28
0
3
   XPS     Spectrum    Lens Mode:Hybrid   Res:80   Iris(Aper):slot(Slot)
   Acqn. Time(s): 121        Sweeps: 1        Anode:Mono(Al (Mono))(225 W)   Step(meV): 1000.0
   Dwell Time(ms): 100        Charge Neutraliser :On (Current 1.9 A: Balance 3.6 V: Bias 1.1 V)   Acquired On :24/04/04 17:41:28
XPS
10.678
1.878
2
Mono(Al (Mono))
1486.69
225
1E+37
1E+37
6000
6000
1E+37
1E+37
FAT
80
1E+37
-4.6
0
1E+37
1E+37
1E+37
1E+37
Wide
None
-1
Kinetic Energy
eV
286.69
1
2
Intensity
d
Transmission
d
pulse counting
0.1
0
1E+37
0
0
1.47543
948
976
951
951
916
933
940
931
958
938
963
930
953
948
931
969
972
978
983
960
968
963
958
966
922
960
999
969
921
957
931
956
986
963
954
1006
1017
1032
1046
1030
1016
1024
1014
1042
1046
1001
1018
1002
1000
1009
983
977
1011
1020
1000
1013
958
1008
981
1040
994
967
996
1054
1023
1006
1054
1076
1074
1050
1003
1058
1061
1078
1044
1042
1064
1056
1028
1008
1080
1089
1087
1070
1062
1074
1079
1073
1114
1058
1083
1071
1106
1133
1118
1133
1139
1130
1064
1094
1082
1081
1076
1150
1089
1116
1094
1150
1170
1101
1114
1158
1191
1113
1121
1121
1127
1121
1177
1137
1155
1154
1169
1181
1111
1122
1105
1143
1175
1207
1189
1162
1193
1163
1225
1213
1190
1171
1181
1212
1209
1230
1233
1242
1197
1246
1228
1167
1208
1193
1207
1251
1276
1230
1242
1250
1253
1247
1296
1291
1232
1295
1230
1282
1302
1318
1274
1313
1270
1296
1271
1321
1264
1305
1281
1288
1324
1348
1330
1342
1364
1394
1406
1368
1427
1424
1414
1441
1413
1400
1415
1447
1359
1385
1379
1314
1365
1444
1477
1495
1528
1537
1605
1648
1646
1481
1431
1395
1333
1254
1241
1198
1134
1116
1165
1161
1162
1141
1273
1432
1530
1695
1899
2009
1990
1879
1652
1420
1285
1199
1135
1074
988
906
829
764
739
699
711
624
611
612
651
681
643
588
602
611
626
641
631
652
624
647
630
621
584
634
596
650
647
626
645
685
639
627
623
663
654
634
605
643
661
669
622
693
617
607
635
651
674
628
633
657
663
654
692
664
681
662
659
675
650
683
633
687
721
691
644
629
659
633
678
708
668
688
686
644
686
662
688
677
664
676
674
711
735
707
712
690
684
697
700
723
725
721
665
716
693
683
704
712
684
722
692
727
723
702
700
697
715
722
739
723
731
738
746
741
707
725
733
716
757
768
732
743
783
742
737
754
760
745
771
782
786
755
742
730
772
799
784
760
831
804
785
786
781
761
772
779
766
745
781
805
772
791
785
765
778
750
732
746
775
798
760
811
768
796
786
794
805
801
817
793
839
776
820
795
791
811
803
803
825
803
828
837
820
848
835
815
843
817
817
787
836
828
864
860
810
807
828
829
843
891
890
850
871
848
844
847
859
879
859
886
850
870
909
884
881
856
879
901
933
900
910
859
881
862
901
903
912
896
913
951
921
836
891
892
925
928
907
945
908
907
966
930
955
924
918
952
956
947
945
970
931
935
990
993
964
973
962
980
1008
987
983
1025
949
986
961
1028
991
1007
988
962
993
1046
1028
1024
991
974
999
1025
1009
1009
1031
1054
1053
1100
1082
1079
1007
994
1039
1059
1038
1005
1003
1068
1091
1092
1064
1094
1093
1013
1059
1069
1090
1130
1041
1095
1113
1076
1099
1084
1124
1119
1111
1125
1126
1112
1128
1135
1164
1123
1126
1138
1155
1136
1105
1148
1123
1146
1152
1169
1184
1185
1176
1160
1167
1235
1180
1176
1154
1206
1223
1220
1246
1207
1208
1224
1192
1238
1237
1230
1236
1275
1258
1230
1228
1239
1230
1280
1286
1254
1273
1217
1272
1299
1249
1319
1309
1297
1297
1291
1331
1319
1342
1333
1353
1348
1322
1297
1307
1321
1307
1346
1352
1355
1350
1348
1435
1353
1377
1375
1409
1389
1373
1406
1378
1375
1406
1385
1378
1350
1392
1366
1339
1362
1367
1310
1380
1445
1524
1500
1584
1653
1765
1792
1751
1807
1647
1583
1420
1332
1186
1139
1044
1013
967
884
794
734
694
634
602
576
645
778
1355
3282
6955
8113
4243
1265
628
545
503
479
454
458
470
471
479
488
509
478
481
437
474
484
505
502
467
443
487
511
478
492
469
486
472
483
469
458
465
483
477
479
486
473
485
471
491
471
466
475
515
524
482
486
510
497
495
508
485
462
526
463
493
484
523
485
524
486
501
498
495
489
532
501
500
474
471
498
506
475
493
475
517
509
511
493
523
519
477
495
491
514
527
513
509
517
504
507
488
518
511
481
523
503
501
499
508
500
497
535
523
527
524
495
532
518
514
537
547
519
515
490
503
501
491
507
523
475
490
488
538
507
526
512
523
512
534
560
537
488
506
524
505
502
506
487
549
512
522
512
517
528
527
499
523
551
529
528
522
532
501
528
515
520
492
526
539
485
541
526
481
519
520
538
515
514
536
532
540
523
497
496
521
486
501
551
509
528
535
522
546
545
537
540
527
530
497
491
507
498
491
545
520
547
558
579
552
533
550
565
514
519
549
513
556
530
543
548
558
559
544
557
553
541
545
557
568
537
557
543
515
565
563
573
556
523
523
492
497
496
505
469
463
497
493
517
539
561
526
692
1123
1320
848
547
491
499
476
486
461
454
456
485
450
475
483
484
453
452
419
439
458
481
499
476
451
495
510
474
460
474
447
466
432
464
496
460
430
429
461
467
452
455
468
453
419
427
403
431
449
433
468
438
445
445
427
429
442
435
452
477
435
418
487
439
421
401
429
430
426
410
425
436
396
423
419
417
393
400
414
406
415
428
406
408
419
402
406
385
386
395
389
383
389
384
406
409
399
389
380
407
422
385
382
394
364
368
384
382
370
352
377
356
383
408
372
363
359
394
394
375
348
382
401
392
390
336
334
360
345
342
338
338
373
358
379
401
411
436
402
385
384
373
382
404
403
418
463
404
378
355
339
357
315
320
279
275
257
239
248
232
221
222
239
285
435
865
1594
1670
895
418
272
248
225
221
203
202
210
174
198
185
172
180
169
170
203
225
237
255
302
235
225
208
213
180
181
156
159
149
132
117
123
105
101
106
77
91
77
86
100
147
531
1408
1162
304
101
79
64
65
50
53
71
73
74
75
65
58
65
71
61
67
51
64
68
62
72
92
78
92
79
70
75
82
74
59
64
58
53
52
55
55
63
55
48
53
57
59
78
70
90
103
122
193
246
249
171
88
49
28
22
14
13
11
11
14
31
65
79
77
59
49
55
59
24
11
2
6
0
1
0
0
1.47543
Sn 3d/7
Not Specified
2024
4
4
17
44
11
0
3
   XPS     Spectrum    Lens Mode:Hybrid   Res:80   Iris(Aper):slot(Slot)
   Acqn. Time(s): 141        Sweeps: 6        Anode:Mono(Al (Mono))(225 W)   Step(meV): 300.0
   Dwell Time(ms): 298        Charge Neutraliser :On (Current 1.9 A: Balance 3.6 V: Bias 1.1 V)   Acquired On :24/04/04 17:44:11
XPS
10.678
1.878
2
Mono(Al (Mono))
1486.69
225
1E+37
1E+37
6000
6000
1E+37
1E+37
FAT
80
1E+37
-4.6
0
1E+37
1E+37
1E+37
1E+37
Sn
3d
-1
Kinetic Energy
eV
986.69
0.3
2
Intensity
d
Transmission
d
pulse counting
0.2985
6
0
1E+37
1E+37
1E+37
0
158
8471
8899
1.64313
1.65517
8598
1.65517
8608
1.65501
8613
1.65486
8656
1.6547
8636
1.65455
8697
1.6544
8748
1.65424
8692
1.65409
8828
1.65393
8617
1.65378
8597
1.65362
8745
1.65347
8771
1.65332
8656
1.65316
8732
1.65301
8609
1.65285
8735
1.6527
8679
1.65254
8637
1.65239
8653
1.65223
8790
1.65208
8712
1.65193
8582
1.65177
8559
1.65162
8712
1.65146
8580
1.65131
8471
1.65115
8743
1.651
8809
1.65085
8724
1.65069
8728
1.65054
8693
1.65038
8671
1.65023
8688
1.65007
8662
1.64992
8692
1.64977
8742
1.64961
8647
1.64946
8735
1.6493
8642
1.64915
8720
1.64899
8847
1.64884
8697
1.64868
8685
1.64853
8682
1.64838
8738
1.64822
8813
1.64807
8764
1.64791
8734
1.64776
8755
1.6476
8697
1.64745
8680
1.6473
8716
1.64714
8790
1.64699
8740
1.64683
8729
1.64668
8873
1.64652
8857
1.64637
8899
1.64622
8898
1.64606
8829
1.64591
8837
1.64575
8654
1.6456
8649
1.64544
8643
1.64529
8869
1.64513
8812
1.64498
8788
1.64483
8827
1.64467
8824
1.64452
8812
1.64436
8816
1.64421
8802
1.64405
8827
1.6439
8827
1.64375
8722
1.64359
8796
1.64344
8762
1.64328
8853
1.64313
Survey/10
Not Specified
2024
4
4
17
48
4
0
3
   XPS     Spectrum    Lens Mode:Hybrid   Res:80   Iris(Aper):slot(Slot)
   Acqn. Time(s): 121        Sweeps: 1        Anode:Mono(Al (Mono))(225 W)   Step(meV): 1000.0
   Dwell Time(ms): 100        Charge Neutraliser :On (Current 1.9 A: Balance 3.6 V: Bias 1.1 V)   Acquired On :24/04/04 17:48:04
XPS
8.784
4.665
3
Mono(Al (Mono))
1486.69
225
1E+37
1E+37
6000
6000
1E+37
1E+37
FAT
80
1E+37
-4.6
0
1E+37
1E+37
1E+37
1E+37
Wide
None
-1
Kinetic Energy
eV
286.69
1
2
Intensity
d
Transmission
d
pulse counting
0.1
0
1E+37
0
0
1.47543
959
904
949
933
949
928
937
905
943
970
952
979
969
977
1014
992
1013
977
968
971
937
953
942
951
987
998
987
966
965
968
977
927
958
968
1003
975
1007
978
985
1026
983
1006
949
992
1038
1027
992
996
1047
1011
999
965
1007
993
977
1008
1017
1027
1052
1054
1078
1081
1068
1098
1065
1013
1022
1054
1037
1009
978
1049
1039
1008
1043
1040
1075
1036
1004
972
1039
1061
1090
1061
1073
1051
1066
1094
1109
1138
1104
1115
1078
1078
1143
1114
1126
1112
1104
1141
1108
1071
1078
1068
1089
1131
1091
1066
1148
1168
1170
1099
1153
1130
1122
1134
1123
1161
1103
1136
1091
1111
1164
1164
1176
1159
1130
1152
1196
1183
1176
1196
1186
1169
1201
1195
1155
1181
1222
1203
1234
1208
1196
1177
1170
1203
1214
1230
1216
1206
1248
1224
1231
1276
1250
1274
1262
1232
1261
1271
1288
1341
1351
1323
1268
1226
1250
1283
1276
1289
1366
1357
1313
1351
1359
1370
1377
1333
1347
1387
1379
1348
1408
1395
1427
1405
1365
1380
1421
1409
1380
1366
1358
1345
1346
1330
1355
1386
1396
1445
1544
1597
1578
1601
1506
1537
1510
1397
1353
1345
1307
1245
1177
1138
1115
1078
1118
1155
1189
1278
1456
1648
1781
1920
1976
2010
1772
1517
1347
1248
1109
1066
1051
961
863
803
735
679
653
633
663
639
674
651
646
641
614
601
630
608
581
593
609
649
607
616
648
650
668
653
647
642
606
649
625
634
651
680
631
620
629
674
674
648
682
640
642
623
612
635
659
644
609
664
700
683
672
699
698
678
635
635
644
682
604
657
691
693
663
672
689
662
687
704
669
680
703
689
676
651
692
667
711
690
697
696
696
695
723
685
694
708
698
689
681
728
715
719
706
714
729
730
715
729
703
754
716
692
727
702
709
731
731
711
738
740
757
738
781
753
738
728
731
728
761
814
747
731
741
737
762
749
727
752
751
771
772
765
768
769
802
734
796
782
786
761
750
764
745
803
766
790
790
784
799
754
782
756
808
827
821
784
781
775
743
817
809
788
779
805
798
782
795
801
780
811
831
814
822
765
797
767
842
846
843
809
822
832
833
859
837
844
795
804
847
846
842
880
857
895
889
870
884
818
882
880
874
861
891
908
864
867
865
858
900
870
880
895
901
911
868
894
898
885
923
922
875
902
876
893
937
928
942
924
905
906
928
904
908
896
932
873
897
938
915
958
956
971
923
950
1011
994
957
969
968
959
931
987
952
965
906
982
1024
972
987
997
989
1017
1003
982
978
1024
1025
934
950
1008
1041
1014
967
1002
1036
1010
974
1041
1061
1044
1088
1110
1074
1051
1020
1088
1066
1060
1090
1097
1056
1032
1089
1045
1072
1056
1023
1102
1096
1075
1091
1086
1070
1107
1144
1086
1102
1086
1085
1137
1117
1082
1122
1097
1119
1120
1151
1120
1113
1146
1151
1156
1149
1188
1143
1139
1163
1141
1179
1165
1180
1280
1196
1214
1250
1192
1234
1274
1223
1173
1226
1210
1197
1202
1264
1274
1298
1239
1232
1272
1264
1250
1224
1274
1278
1278
1251
1206
1250
1276
1274
1234
1241
1282
1299
1334
1294
1316
1291
1281
1297
1309
1333
1376
1326
1314
1370
1321
1361
1414
1378
1348
1340
1346
1326
1359
1390
1361
1368
1383
1411
1409
1411
1381
1420
1367
1338
1375
1299
1346
1316
1314
1346
1336
1379
1399
1449
1467
1583
1665
1702
1751
1763
1757
1723
1570
1450
1319
1200
1155
1097
1059
974
927
850
788
758
664
635
574
612
713
1043
2337
5519
8112
5712
2024
773
553
530
469
488
497
461
488
509
468
501
473
477
493
485
488
465
467
450
459
477
487
471
481
476
462
521
476
481
478
501
459
460
513
491
479
496
497
490
510
496
511
482
498
462
468
476
486
511
482
497
517
508
457
475
466
495
483
490
477
487
486
475
510
486
525
512
488
491
518
493
500
496
531
522
524
497
511
469
494
499
444
520
504
458
480
499
543
496
494
534
498
520
508
518
516
525
500
520
518
480
505
506
510
522
517
525
492
486
508
523
495
531
518
494
490
521
486
516
475
489
502
521
455
487
493
518
546
563
550
522
516
511
497
502
494
531
538
511
508
482
497
512
489
519
512
493
546
512
505
513
514
497
474
531
512
517
497
500
493
498
511
540
541
513
494
509
522
518
516
529
529
531
525
504
522
508
519
515
504
539
530
494
504
549
516
528
520
538
496
520
528
550
565
543
546
531
485
508
500
487
536
512
510
529
552
540
532
528
516
565
550
553
555
559
547
535
513
522
523
516
575
518
556
540
540
533
529
544
583
541
483
492
514
462
494
495
550
537
517
541
648
914
1324
1029
601
505
499
468
450
438
431
465
477
449
467
473
465
426
445
437
443
415
457
428
444
465
493
458
475
438
458
453
479
408
419
420
445
452
462
408
426
440
450
432
453
448
455
423
434
443
427
432
463
418
435
404
403
398
439
442
460
439
398
405
415
403
398
407
414
407
390
396
398
406
419
387
396
387
387
408
407
421
395
397
378
418
407
371
382
390
405
384
350
347
385
401
358
391
407
396
397
383
397
390
400
376
399
342
362
407
397
364
374
359
400
351
364
343
349
379
386
394
368
406
366
360
346
336
342
356
372
358
368
364
369
355
382
380
417
411
374
386
383
386
398
417
402
396
394
392
382
388
351
348
345
308
269
267
255
221
218
232
214
232
280
336
626
1284
1795
1225
558
305
242
226
218
194
176
180
203
198
201
153
160
193
185
190
226
218
222
291
238
215
204
208
185
174
175
178
164
147
137
105
120
109
85
72
80
79
80
87
110
271
1005
1410
670
158
94
77
61
68
66
61
60
74
56
63
71
60
60
66
65
70
81
61
78
85
79
81
78
89
78
86
90
92
65
56
56
61
56
49
62
48
33
63
50
48
59
57
67
73
85
127
150
234
241
213
128
53
40
19
22
16
11
17
18
26
51
67
80
57
57
66
61
32
17
2
3
2
1
0
0
1.47543
Sn 3d/11
Not Specified
2024
4
4
17
50
47
0
3
   XPS     Spectrum    Lens Mode:Hybrid   Res:80   Iris(Aper):slot(Slot)
   Acqn. Time(s): 141        Sweeps: 6        Anode:Mono(Al (Mono))(225 W)   Step(meV): 300.0
   Dwell Time(ms): 298        Charge Neutraliser :On (Current 1.9 A: Balance 3.6 V: Bias 1.1 V)   Acquired On :24/04/04 17:50:47
XPS
8.784
4.665
3
Mono(Al (Mono))
1486.69
225
1E+37
1E+37
6000
6000
1E+37
1E+37
FAT
80
1E+37
-4.6
0
1E+37
1E+37
1E+37
1E+37
Sn
3d
-1
Kinetic Energy
eV
986.69
0.3
2
Intensity
d
Transmission
d
pulse counting
0.2985
6
0
1E+37
1E+37
1E+37
0
158
8564
8853
1.64313
1.65517
8578
1.65517
8616
1.65501
8666
1.65486
8637
1.6547
8736
1.65455
8782
1.6544
8587
1.65424
8669
1.65409
8673
1.65393
8702
1.65378
8713
1.65362
8620
1.65347
8689
1.65332
8688
1.65316
8624
1.65301
8721
1.65285
8571
1.6527
8718
1.65254
8716
1.65239
8679
1.65223
8658
1.65208
8702
1.65193
8646
1.65177
8684
1.65162
8628
1.65146
8733
1.65131
8830
1.65115
8761
1.651
8733
1.65085
8629
1.65069
8619
1.65054
8674
1.65038
8711
1.65023
8591
1.65007
8638
1.64992
8801
1.64977
8707
1.64961
8647
1.64946
8738
1.6493
8669
1.64915
8726
1.64899
8663
1.64884
8604
1.64868
8747
1.64853
8564
1.64838
8651
1.64822
8656
1.64807
8764
1.64791
8700
1.64776
8721
1.6476
8679
1.64745
8713
1.6473
8751
1.64714
8776
1.64699
8730
1.64683
8752
1.64668
8769
1.64652
8802
1.64637
8800
1.64622
8835
1.64606
8707
1.64591
8713
1.64575
8630
1.6456
8709
1.64544
8812
1.64529
8709
1.64513
8741
1.64498
8723
1.64483
8692
1.64467
8737
1.64452
8658
1.64436
8768
1.64421
8781
1.64405
8670
1.6439
8735
1.64375
8853
1.64359
8749
1.64344
8767
1.64328
8774
1.64313
Survey/14
Not Specified
2024
4
4
17
54
43
0
3
   XPS     Spectrum    Lens Mode:Hybrid   Res:80   Iris(Aper):slot(Slot)
   Acqn. Time(s): 121        Sweeps: 1        Anode:Mono(Al (Mono))(225 W)   Step(meV): 1000.0
   Dwell Time(ms): 100        Charge Neutraliser :On (Current 1.9 A: Balance 3.6 V: Bias 1.1 V)   Acquired On :24/04/04 17:54:43
XPS
26.944
4.665
4
Mono(Al (Mono))
1486.69
225
1E+37
1E+37
6000
6000
1E+37
1E+37
FAT
80
1E+37
-4.6
0
1E+37
1E+37
1E+37
1E+37
Wide
None
-1
Kinetic Energy
eV
286.69
1
2
Intensity
d
Transmission
d
pulse counting
0.1
0
1E+37
0
0
1.47543
713
661
683
707
702
684
705
737
734
716
730
742
725
718
714
702
692
727
736
776
734
701
718
693
698
720
731
726
695
719
719
730
716
751
747
729
725
752
743
758
719
737
715
751
778
784
752
749
721
764
741
714
738
754
770
749
786
762
752
767
788
760
759
748
750
810
811
790
732
765
775
780
781
794
778
785
751
817
768
789
782
822
796
812
796
818
772
766
824
804
805
791
847
798
820
786
814
782
769
804
760
798
811
781
859
813
836
809
785
818
827
845
844
813
818
819
827
814
839
835
875
837
819
821
851
863
854
865
879
839
835
849
875
857
882
846
829
854
863
858
896
851
853
871
877
821
845
851
852
869
895
910
921
918
946
900
898
862
847
910
923
914
874
913
900
927
968
913
938
929
940
900
904
924
879
946
918
948
949
929
951
928
971
972
971
996
956
922
991
970
952
979
935
940
957
939
1008
1021
1008
944
1026
1009
1113
1078
1077
1070
1069
990
974
927
900
955
925
930
923
872
866
869
893
941
1012
1062
1146
1186
1237
1271
1207
1092
1103
992
895
930
835
758
730
678
683
647
637
636
632
626
625
626
559
559
597
575
596
593
593
589
586
561
599
591
591
593
582
593
604
570
591
612
595
595
564
577
599
601
611
639
606
634
637
584
652
624
623
595
609
631
617
609
636
601
619
607
627
639
651
668
625
639
622
612
623
653
614
626
623
634
662
679
664
675
652
648
667
640
619
583
659
656
675
649
627
690
643
617
636
699
656
673
695
676
672
621
647
694
631
624
622
638
658
671
669
672
589
675
666
644
662
706
693
648
669
656
691
681
679
669
692
686
699
672
699
710
710
685
699
716
668
733
716
714
733
692
716
695
693
731
681
699
728
660
707
673
727
711
742
742
671
716
696
692
697
722
715
727
691
681
739
711
711
721
733
740
725
754
770
747
728
718
762
772
751
733
747
720
759
751
755
753
729
767
761
745
775
736
790
762
769
805
733
766
741
792
749
785
763
758
816
797
760
769
763
768
794
781
828
769
791
813
782
773
786
809
804
764
788
814
766
828
802
827
822
784
780
842
822
823
834
832
783
795
837
843
837
850
766
772
827
823
825
828
833
802
845
886
855
835
878
853
848
826
793
858
797
824
836
849
872
839
837
839
837
852
844
860
855
884
850
824
844
900
878
893
896
923
868
885
829
904
935
936
912
966
910
914
901
932
872
917
903
896
933
899
897
909
888
906
908
941
927
899
928
926
927
869
912
925
944
945
875
917
926
879
964
939
911
924
944
926
964
997
981
982
991
949
935
936
943
963
972
950
976
967
931
972
933
943
959
906
981
981
991
969
989
1001
972
1011
969
994
1029
1002
954
967
1018
974
991
1001
1023
1027
1004
995
966
982
1011
1066
1015
994
975
1051
988
1001
1006
1024
1048
1002
1019
1047
999
1017
997
980
1002
1040
1031
1031
1018
1034
1052
1001
1026
1047
1021
1028
1058
1043
966
1020
1032
1025
999
1008
991
994
999
997
1017
1054
1077
1093
1070
1115
1166
1181
1153
1112
1128
1144
1033
1045
1024
938
908
883
796
780
755
690
707
694
678
648
669
727
767
1084
2541
4446
3469
1692
820
603
571
556
580
533
582
577
582
574
544
556
568
557
564
569
610
583
546
570
534
566
536
525
599
550
589
568
573
572
552
555
581
566
550
571
580
597
544
536
546
566
540
591
562
589
559
561
575
575
598
588
586
587
552
547
565
579
585
624
615
582
594
555
561
571
585
575
606
593
578
582
592
595
606
610
602
591
594
631
605
579
564
584
559
590
576
604
602
614
551
598
584
604
590
605
621
610
594
574
602
606
597
588
578
634
601
602
583
554
595
572
558
619
648
636
631
625
634
621
624
617
596
612
633
622
587
610
626
626
610
618
612
600
599
611
593
587
583
620
629
631
617
618
606
621
648
643
605
628
627
622
615
591
624
602
600
618
648
632
641
617
612
595
641
674
623
590
627
609
628
595
630
631
633
637
666
637
632
624
635
637
635
634
620
605
645
616
634
625
631
643
649
625
606
618
608
621
662
623
614
647
603
629
592
617
626
619
604
608
644
646
645
644
663
637
656
649
652
666
664
697
699
649
620
651
605
593
536
519
500
461
436
442
430
411
423
377
384
353
394
578
1293
2144
2382
1720
662
329
241
258
254
254
250
254
267
238
231
227
219
228
235
223
215
212
236
224
213
212
217
214
227
213
243
225
229
233
245
209
195
205
218
192
185
196
200
189
194
189
203
201
179
193
217
211
186
195
188
188
170
221
203
191
194
191
198
192
177
197
222
184
178
185
171
181
155
171
173
179
175
178
172
177
146
162
173
162
181
186
167
155
178
166
180
185
170
166
163
150
173
176
165
162
162
173
158
152
173
163
162
161
155
159
150
161
153
160
152
162
150
146
158
152
157
167
152
169
166
160
169
153
153
140
134
155
156
164
149
150
158
151
168
145
152
159
156
154
176
163
149
165
169
177
151
153
137
144
155
123
118
106
120
109
112
113
101
107
105
148
213
412
570
381
188
111
107
93
101
98
85
92
99
86
97
99
83
82
85
90
106
108
110
141
111
101
86
87
99
89
79
75
77
75
65
56
49
57
37
52
63
50
40
48
63
101
330
459
224
88
49
43
50
41
45
51
52
46
51
50
49
51
46
48
50
45
52
54
54
51
47
66
56
49
51
43
41
43
53
50
41
40
51
41
39
39
40
38
39
35
41
42
44
53
63
104
117
120
91
53
37
33
31
47
47
56
54
36
36
35
34
28
36
31
36
30
35
21
20
3
1
1
1
0
1.47543
Sn 3d/15
Not Specified
2024
4
4
17
57
26
0
3
   XPS     Spectrum    Lens Mode:Hybrid   Res:80   Iris(Aper):slot(Slot)
   Acqn. Time(s): 141        Sweeps: 6        Anode:Mono(Al (Mono))(225 W)   Step(meV): 300.0
   Dwell Time(ms): 298        Charge Neutraliser :On (Current 1.9 A: Balance 3.6 V: Bias 1.1 V)   Acquired On :24/04/04 17:57:26
XPS
26.944
4.665
4
Mono(Al (Mono))
1486.69
225
1E+37
1E+37
6000
6000
1E+37
1E+37
FAT
80
1E+37
-4.6
0
1E+37
1E+37
1E+37
1E+37
Sn
3d
-1
Kinetic Energy
eV
986.69
0.3
2
Intensity
d
Transmission
d
pulse counting
0.2985
6
0
1E+37
1E+37
1E+37
0
158
10020
10571
1.64313
1.65517
10031
1.65517
10098
1.65501
10191
1.65486
10020
1.6547
10041
1.65455
10052
1.6544
10174
1.65424
10301
1.65409
10084
1.65393
10160
1.65378
10166
1.65362
10233
1.65347
10306
1.65332
10179
1.65316
10098
1.65301
10127
1.65285
10101
1.6527
10102
1.65254
10280
1.65239
10223
1.65223
10260
1.65208
10142
1.65193
10227
1.65177
10167
1.65162
10147
1.65146
10165
1.65131
10331
1.65115
10347
1.651
10300
1.65085
10210
1.65069
10285
1.65054
10300
1.65038
10190
1.65023
10251
1.65007
10301
1.64992
10431
1.64977
10257
1.64961
10093
1.64946
10347
1.6493
10325
1.64915
10245
1.64899
10212
1.64884
10320
1.64868
10200
1.64853
10195
1.64838
10349
1.64822
10233
1.64807
10384
1.64791
10344
1.64776
10262
1.6476
10348
1.64745
10253
1.6473
10244
1.64714
10245
1.64699
10482
1.64683
10316
1.64668
10312
1.64652
10393
1.64637
10390
1.64622
10389
1.64606
10091
1.64591
10270
1.64575
10280
1.6456
10236
1.64544
10181
1.64529
10277
1.64513
10462
1.64498
10421
1.64483
10338
1.64467
10381
1.64452
10343
1.64436
10397
1.64421
10304
1.64405
10371
1.6439
10335
1.64375
10422
1.64359
10264
1.64344
10571
1.64328
10362
1.64313
Survey/18
Not Specified
2024
4
4
18
1
17
0
3
   XPS     Spectrum    Lens Mode:Hybrid   Res:80   Iris(Aper):slot(Slot)
   Acqn. Time(s): 121        Sweeps: 1        Anode:Mono(Al (Mono))(225 W)   Step(meV): 1000.0
   Dwell Time(ms): 100        Charge Neutraliser :On (Current 1.9 A: Balance 3.6 V: Bias 1.1 V)   Acquired On :24/04/04 18:01:17
XPS
29.63
3.415
5
Mono(Al (Mono))
1486.69
225
1E+37
1E+37
6000
6000
1E+37
1E+37
FAT
80
1E+37
-4.6
0
1E+37
1E+37
1E+37
1E+37
Wide
None
-1
Kinetic Energy
eV
286.69
1
2
Intensity
d
Transmission
d
pulse counting
0.1
0
1E+37
0
0
1.47543
684
656
713
705
710
676
721
734
756
728
765
741
705
718
723
723
778
765
727
743
784
713
698
718
680
729
747
695
732
742
734
719
720
735
774
738
752
782
777
793
796
760
753
757
766
760
761
758
795
784
772
770
799
824
773
802
778
781
769
786
772
719
793
742
757
812
806
758
780
787
789
773
805
775
797
780
800
802
819
816
841
845
784
827
809
828
808
828
826
792
787
813
815
850
825
815
863
815
791
828
823
834
839
874
878
829
828
810
856
875
827
832
855
815
866
832
834
854
876
904
871
895
873
892
858
903
929
898
896
865
896
899
911
866
876
884
886
844
878
883
851
906
895
894
935
885
917
930
924
886
930
916
888
895
911
867
943
919
941
897
910
934
930
903
955
929
920
888
922
939
929
963
959
939
945
914
951
984
960
949
971
941
961
970
997
953
974
1007
989
945
967
1008
1009
975
965
1007
956
995
1044
1038
1115
1107
1101
1037
1031
1032
992
985
977
980
951
936
925
961
904
880
929
943
981
1072
1117
1185
1214
1340
1257
1121
1083
1035
985
878
867
856
811
769
712
703
655
640
597
597
604
591
628
613
598
602
653
567
574
617
605
572
571
620
622
625
641
606
622
614
583
597
610
659
645
604
585
605
623
645
615
621
646
613
622
620
627
641
643
633
623
638
648
647
668
616
655
631
652
634
645
644
624
621
667
613
638
677
652
654
619
636
663
639
602
610
651
664
635
666
619
638
687
695
696
682
696
675
666
640
676
690
695
711
693
679
693
653
691
697
696
674
680
691
673
723
689
668
661
665
704
700
684
665
670
686
691
680
683
706
679
696
729
711
722
678
721
723
723
744
752
716
741
745
689
681
689
713
774
750
763
745
704
698
699
729
745
743
751
722
699
757
720
713
725
728
759
761
738
765
739
706
722
734
719
699
710
771
738
728
777
768
699
713
756
723
758
788
788
752
768
760
774
800
811
794
784
775
789
769
787
769
795
743
792
797
754
733
780
824
790
829
786
778
735
777
765
812
789
772
761
793
781
812
824
810
859
828
838
825
777
766
832
853
791
819
804
805
807
781
839
833
825
835
809
851
836
802
824
874
835
860
828
867
819
816
839
870
855
848
806
886
863
865
882
857
878
859
841
850
894
919
857
884
890
876
835
874
814
849
882
879
888
883
877
859
908
889
879
863
875
909
895
900
905
885
901
890
887
927
905
905
931
919
888
916
886
884
908
964
922
945
915
897
911
912
933
949
958
952
902
954
977
965
931
942
907
956
996
964
975
942
935
937
1000
953
970
992
945
988
949
936
952
951
978
964
982
1021
995
980
1043
1008
971
1009
1010
961
996
1031
1000
972
995
980
988
1005
958
1002
1004
981
1038
1031
1039
1035
1014
994
1005
1004
1029
1006
998
1044
1036
1021
1033
1022
1043
998
1018
1010
978
1012
998
1011
1022
1050
989
1034
1034
1061
1061
1057
1062
1022
1043
1074
1085
1048
1072
1073
1040
1042
1039
1057
1033
1043
1070
1041
1046
1078
1074
1068
1014
1080
1132
1172
1135
1144
1169
1132
1094
1114
1070
1086
1039
951
1006
961
907
861
844
766
754
785
720
685
698
668
655
744
1195
2135
3498
3844
2456
1188
672
624
587
540
560
566
586
553
565
570
551
549
578
594
578
602
607
597
591
588
534
519
532
560
588
604
611
599
606
571
582
581
558
526
580
608
534
592
562
577
562
589
580
588
601
606
611
573
599
589
601
598
602
605
581
598
606
602
616
626
593
586
589
597
622
586
589
583
581
588
580
597
609
594
597
637
601
644
591
584
603
600
600
526
595
557
572
605
588
608
590
614
617
632
641
613
635
616
607
634
662
585
605
602
588
591
634
626
626
648
621
602
603
593
589
601
639
602
605
615
636
640
611
617
600
623
618
598
576
654
667
610
638
629
603
617
628
625
617
624
616
632
621
653
601
652
654
622
640
595
630
628
654
644
628
632
612
631
608
635
571
643
624
612
633
623
615
592
609
625
591
652
612
621
652
653
608
639
632
639
630
646
637
646
615
629
628
600
619
619
641
644
648
621
662
636
610
607
619
688
669
634
628
608
622
634
627
616
630
638
616
624
608
656
611
649
631
657
665
653
673
688
647
647
615
595
538
570
496
488
465
457
454
415
408
392
409
407
386
405
545
1017
1805
2310
2094
1300
496
315
284
256
247
246
245
254
227
204
244
232
225
220
242
227
223
227
217
220
208
205
205
220
219
234
232
211
203
191
184
201
210
192
216
174
198
221
196
197
197
198
209
179
171
169
183
181
188
185
181
200
190
181
191
182
168
183
158
182
191
186
164
180
174
189
191
157
161
159
169
160
157
167
162
164
162
171
155
162
175
168
178
178
149
173
164
147
167
185
144
166
149
168
153
169
151
148
160
178
153
150
156
166
167
180
146
153
149
139
154
139
148
143
135
150
150
142
136
156
168
164
151
148
163
134
149
123
153
139
139
132
149
154
165
147
149
146
139
157
173
181
156
190
171
146
144
133
148
141
129
115
116
117
110
113
109
103
95
97
131
148
263
453
540
347
170
127
114
91
103
111
86
89
79
95
72
84
91
90
80
91
85
105
100
91
93
95
91
93
87
80
93
78
69
81
72
65
58
65
59
54
52
41
67
58
84
195
371
401
180
82
55
58
49
50
34
44
54
55
52
43
51
41
41
59
48
47
55
50
54
49
49
48
53
59
57
52
52
41
48
52
52
50
58
46
41
28
33
30
41
38
32
45
50
47
76
106
115
114
73
59
45
42
30
37
48
50
43
41
35
25
42
31
24
20
28
26
27
23
18
3
0
0
0
1
1.47543
Sn 3d/19
Not Specified
2024
4
4
18
4
0
0
3
   XPS     Spectrum    Lens Mode:Hybrid   Res:80   Iris(Aper):slot(Slot)
   Acqn. Time(s): 141        Sweeps: 6        Anode:Mono(Al (Mono))(225 W)   Step(meV): 300.0
   Dwell Time(ms): 298        Charge Neutraliser :On (Current 1.9 A: Balance 3.6 V: Bias 1.1 V)   Acquired On :24/04/04 18:04:00
XPS
29.63
3.415
5
Mono(Al (Mono))
1486.69
225
1E+37
1E+37
6000
6000
1E+37
1E+37
FAT
80
1E+37
-4.6
0
1E+37
1E+37
1E+37
1E+37
Sn
3d
-1
Kinetic Energy
eV
986.69
0.3
2
Intensity
d
Transmission
d
pulse counting
0.2985
6
0
1E+37
1E+37
1E+37
0
158
10149
10643
1.64313
1.65517
10178
1.65517
10309
1.65501
10433
1.65486
10238
1.6547
10149
1.65455
10310
1.6544
10238
1.65424
10288
1.65409
10248
1.65393
10403
1.65378
10369
1.65362
10274
1.65347
10336
1.65332
10366
1.65316
10179
1.65301
10251
1.65285
10331
1.6527
10318
1.65254
10359
1.65239
10442
1.65223
10428
1.65208
10322
1.65193
10466
1.65177
10401
1.65162
10532
1.65146
10573
1.65131
10406
1.65115
10281
1.651
10486
1.65085
10370
1.65069
10412
1.65054
10434
1.65038
10264
1.65023
10421
1.65007
10404
1.64992
10362
1.64977
10387
1.64961
10439
1.64946
10626
1.6493
10336
1.64915
10514
1.64899
10431
1.64884
10348
1.64868
10503
1.64853
10468
1.64838
10401
1.64822
10419
1.64807
10353
1.64791
10479
1.64776
10452
1.6476
10415
1.64745
10612
1.6473
10528
1.64714
10421
1.64699
10442
1.64683
10487
1.64668
10403
1.64652
10383
1.64637
10464
1.64622
10406
1.64606
10375
1.64591
10578
1.64575
10482
1.6456
10324
1.64544
10525
1.64529
10578
1.64513
10532
1.64498
10632
1.64483
10584
1.64467
10569
1.64452
10643
1.64436
10534
1.64421
10625
1.64405
10626
1.6439
10568
1.64375
10612
1.64359
10591
1.64344
10441
1.64328
10567
1.64313
Survey/22
Not Specified
2024
4
4
18
7
55
0
3
   XPS     Spectrum    Lens Mode:Hybrid   Res:80   Iris(Aper):slot(Slot)
   Acqn. Time(s): 121        Sweeps: 1        Anode:Mono(Al (Mono))(225 W)   Step(meV): 1000.0
   Dwell Time(ms): 100        Charge Neutraliser :On (Current 1.9 A: Balance 3.6 V: Bias 1.1 V)   Acquired On :24/04/04 18:07:55
XPS
30.428
1.227
6
Mono(Al (Mono))
1486.69
225
1E+37
1E+37
6000
6000
1E+37
1E+37
FAT
80
1E+37
-4.6
0
1E+37
1E+37
1E+37
1E+37
Wide
None
-1
Kinetic Energy
eV
286.69
1
2
Intensity
d
Transmission
d
pulse counting
0.1
0
1E+37
0
0
1.47543
677
699
717
707
715
699
702
721
773
741
725
749
725
738
779
773
735
710
714
749
712
718
749
732
715
741
750
741
684
737
728
726
763
728
741
727
757
763
796
770
768
744
753
786
775
790
811
772
746
779
744
762
757
724
797
764
767
752
718
778
793
797
800
803
811
796
767
819
800
773
821
804
813
792
827
792
787
834
819
792
781
799
799
798
794
771
833
826
832
769
834
878
823
793
774
776
803
805
833
862
799
832
827
796
818
878
829
827
816
848
873
893
884
846
824
875
836
841
834
845
872
834
861
842
891
916
890
870
835
864
893
898
864
907
904
874
923
930
906
829
886
880
870
922
881
880
867
890
926
860
886
923
872
875
941
936
901
924
943
928
938
908
954
913
922
960
949
939
955
973
960
968
955
955
939
954
981
952
967
934
969
998
996
996
1019
965
981
976
1017
991
971
1014
1042
989
1037
1018
1082
1029
1069
1028
1075
1074
1088
1116
1044
1073
1011
1021
963
994
931
922
917
917
905
919
891
890
983
1024
1107
1161
1209
1278
1295
1196
1069
1006
967
926
873
834
783
735
680
655
624
595
583
606
616
607
606
614
625
606
624
591
584
625
643
617
632
615
631
585
581
616
639
595
594
599
626
616
630
612
628
636
644
618
607
644
660
652
655
675
647
649
648
644
606
641
637
648
631
650
653
646
652
628
662
670
645
627
634
662
667
662
654
651
656
663
653
630
639
682
668
633
649
636
663
685
679
694
646
644
655
686
652
646
657
702
679
660
678
735
715
652
697
685
704
708
726
685
696
682
659
679
673
695
673
694
726
688
706
732
688
686
699
714
659
695
693
697
688
704
683
711
706
781
727
692
746
727
715
688
740
720
727
739
679
707
719
695
740
710
754
721
703
733
719
708
714
696
751
748
724
773
763
758
696
747
760
720
741
728
738
709
718
756
772
788
765
766
764
797
771
743
805
777
738
763
819
776
754
777
786
832
771
788
755
805
800
820
755
842
832
807
804
818
753
771
770
798
814
801
753
763
815
739
781
773
841
825
803
786
806
787
812
790
779
782
829
837
818
823
822
840
820
861
808
838
881
839
860
861
900
866
874
835
850
880
878
814
876
872
847
848
871
820
846
862
887
924
879
856
855
821
852
886
869
835
839
860
873
916
851
881
876
866
908
878
865
894
892
920
914
888
957
932
905
914
941
950
958
938
922
921
923
974
941
877
957
906
913
924
912
928
919
912
922
923
962
928
917
923
943
988
987
949
992
957
981
968
922
944
943
959
962
945
902
950
956
984
944
961
954
964
932
978
995
1002
993
961
1036
1040
986
945
924
975
1002
985
983
980
1010
980
977
1011
1065
1049
1034
1017
988
1001
1016
999
1011
1032
1033
1056
968
1050
1021
1027
986
1033
1045
1014
1024
1044
1055
1012
1000
1042
1074
975
1034
1049
1070
1031
1084
1080
1061
1066
1074
1046
1046
1058
1064
1020
1063
1095
1045
1094
1093
1026
1068
1084
1074
1111
1010
1033
1067
1075
1034
1046
1019
981
1041
1085
1086
1092
1128
1166
1163
1132
1145
1206
1150
1137
1104
1035
1001
988
932
888
885
829
799
779
686
703
713
679
659
678
841
1469
3097
4317
3109
1591
834
623
579
556
532
574
584
527
524
584
629
594
520
551
559
559
563
556
565
548
588
558
549
534
564
617
579
580
592
593
584
579
585
544
571
592
599
583
587
611
527
556
591
585
591
590
574
573
597
592
569
540
568
591
613
600
593
625
655
618
604
610
587
581
575
551
598
570
567
585
578
631
577
621
[...]
1961
0.348926
1969
0.348921
2003
0.348916
2014
0.348911
1992
0.348906
1999
0.348901
1977
0.348896
2033
0.34889
2009
0.348885
1949
0.34888
1947
0.348875
2008
0.34887
1934
0.348865
1972
0.34886
2049
0.348855
1988
0.34885
2007
0.348845
2030
0.34884
1985
0.348835
2080
0.34883
2057
0.348825
2095
0.34882
2063
0.348815
2136
0.34881
2135
0.348805
2209
0.3488
2278
0.348795
2280
0.34879
2315
0.348785
2315
0.34878
2307
0.348775
2269
0.34877
2348
0.348765
2279
0.34876
2319
0.348755
2310
0.348749
2334
0.348744
2242
0.348739
2225
0.348734
2262
0.348729
2206
0.348724
2173
0.348719
2142
0.348714
2178
0.348709
2114
0.348704
2101
0.348699
2136
0.348694
2185
0.348689
2213
0.348684
2250
0.348679
2314
0.348674
2342
0.348669
2373
0.348664
2501
0.348659
2483
0.348654
2537
0.348649
2530
0.348644
2599
0.348639
2722
0.348634
2844
0.348629
2911
0.348624
3258
0.348619
3279
0.348614
3736
0.348608
4021
0.348603
4499
0.348598
4992
0.348593
5637
0.348588
6239
0.348583
7070
0.348578
7804
0.348573
8486
0.348568
9119
0.348563
9681
0.348558
9751
0.348553
9566
0.348548
9089
0.348543
8517
0.348538
7897
0.348533
7035
0.348528
6128
0.348523
5478
0.348518
4724
0.348513
4137
0.348508
3627
0.348503
3243
0.348498
2942
0.348493
2807
0.348488
2479
0.348483
2350
0.348478
2200
0.348473
2144
0.348467
2175
0.348462
2091
0.348457
2034
0.348452
2002
0.348447
2044
0.348442
2013
0.348437
1956
0.348432
1981
0.348427
1931
0.348422
1881
0.348417
1990
0.348412
1881
0.348407
1919
0.348402
1907
0.348397
1870
0.348392
1942
0.348387
1867
0.348382
1883
0.348377
1869
0.348372
1962
0.348367
1920
0.348362
1882
0.348357
1945
0.348352
1931
0.348347
1927
0.348342
1908
0.348337
1842
0.348331
1827
0.348326
1904
0.348321
1846
0.348316
1882
0.348311
1920
0.348306
1873
0.348301
1924
0.348296
1834
0.348291
Al 2p/173
Not Specified
2024
4
5
10
17
53
0
3
   XPS     Spectrum    Lens Mode:Hybrid   Res:20   Iris(Aper):slot(Slot)
   Acqn. Time(s): 827        Sweeps: 12       Anode:Mono(Al (Mono))(225 W)   Step(meV): 100.0
   Dwell Time(ms): 298        Charge Neutraliser :On (Current 1.9 A: Balance 3.6 V: Bias 1.1 V)   Acquired On :24/04/05 10:17:53
XPS
88.734
-0.925
35
Mono(Al (Mono))
1486.69
225
1E+37
1E+37
6000
6000
1E+37
1E+37
FAT
20
1E+37
-4.6
0
1E+37
1E+37
1E+37
1E+37
Al
2p
-1
Kinetic Energy
eV
1400.69
0.1
2
Intensity
d
Transmission
d
pulse counting
0.2985
12
0
1E+37
1E+37
1E+37
0
462
499
16838
0.333188
0.333748
1261
0.333748
1210
0.333746
1252
0.333744
1242
0.333741
1315
0.333739
1306
0.333736
1194
0.333734
1228
0.333731
1174
0.333729
1171
0.333726
1205
0.333724
1143
0.333722
1100
0.333719
1107
0.333717
1082
0.333714
1120
0.333712
1098
0.333709
1091
0.333707
1073
0.333705
1028
0.333702
1089
0.3337
1075
0.333697
1014
0.333695
1025
0.333692
998
0.33369
1010
0.333687
1004
0.333685
1018
0.333683
969
0.33368
1014
0.333678
944
0.333675
972
0.333673
893
0.33367
941
0.333668
954
0.333666
981
0.333663
962
0.333661
938
0.333658
921
0.333656
877
0.333653
909
0.333651
839
0.333649
876
0.333646
851
0.333644
857
0.333641
864
0.333639
820
0.333636
799
0.333634
835
0.333631
785
0.333629
793
0.333627
813
0.333624
751
0.333622
751
0.333619
774
0.333617
751
0.333614
736
0.333612
712
0.333609
731
0.333607
667
0.333605
664
0.333602
653
0.3336
640
0.333597
653
0.333595
621
0.333592
627
0.33359
607
0.333588
587
0.333585
599
0.333583
608
0.33358
613
0.333578
612
0.333575
589
0.333573
612
0.333571
546
0.333568
576
0.333566
519
0.333563
553
0.333561
577
0.333558
526
0.333556
541
0.333553
547
0.333551
531
0.333549
515
0.333546
527
0.333544
510
0.333541
512
0.333539
541
0.333536
518
0.333534
510
0.333532
542
0.333529
563
0.333527
548
0.333524
524
0.333522
509
0.333519
536
0.333517
531
0.333514
537
0.333512
534
0.33351
519
0.333507
527
0.333505
527
0.333502
542
0.3335
533
0.333497
579
0.333495
549
0.333493
531
0.33349
556
0.333488
587
0.333485
599
0.333483
581
0.33348
575
0.333478
626
0.333475
625
0.333473
682
0.333471
696
0.333468
673
0.333466
720
0.333463
708
0.333461
736
0.333458
730
0.333456
813
0.333454
827
0.333451
867
0.333449
976
0.333446
1024
0.333444
1141
0.333441
1394
0.333439
1609
0.333436
2026
0.333434
2422
0.333432
2947
0.333429
3687
0.333427
4510
0.333424
5431
0.333422
6699
0.333419
8027
0.333417
9431
0.333415
10862
0.333412
12315
0.33341
13485
0.333407
14916
0.333405
15912
0.333402
16578
0.3334
16726
0.333398
16838
0.333395
16331
0.333393
15717
0.33339
14546
0.333388
13178
0.333385
11691
0.333383
9976
0.33338
8691
0.333378
7250
0.333376
5761
0.333373
4590
0.333371
3623
0.333368
2877
0.333366
2253
0.333363
1723
0.333361
1424
0.333359
1121
0.333356
949
0.333354
802
0.333351
754
0.333349
686
0.333346
665
0.333344
640
0.333341
609
0.333339
573
0.333337
600
0.333334
595
0.333332
586
0.333329
596
0.333327
560
0.333324
560
0.333322
550
0.33332
607
0.333317
542
0.333315
519
0.333312
542
0.33331
563
0.333307
520
0.333305
551
0.333302
559
0.3333
508
0.333298
545
0.333295
566
0.333293
502
0.33329
545
0.333288
526
0.333285
539
0.333283
499
0.333281
533
0.333278
539
0.333276
555
0.333273
511
0.333271
569
0.333268
529
0.333266
562
0.333263
545
0.333261
524
0.333259
519
0.333256
557
0.333254
560
0.333251
539
0.333249
550
0.333246
570
0.333244
553
0.333242
532
0.333239
563
0.333237
532
0.333234
519
0.333232
522
0.333229
531
0.333227
554
0.333225
528
0.333222
516
0.33322
502
0.333217
555
0.333215
528
0.333212
520
0.33321
523
0.333207
545
0.333205
517
0.333203
536
0.3332
532
0.333198
527
0.333195
529
0.333193
522
0.33319
522
0.333188
O 1s/176
Not Specified
2024
4
5
10
34
29
0
3
   XPS     Spectrum    Lens Mode:Hybrid   Res:20   Iris(Aper):slot(Slot)
   Acqn. Time(s): 488        Sweeps: 8        Anode:Mono(Al (Mono))(225 W)   Step(meV): 100.0
   Dwell Time(ms): 332        Charge Neutraliser :On (Current 1.9 A: Balance 3.6 V: Bias 1.1 V)   Acquired On :24/04/05 10:34:29
XPS
92.918
-0.096
36
Mono(Al (Mono))
1486.69
225
1E+37
1E+37
6000
6000
1E+37
1E+37
FAT
20
1E+37
-4.6
0
1E+37
1E+37
1E+37
1E+37
O
1s
-1
Kinetic Energy
eV
943.69
0.1
2
Intensity
d
Transmission
d
pulse counting
0.3315
8
0
1E+37
1E+37
1E+37
0
368
2872
54415
0.358325
0.359889
6328
0.359889
6316
0.35988
6219
0.359872
6131
0.359863
6113
0.359854
5985
0.359846
6066
0.359837
5965
0.359829
6092
0.35982
6001
0.359812
5956
0.359803
5820
0.359795
5789
0.359786
5774
0.359778
5859
0.359769
5681
0.35976
5727
0.359752
5600
0.359743
5601
0.359735
5641
0.359726
5501
0.359718
5502
0.359709
5417
0.359701
5412
0.359692
5339
0.359684
5189
0.359675
5306
0.359666
5267
0.359658
5264
0.359649
5338
0.359641
5096
0.359632
5170
0.359624
5066
0.359615
5016
0.359607
4975
0.359598
4985
0.359589
4935
0.359581
4860
0.359572
4808
0.359564
4752
0.359555
4631
0.359547
4699
0.359538
4661
0.35953
4571
0.359521
4618
0.359513
4563
0.359504
4452
0.359495
4316
0.359487
4320
0.359478
4365
0.35947
4301
0.359461
4245
0.359453
4196
0.359444
4149
0.359436
4064
0.359427
4029
0.359419
3925
0.35941
3943
0.359401
3849
0.359393
3910
0.359384
3801
0.359376
3735
0.359367
3678
0.359359
3593
0.35935
3509
0.359342
3547
0.359333
3575
0.359325
3516
0.359316
3457
0.359307
3380
0.359299
3281
0.35929
3257
0.359282
3249
0.359273
3213
0.359265
3062
0.359256
3137
0.359248
3122
0.359239
3058
0.359231
3055
0.359222
2958
0.359213
3052
0.359205
3018
0.359196
2973
0.359188
2937
0.359179
2917
0.359171
2962
0.359162
2925
0.359154
2954
0.359145
2892
0.359137
2892
0.359128
2872
0.359119
2970
0.359111
2932
0.359102
2971
0.359094
2929
0.359085
2902
0.359077
2946
0.359068
2994
0.35906
2932
0.359051
2938
0.359043
3029
0.359034
3011
0.359025
2979
0.359017
3014
0.359008
3192
0.359
3138
0.358991
3218
0.358983
3162
0.358974
3281
0.358966
3348
0.358957
3434
0.358949
3519
0.35894
3729
0.358931
3812
0.358923
3910
0.358914
4206
0.358906
4445
0.358897
4638
0.358889
4971
0.35888
5363
0.358872
5878
0.358863
6396
0.358855
6987
0.358846
7591
0.358837
8419
0.358829
9260
0.35882
10496
0.358812
11699
0.358803
12908
0.358795
14305
0.358786
15845
0.358778
17690
0.358769
19811
0.358761
21971
0.358752
24335
0.358743
26697
0.358735
28970
0.358726
31708
0.358718
34406
0.358709
37297
0.358701
39985
0.358692
42671
0.358684
45320
0.358675
47751
0.358667
50174
0.358658
52325
0.358649
54036
0.358641
54406
0.358632
54415
0.358624
54183
0.358615
53023
0.358607
50848
0.358598
48062
0.35859
45097
0.358581
41487
0.358573
37451
0.358564
33663
0.358555
29773
0.358547
26165
0.358538
22558
0.35853
19447
0.358521
16419
0.358513
13921
0.358504
11560
0.358496
9957
0.358487
8533
0.358478
7220
0.35847
6223
0.358461
5532
0.358453
4955
0.358444
4420
0.358436
3993
0.358427
3737
0.358419
3723
0.35841
3541
0.358402
3358
0.358393
3296
0.358384
3107
0.358376
3057
0.358367
2970
0.358359
3030
0.35835
3000
0.358342
2877
0.358333
2983
0.358325
Sn 3d/177
Not Specified
2024
4
5
10
44
27
0
3
   XPS     Spectrum    Lens Mode:Hybrid   Res:20   Iris(Aper):slot(Slot)
   Acqn. Time(s): 827        Sweeps: 12       Anode:Mono(Al (Mono))(225 W)   Step(meV): 100.0
   Dwell Time(ms): 298        Charge Neutraliser :On (Current 1.9 A: Balance 3.6 V: Bias 1.1 V)   Acquired On :24/04/05 10:44:27
XPS
92.918
-0.096
36
Mono(Al (Mono))
1486.69
225
1E+37
1E+37
6000
6000
1E+37
1E+37
FAT
20
1E+37
-4.6
0
1E+37
1E+37
1E+37
1E+37
Sn
3d
-1
Kinetic Energy
eV
986.69
0.1
2
Intensity
d
Transmission
d
pulse counting
0.2985
12
0
1E+37
1E+37
1E+37
0
462
3385
3744
0.355784
0.356861
3505
0.356861
3565
0.356857
3532
0.356852
3621
0.356847
3611
0.356843
3597
0.356838
3482
0.356833
3405
0.356829
3544
0.356824
3566
0.356819
3564
0.356815
3572
0.35681
3550
0.356805
3546
0.356801
3606
0.356796
3513
0.356791
3432
0.356786
3523
0.356782
3532
0.356777
3572
0.356772
3559
0.356768
3589
0.356763
3535
0.356758
3568
0.356754
3531
0.356749
3504
0.356744
3593
0.35674
3576
0.356735
3585
0.35673
3550
0.356726
3538
0.356721
3595
0.356716
3546
0.356712
3563
0.356707
3541
0.356702
3512
0.356697
3611
0.356693
3605
0.356688
3385
0.356683
3597
0.356679
3607
0.356674
3591
0.356669
3565
0.356665
3547
0.35666
3500
0.356655
3597
0.356651
3628
0.356646
3655
0.356641
3607
0.356637
3479
0.356632
3654
0.356627
3513
0.356622
3534
0.356618
3621
0.356613
3594
0.356608
3588
0.356604
3623
0.356599
3524
0.356594
3452
0.35659
3554
0.356585
3608
0.35658
3617
0.356576
3560
0.356571
3516
0.356566
3535
0.356562
3479
0.356557
3463
0.356552
3533
0.356547
3634
0.356543
3635
0.356538
3586
0.356533
3539
0.356529
3545
0.356524
3597
0.356519
3581
0.356515
3501
0.35651
3508
0.356505
3595
0.356501
3578
0.356496
3574
0.356491
3467
0.356487
3522
0.356482
3538
0.356477
3508
0.356472
3544
0.356468
3588
0.356463
3705
0.356458
3609
0.356454
3550
0.356449
3520
0.356444
3675
0.35644
3628
0.356435
3646
0.35643
3541
0.356426
3646
0.356421
3744
0.356416
3630
0.356412
3602
0.356407
3552
0.356402
3602
0.356398
3592
0.356393
3516
0.356388
3698
0.356383
3663
0.356379
3500
0.356374
3543
0.356369
3557
0.356365
3623
0.35636
3607
0.356355
3529
0.356351
3597
0.356346
3577
0.356341
3532
0.356337
3493
0.356332
3468
0.356327
3504
0.356323
3569
0.356318
3587
0.356313
3516
0.356308
3584
0.356304
3592
0.356299
3613
0.356294
3537
0.35629
3571
0.356285
3535
0.35628
3568
0.356276
3555
0.356271
3673
0.356266
3577
0.356262
3570
0.356257
3595
0.356252
3517
0.356248
3592
0.356243
3714
0.356238
3710
0.356233
3609
0.356229
3674
0.356224
3637
0.356219
3628
0.356215
3524
0.35621
3514
0.356205
3616
0.356201
3631
0.356196
3703
0.356191
3646
0.356187
3594
0.356182
3662
0.356177
3593
0.356173
3563
0.356168
3574
0.356163
3622
0.356158
3603
0.356154
3630
0.356149
3523
0.356144
3629
0.35614
3629
0.356135
3688
0.35613
3591
0.356126
3695
0.356121
3700
0.356116
3637
0.356112
3698
0.356107
3620
0.356102
3585
0.356098
3591
0.356093
3544
0.356088
3573
0.356084
3699
0.356079
3588
0.356074
3633
0.356069
3698
0.356065
3552
0.35606
3591
0.356055
3575
0.356051
3519
0.356046
3602
0.356041
3594
0.356037
3634
0.356032
3588
0.356027
3615
0.356023
3618
0.356018
3592
0.356013
3529
0.356009
3517
0.356004
3558
0.355999
3683
0.355994
3559
0.35599
3587
0.355985
3593
0.35598
3649
0.355976
3629
0.355971
3537
0.355966
3498
0.355962
3625
0.355957
3583
0.355952
3689
0.355948
3517
0.355943
3650
0.355938
3479
0.355934
3571
0.355929
3614
0.355924
3466
0.35592
3587
0.355915
3566
0.35591
3639
0.355905
3578
0.355901
3671
0.355896
3582
0.355891
3647
0.355887
3627
0.355882
3548
0.355877
3530
0.355873
3603
0.355868
3613
0.355863
3572
0.355859
3590
0.355854
3625
0.355849
3645
0.355845
3538
0.35584
3636
0.355835
3634
0.35583
3661
0.355826
3569
0.355821
3592
0.355816
3621
0.355812
3484
0.355807
3598
0.355802
3639
0.355798
3595
0.355793
3549
0.355788
3592
0.355784
C 1s/178
Not Specified
2024
4
5
11
0
57
0
3
   XPS     Spectrum    Lens Mode:Hybrid   Res:20   Iris(Aper):slot(Slot)
   Acqn. Time(s): 482        Sweeps: 8        Anode:Mono(Al (Mono))(225 W)   Step(meV): 100.0
   Dwell Time(ms): 260        Charge Neutraliser :On (Current 1.9 A: Balance 3.6 V: Bias 1.1 V)   Acquired On :24/04/05 11:00:57
XPS
92.918
-0.096
36
Mono(Al (Mono))
1486.69
225
1E+37
1E+37
6000
6000
1E+37
1E+37
FAT
20
1E+37
-4.6
0
1E+37
1E+37
1E+37
1E+37
C
1s
-1
Kinetic Energy
eV
1186.69
0.1
2
Intensity
d
Transmission
d
pulse counting
0.2597
8
0
1E+37
1E+37
1E+37
0
464
1723
10112
0.348291
0.349292
2182
0.349254
2254
0.349255
2143
0.349256
2255
0.349257
2276
0.349258
2217
0.34926
2236
0.349261
2186
0.349262
2197
0.349263
2193
0.349264
2155
0.349266
2197
0.349267
2182
0.349268
2232
0.349269
2249
0.34927
2225
0.349272
2208
0.349273
2192
0.349274
2158
0.349275
2230
0.349276
2204
0.349278
2153
0.349279
2109
0.34928
2208
0.349281
2172
0.349282
2227
0.349284
2126
0.349285
2158
0.349286
2218
0.349287
2167
0.349289
2117
0.34929
2164
0.349291
2166
0.349292
2165
0.349288
2091
0.349283
2097
0.349278
2115
0.349273
2160
0.349268
2138
0.349263
2102
0.349258
2091
0.349253
2088
0.349248
2088
0.349243
2065
0.349238
2125
0.349233
2063
0.349228
2053
0.349223
2076
0.349218
2129
0.349213
2121
0.349208
2094
0.349203
2068
0.349198
2085
0.349193
2092
0.349188
2027
0.349183
2096
0.349178
2074
0.349173
2111
0.349167
2056
0.349162
2104
0.349157
1996
0.349152
2055
0.349147
2041
0.349142
2055
0.349137
1952
0.349132
2023
0.349127
2024
0.349122
2012
0.349117
2069
0.349112
2038
0.349107
2081
0.349102
2054
0.349097
1992
0.349092
2013
0.349087
2045
0.349082
1968
0.349077
2043
0.349072
2015
0.349067
2037
0.349062
2004
0.349057
2041
0.349052
1930
0.349047
1973
0.349042
1992
0.349037
1981
0.349032
1979
0.349026
2002
0.349021
2119
0.349016
1966
0.349011
1974
0.349006
1927
0.349001
1970
0.348996
1926
0.348991
1919
0.348986
1976
0.348981
1975
0.348976
1970
0.348971
1960
0.348966
1959
0.348961
1970
0.348956
1950
0.348951
1942
0.348946
1958
0.348941
1877
0.348936
1913
0.348931
1938
0.348926
1944
0.348921
1902
0.348916
1962
0.348911
1915
0.348906
1922
0.348901
2014
0.348896
1952
0.34889
1925
0.348885
1877
0.34888
1942
0.348875
1922
0.34887
1916
0.348865
1889
0.34886
1964
0.348855
1936
0.34885
2003
0.348845
1993
0.34884
1959
0.348835
1973
0.34883
1951
0.348825
1993
0.34882
2020
0.348815
2037
0.34881
2126
0.348805
2075
0.3488
2053
0.348795
2143
0.34879
2176
0.348785
2195
0.34878
2195
0.348775
2292
0.34877
2275
0.348765
2254
0.34876
2292
0.348755
2300
0.348749
2354
0.348744
2253
0.348739
2285
0.348734
2275
0.348729
2204
0.348724
2172
0.348719
2130
0.348714
2148
0.348709
2130
0.348704
2094
0.348699
2103
0.348694
2171
0.348689
2152
0.348684
2181
0.348679
2162
0.348674
2200
0.348669
2234
0.348664
2330
0.348659
2287
0.348654
2372
0.348649
2441
0.348644
2485
0.348639
2548
0.348634
2551
0.348629
2710
0.348624
2804
0.348619
2895
0.348614
3094
0.348608
3291
0.348603
3626
0.348598
4053
0.348593
4572
0.348588
5166
0.348583
5788
0.348578
6440
0.348573
7360
0.348568
8212
0.348563
8950
0.348558
9536
0.348553
10112
0.348548
10047
0.348543
9833
0.348538
9390
0.348533
8697
0.348528
7966
0.348523
7172
0.348518
6335
0.348513
5372
0.348508
4688
0.348503
4078
0.348498
3519
0.348493
3149
0.348488
2886
0.348483
2646
0.348478
2405
0.348473
2250
0.348467
2266
0.348462
2197
0.348457
2146
0.348452
2029
0.348447
1987
0.348442
1959
0.348437
1935
0.348432
1820
0.348427
1832
0.348422
1920
0.348417
1964
0.348412
1864
0.348407
1854
0.348402
1852
0.348397
1875
0.348392
1784
0.348387
1820
0.348382
1865
0.348377
1872
0.348372
1785
0.348367
1846
0.348362
1872
0.348357
1868
0.348352
1938
0.348347
1819
0.348342
1824
0.348337
1806
0.348331
1819
0.348326
1828
0.348321
1862
0.348316
1846
0.348311
1858
0.348306
1890
0.348301
1723
0.348296
1807
0.348291
Al 2p/179
Not Specified
2024
4
5
11
10
44
0
3
   XPS     Spectrum    Lens Mode:Hybrid   Res:20   Iris(Aper):slot(Slot)
   Acqn. Time(s): 827        Sweeps: 12       Anode:Mono(Al (Mono))(225 W)   Step(meV): 100.0
   Dwell Time(ms): 298        Charge Neutraliser :On (Current 1.9 A: Balance 3.6 V: Bias 1.1 V)   Acquired On :24/04/05 11:10:44
XPS
92.918
-0.096
36
Mono(Al (Mono))
1486.69
225
1E+37
1E+37
6000
6000
1E+37
1E+37
FAT
20
1E+37
-4.6
0
1E+37
1E+37
1E+37
1E+37
Al
2p
-1
Kinetic Energy
eV
1400.69
0.1
2
Intensity
d
Transmission
d
pulse counting
0.2985
12
0
1E+37
1E+37
1E+37
0
462
473
16643
0.333188
0.333748
1271
0.333748
1290
0.333746
1282
0.333744
1250
0.333741
1237
0.333739
1297
0.333736
1248
0.333734
1242
0.333731
1202
0.333729
1241
0.333726
1186
0.333724
1218
0.333722
1142
0.333719
1175
0.333717
1113
0.333714
1179
0.333712
1117
0.333709
1132
0.333707
1099
0.333705
1101
0.333702
1057
0.3337
1113
0.333697
1052
0.333695
995
0.333692
1036
0.33369
1028
0.333687
1042
0.333685
1032
0.333683
1001
0.33368
1012
0.333678
1077
0.333675
933
0.333673
975
0.33367
969
0.333668
967
0.333666
958
0.333663
888
0.333661
919
0.333658
905
0.333656
886
0.333653
844
0.333651
873
0.333649
882
0.333646
882
0.333644
843
0.333641
812
0.333639
818
0.333636
843
0.333634
793
0.333631
772
0.333629
805
0.333627
778
0.333624
755
0.333622
778
0.333619
740
0.333617
771
0.333614
738
0.333612
671
0.333609
707
0.333607
706
0.333605
741
0.333602
712
0.3336
654
0.333597
697
0.333595
655
0.333592
698
0.33359
651
0.333588
651
0.333585
624
0.333583
638
0.33358
604
0.333578
612
0.333575
606
0.333573
601
0.333571
565
0.333568
557
0.333566
552
0.333563
530
0.333561
550
0.333558
573
0.333556
569
0.333553
550
0.333551
550
0.333549
522
0.333546
495
0.333544
528
0.333541
514
0.333539
502
0.333536
568
0.333534
542
0.333532
512
0.333529
517
0.333527
541
0.333524
546
0.333522
499
0.333519
533
0.333517
547
0.333514
558
0.333512
540
0.33351
545
0.333507
521
0.333505
508
0.333502
558
0.3335
526
0.333497
520
0.333495
531
0.333493
550
0.33349
567
0.333488
554
0.333485
566
0.333483
612
0.33348
573
0.333478
582
0.333475
646
0.333473
614
0.333471
633
0.333468
639
0.333466
664
0.333463
684
0.333461
693
0.333458
733
0.333456
751
0.333454
749
0.333451
819
0.333449
802
0.333446
879
0.333444
996
0.333441
1048
0.333439
1150
0.333436
1423
0.333434
1652
0.333432
2049
0.333429
2448
0.333427
3096
0.333424
3841
0.333422
4723
0.333419
5767
0.333417
6903
0.333415
8276
0.333412
9812
0.33341
11034
0.333407
12538
0.333405
13820
0.333402
14906
0.3334
15754
0.333398
16367
0.333395
16643
0.333393
16473
0.33339
15712
0.333388
14767
0.333385
13789
0.333383
12387
0.33338
10881
0.333378
9274
0.333376
7839
0.333373
6444
0.333371
5215
0.333368
4140
0.333366
3288
0.333363
2557
0.333361
1961
0.333359
1576
0.333356
1257
0.333354
1072
0.333351
931
0.333349
772
0.333346
768
0.333344
728
0.333341
654
0.333339
617
0.333337
622
0.333334
596
0.333332
575
0.333329
557
0.333327
597
0.333324
581
0.333322
525
0.33332
560
0.333317
582
0.333315
532
0.333312
532
0.33331
538
0.333307
583
0.333305
552
0.333302
526
0.3333
538
0.333298
537
0.333295
521
0.333293
535
0.33329
516
0.333288
485
0.333285
525
0.333283
554
0.333281
573
0.333278
528
0.333276
560
0.333273
504
0.333271
508
0.333268
538
0.333266
542
0.333263
532
0.333261
531
0.333259
505
0.333256
491
0.333254
534
0.333251
537
0.333249
556
0.333246
553
0.333244
473
0.333242
514
0.333239
556
0.333237
535
0.333234
523
0.333232
536
0.333229
527
0.333227
520
0.333225
532
0.333222
549
0.33322
539
0.333217
512
0.333215
522
0.333212
549
0.33321
553
0.333207
536
0.333205
545
0.333203
531
0.3332
505
0.333198
525
0.333195
491
0.333193
522
0.33319
520
0.333188
end of experiment